Workbook

Sheet %Cost vs Budget
A1: Partner | B1: Used of Budget
A2: GOT | B2: 20.498143
A3: MNU | B3: 29.334355
A4: SCA | B4: 22.228008
A5: FOC | B5: 23.329146
A6: CLTV | B6: 15.344396
A7: MAI | B7: 10.421054
A8: BIN | B8: 7.6098034
A9: IOC | B9: 6.7956784
A10: HIE | B10: 22.468177
A11: BAL | B11: 45.780785
A12: MEERI | B12: 23.913983
A13: MCN | B13: 11.289715
A14: CKR | B14: 33.117715

Sheet WP Cost vs Budget
B23: Task/WP | C23: TOTAL COST | D23: TOTAL BUDGET
B24: WP1 | C24: =SUM('Direct &Indirect Personnal Cost'!C7) -> 104301.99 | D24: =SUM('Direct &Indirect Personnal Cost'!E7) -> 226991.17
B25: T1.1 | C25: =SUM('Direct &Indirect Personnal Cost'!C8) -> 41306.53 | D25: =SUM('Direct &Indirect Personnal Cost'!E8) -> 88440.74
B26: T1.2 | C26: =SUM('Direct &Indirect Personnal Cost'!C9) -> 29037.419 | D26: =SUM('Direct &Indirect Personnal Cost'!E9) -> 53116.01
B27: T1.3 | C27: =SUM('Direct &Indirect Personnal Cost'!C10) -> 30982.771 | D27: =SUM('Direct &Indirect Personnal Cost'!E10) -> 85434.42
B38: Task/WP | C38: TOTAL COST | D38: TOTAL BUDGET
B39: WP2 | C39: =SUM('Direct &Indirect Personnal Cost'!C11) -> 67811.891 | D39: =SUM('Direct &Indirect Personnal Cost'!E11) -> 153493.81
B40: T2.1 | C40: =SUM('Direct &Indirect Personnal Cost'!C12) -> 19605.459 | D40: =SUM('Direct &Indirect Personnal Cost'!E12) -> 67887.51
B41: T2.2 | C41: =SUM('Direct &Indirect Personnal Cost'!C13) -> 5204.3416 | D41: =SUM('Direct &Indirect Personnal Cost'!E13) -> 3343.75
B42: T2.3 | C42: =SUM('Direct &Indirect Personnal Cost'!C14) -> 10794.029 | D42: =SUM('Direct &Indirect Personnal Cost'!E14) -> 12525
B43: T2.4 | C43: =SUM('Direct &Indirect Personnal Cost'!C15) -> 32291.647 | D43: =SUM('Direct &Indirect Personnal Cost'!E15) -> 69737.55
B53: Task/WP | C53: TOTAL COST | D53: TOTAL BUDGET
B54: WP3 | C54: =SUM('Direct &Indirect Personnal Cost'!C16) -> 84177.462 | D54: =SUM('Direct &Indirect Personnal Cost'!E16) -> 3434125.1
B55: T3.1 | C55: =SUM('Direct &Indirect Personnal Cost'!C17) -> 47109.12 | D55: =SUM('Direct &Indirect Personnal Cost'!E17) -> 68475.03
B56: T3.2 | C56: =SUM('Direct &Indirect Personnal Cost'!C18) -> 14557.76 | D56: =SUM('Direct &Indirect Personnal Cost'!E18) -> 18562.5
B57: T3.3 | C57: =SUM('Direct &Indirect Personnal Cost'!C19) -> 15885.025 | D57: =SUM('Direct &Indirect Personnal Cost'!E19) -> 121637.57
B58: T3.4 | C58: =SUM('Direct &Indirect Personnal Cost'!C20) -> 0 | D58: =SUM('Direct &Indirect Personnal Cost'!E20) -> 26750
B59: T3.5 | C59: =SUM('Direct &Indirect Personnal Cost'!C21) -> 0 | D59: =SUM('Direct &Indirect Personnal Cost'!E21) -> 3026750
B60: T3.6 | C60: =SUM('Direct &Indirect Personnal Cost'!C22) -> 6187.5 | D60: =SUM('Direct &Indirect Personnal Cost'!E22) -> 171950.02
B68: Task/WP | C68: TOTAL COST | D68: TOTAL BUDGET
B69: WP4 | C69: =SUM('Direct &Indirect Personnal Cost'!C23) -> 21789.228 | D69: =SUM('Direct &Indirect Personnal Cost'!E23) -> 701740.32
B70: T4.1 | C70: =SUM('Direct &Indirect Personnal Cost'!C24) -> 8330.8886 | D70: =SUM('Direct &Indirect Personnal Cost'!E24) -> 24218.75
B71: T4.2 | C71: =SUM('Direct &Indirect Personnal Cost'!C25) -> 5322.8375 | D71: =SUM('Direct &Indirect Personnal Cost'!E25) -> 170550.08
B72: T4.3 | C72: =SUM('Direct &Indirect Personnal Cost'!C26) -> 261.4 | D72: =SUM('Direct &Indirect Personnal Cost'!E26) -> 113875.05
B73: T4.4 | C73: =SUM('Direct &Indirect Personnal Cost'!C27) -> 0 | D73: =SUM('Direct &Indirect Personnal Cost'!E27) -> 70268.81
B74: T4.5 | C74: =SUM('Direct &Indirect Personnal Cost'!C28) -> 359.90748 | D74: =SUM('Direct &Indirect Personnal Cost'!E28) -> 114196.76
B75: T4.6 | C75: =SUM('Direct &Indirect Personnal Cost'!C29) -> 230.555 | D75: =SUM('Direct &Indirect Personnal Cost'!E29) -> 6925
B76: T4.7 | C76: =SUM('Direct &Indirect Personnal Cost'!C30) -> 798.075 | D76: =SUM('Direct &Indirect Personnal Cost'!E30) -> 54018.33
B77: T4.8 | C77: =SUM('Direct &Indirect Personnal Cost'!C31) -> 595.19468 | D77: =SUM('Direct &Indirect Personnal Cost'!E31) -> 53087.47
B78: T4.9 | C78: =SUM('Direct &Indirect Personnal Cost'!C32) -> 5748.05 | D78: =SUM('Direct &Indirect Personnal Cost'!E32) -> 94600.07
B83: Task/WP | C83: TOTAL COST | D83: TOTAL BUDGET
B84: WP5 | C84: =SUM('Direct &Indirect Personnal Cost'!C33) -> 42546.324 | D84: =SUM('Direct &Indirect Personnal Cost'!E33) -> 148095.23
B85: T5.1 | C85: =SUM('Direct &Indirect Personnal Cost'!C34) -> 40961.187 | D85: =SUM('Direct &Indirect Personnal Cost'!E34) -> 55221.35
B86: T5.2 | C86: =SUM('Direct &Indirect Personnal Cost'!C35) -> 771.5 | D86: =SUM('Direct &Indirect Personnal Cost'!E35) -> 55221.35
B87: T5.3 | C87: =SUM('Direct &Indirect Personnal Cost'!C36) -> 796.20625 | D87: =SUM('Direct &Indirect Personnal Cost'!E36) -> 37652.53
B98: Task/WP | C98: TOTAL COST | D98: TOTAL BUDGET
B99: WP6 | C99: =SUM('Direct &Indirect Personnal Cost'!C37) -> 56406.84 | D99: =SUM('Direct &Indirect Personnal Cost'!E37) -> 231218.95
B100: T6.1 | C100: =SUM('Direct &Indirect Personnal Cost'!C38) -> 39381.405 | D100: =SUM('Direct &Indirect Personnal Cost'!E38) -> 55825.06
B101: T6.2 | C101: =SUM('Direct &Indirect Personnal Cost'!C39) -> 10860.063 | D101: =SUM('Direct &Indirect Personnal Cost'!E39) -> 108168.84
B102: T6.3 | C102: =SUM('Direct &Indirect Personnal Cost'!C40) -> 1066.5956 | D102: =SUM('Direct &Indirect Personnal Cost'!E40) -> 67225.05
...

Sheet PM Efforth per Task
G1: B1 | H1: B2 | I1: B3 | J1: B4 | K1: B5 | L1: B6 | M1: B7 | N1: B8 | O1: B9 | P1: B10 | Q1: B11 | R1: B12
B2: No | C2: Work Packages (WP) & Tasks (T) | D2: Lead | E2: Start | F2: End | G2: MNU | H2: FOC | I2: CTLV | J2: CKR | K2: MAI | L2: BIN | M2: IOC | N2: HIE | O2: MCN | P2: MEERI | Q2: SCA | R2: BAL | S2: TOTAL PMs | T2: =T3+T7+T12+T19+T29+T33+T37 -> 1
B3: WP1 | C3: Assessment of potential new value chains and selection of Topics for Call of Proposals | D3: MEERI | E3: 1 | F3: 6 | G3: =SUM( G4:G6) -> 1.5 | H3: =SUM(H4:H6) -> 2.25 | I3: =SUM(I4:I6) -> 2.25 | J3: =SUM(J4:J6) -> 3.25 | K3: =SUM(K4:K6) -> 3.25 | L3: =SUM(L4:L6) -> 3.25 | M3: =SUM(M4:M6) -> 1.5 | N3: =SUM(N4:N6) -> 2.25 | O3: =SUM(O4:O6) -> 1.5 | ... R3: =SUM(R4:R6) -> 1 | S3: =SUM(G3:R3) -> 26.75 | T3: =S3/ S$41 -> 0.12022472
B4: T1.1 | C4: Sustainable challenges, needs and trends of four industrial offshore sectors | D4: HIE | E4: 1 | F4: 3 | G4: 1 | H4: 1 | I4: 0.25 | J4: 0.25 | K4: 0.25 | L4: 0.25 | M4: 1 | N4: 1.75 | O4: 1 | P4: 0 | Q4: 0.5 | R4: 0.5 | S4: =SUM(G4:R4) -> 7.75
B5: T1.2 | C5: Assessment of emerging technology trends and solutions | D5: MEERI | E5: 1 | F5: 4 | G5: 0.25 | H5: 0.25 | I5: 1 | J5: 1 | K5: 1 | L5: 1 | M5: 0.25 | N5: 0.25 | O5: 0.25 | P5: 1.75 | Q5: 0.25 | R5: 0.25 | S5: =SUM(G5:R5) -> 7.5
B6: T1.3 | C6: Potential new value chains and selection of Call Topics | D6: MEERI | E6: 3 | F6: 6 | G6: 0.25 | H6: 1 | I6: 1 | J6: 2 | K6: 2 | L6: 2 | M6: 0.25 | N6: 0.25 | O6: 0.25 | P6: 2 | Q6: 0.25 | R6: 0.25 | S6: =SUM(G6:R6) -> 11.5
B7: WP2 | C7: Methodologies and tools for cross-sectoral/-border collaboration and technology transfer | D7: HIE | E7: 1 | F7: 36 | G7: =SUM(G8:G11) -> 0.5 | H7: =SUM(H8:H11) -> 2.5 | I7: =SUM(I8:I11) -> 2.5 | J7: =SUM(J8:J11) -> 2 | K7: =SUM(K8:K11) -> 0.5 | L7: =SUM(L8:L11) -> 0.5 | M7: =SUM(M8:M11) -> 0.5 | N7: =SUM(N8:N11) -> 3.5 | ... S7: =SUM(S8:S11) -> 17.75 | T7: =S7/ S$41 -> 0.079775281
B8: T2.1 | C8: Methologies and tools for cross-sectoral/-border collaboration and technology transfer | D8: HIE | E8: 1 | F8: 36 | G8: 0.25 | H8: 1.25 | I8: 1.25 | J8: 0.75 | K8: 0.25 | L8: 0.25 | M8: 0.25 | N8: 3.25 | O8: 0.25 | P8: 0.25 | Q8: 0.25 | R8: 0 | S8: =SUM(G8:R8) -> 8.25
B9: T2.2 | C9: Establishment of a Collaborative Virtual Environment | D9: MNU | E9: 1 | F9: 36 | G9: 0.25 | H9: 0 | I9: 0 | J9: 0 | K9: 0 | L9: 0 | M9: 0 | N9: 0 | O9: 0 | P9: 0 | Q9: 0 | R9: 0 | S9: =SUM(G9:R9) -> 0.25
B10: T2.3 | C10: Establishment of a Survey tool | D10: CKR | E10: 1 | F10: 36 | G10: 0 | H10: 1 | I10: 1 | J10: 1 | K10: 0 | L10: 0 | M10: 0 | N10: 0 | O10: 0 | P10: 0 | Q10: 0 | R10: 0 | S10: =SUM(G10:R10) -> 3
B11: T2.4 | C11: Establishment of the GreenOffshoreTech Cluster Collaboration Platform | D11: BAL | E11: 1 | F11: 36 | G11: 0 | H11: 0.25 | I11: 0.25 | J11: 0.25 | K11: 0.25 | L11: 0.25 | M11: 0.25 | N11: 0.25 | O11: 0.25 | P11: 0.25 | Q11: 0.25 | R11: 3.75 | S11: =SUM(G11:R11) -> 6.25
B12: WP3 | C12: Direct financial support to SMEs through a competitive Call for Proposals | D12: CKR | E12: 1 | F12: 36 | G12: =SUM(G13:G18) -> 7 | H12: =SUM(H13:H18) -> 2.5 | I12: =SUM(I13:I18) -> 3.5 | J12: =SUM(J13:J18) -> 6 | K12: =SUM(K13:K18) -> 3.5 | L12: =SUM(L13:L18) -> 3.5 | M12: =SUM(M13:M18) -> 2.5 | N12: =SUM(N13:N18) -> 2.5 | ... S12: =SUM(S13:S18) -> 45.5 | T12: =S12/ S$41 -> 0.20449438
B13: T3.1 | C13: Preparation of the Call for Proposals | D13: CKR | E13: 1 | F13: 7 | G13: 0.5 | H13: 0.5 | I13: 0.5 | J13: 3 | K13: 0.5 | L13: 0.5 | M13: 0.5 | N13: 0.5 | O13: 0.5 | P13: 0.5 | Q13: 0.5 | R13: 0.5 | S13: =SUM(G13:R13) -> 8.5
B14: T3.2 | C14: Publication of the Call for Proposals and Proposal reception. | D14: BAL | E14: 8 | F14: 18 | G14: 0.5 | H14: 0 | I14: 0 | J14: 0 | K14: 0 | L14: 0 | M14: 0 | N14: 0 | O14: 0 | P14: 0 | Q14: 0 | R14: 1 | S14: =SUM(G14:R14) -> 1.5
B15: T3.3 | C15: Evaluation and Selection of SMEs Proposals | D15: BAL | E15: 11 | F15: 20 | G15: 1 | H15: 1 | I15: 1 | J15: 1 | K15: 1 | L15: 1 | M15: 1 | N15: 1 | O15: 1 | P15: 1 | Q15: 1 | R15: 1.5 | S15: =SUM(G15:R15) -> 12.5
B16: T3.4 | C16: Contracting with winner SMEs Projects | D16: MNU | E16: 13 | F16: 22 | G16: 2 | H16: 0 | I16: 0 | J16: 0 | K16: 0 | L16: 0 | M16: 0 | N16: 0 | O16: 0 | P16: 0 | Q16: 0 | R16: 0 | S16: =SUM(G16:R16) -> 2
B17: T3.5 | C17: Payments and financial monitoring of winner SMEs Projects | D17: MNU | E17: 13 | F17: 36 | G17: 2 | H17: 0 | I17: 0 | J17: 0 | K17: 0 | L17: 0 | M17: 0 | N17: 0 | O17: 0 | P17: 0 | Q17: 0 | R17: 0 | S17: =SUM(G17:R17) -> 2
B18: T3.6 | C18: Technical monitoring of winner SMEs Projects | D18: SCA | E18: 13 | F18: 36 | G18: 1 | H18: 1 | I18: 2 | J18: 2 | K18: 2 | L18: 2 | M18: 1 | N18: 1 | O18: 1 | P18: 2 | Q18: 3 | R18: 1 | S18: =SUM(G18:R18) -> 19
B19: WP4 | C19: Business Support Services to winner SMEs | D19: MAI | E19: 1 | F19: 36 | G19: =SUM(G20:G28) -> 5.5 | H19: =SUM(H20:H28) -> 8.5 | I19: =SUM(I20:I28) -> 7 | J19: =SUM(J20:J28) -> 3 | K19: =SUM(K20:K28) -> 8 | L19: =SUM(L20:L28) -> 9 | M19: =SUM(M20:M28) -> 3 | N19: =SUM(N20:N28) -> 7 | ... S19: =SUM(S20:S28) -> 74.75 | T19: =S19/ S$41 -> 0.33595506
B20: T4.1 | C20: Programme of Business Support Services to winner SMEs | D20: MAI | E20: 1 | F20: 36 | G20: 0 | H20: 0 | I20: 0 | J20: 0 | K20: 2.5 | L20: 0 | M20: 0 | N20: 0 | O20: 0 | P20: 0 | Q20: 0 | R20: 0 | S20: =SUM(G20:R20) -> 2.5
B21: T4.2 | C21: Business Support Service #1 Business & Tech Academy | D21: MAI | E21: 1 | F21: 24 | G21: 1 | H21: 1 | I21: 1 | J21: 1 | K21: 3 | L21: 3.5 | M21: 1 | N21: 1 | O21: 1 | P21: 1.5 | Q21: 1 | R21: 1.5 | S21: =SUM(G21:R21) -> 17.5
B22: T4.3 | C22: Business Support Service #2 Brokerage & B2B matchmaking events | D22: CMAB | E22: 1 | F22: 24 | G22: 0.5 | H22: 4 | I22: 0.5 | J22: 0.5 | K22: 1 | L22: 4 | M22: 0.5 | N22: 0.5 | O22: 0.5 | P22: 0.5 | Q22: 0.5 | R22: 0.5 | S22: =SUM(G22:R22) -> 13.5
B23: T4.4 | C23: Business Support Service #3 Access to Finance | D23: HIE | E23: 1 | F23: 24 | G23: 0.5 | H23: 0.5 | I23: 0.5 | J23: 0.5 | K23: 0.5 | L23: 0.5 | M23: 0.5 | N23: 3 | O23: 0.5 | P23: 0 | Q23: 0 | R23: 0 | S23: =SUM(G23:R23) -> 7
B24: T4.5 | C24: Business Support Service #4 One-to-One Mentoring and Coaching | D24: SCA | E24: 1 | F24: 32 | G24: 0 | H24: 0 | I24: 0 | J24: 0 | K24: 0 | L24: 0 | M24: 0 | N24: 0 | O24: 0 | P24: 0 | Q24: 9.75 | R24: 0 | S24: =SUM(G24:R24) -> 9.75
B25: T4.6 | C25: Business Support Service #5 Branding | D25: FOC | E25: 1 | F25: 32 | G25: 0 | H25: 2 | I25: 0 | J25: 0 | K25: 0 | L25: 0 | M25: 0 | N25: 0 | O25: 0 | P25: 0 | Q25: 0 | R25: 0 | S25: =SUM(G25:R25) -> 2
B26: T4.7 | C26: Business Support Service #6 Internationalisation | D26: MCN | E26: 1 | F26: 32 | G26: 0.5 | H26: 0.5 | I26: 0.5 | J26: 0.5 | K26: 0.5 | L26: 0.5 | M26: 0.5 | N26: 0.5 | O26: 2 | P26: 0 | Q26: 0 | R26: 0 | S26: =SUM(G26:R26) -> 6
B27: T4.8 | C27: Business Support Service #7 Investor pitching | D27: CTLV | E27: 1 | F27: 32 | G27: 0.5 | H27: 0 | I27: 4 | J27: 0 | K27: 0 | L27: 0 | M27: 0 | N27: 1.5 | O27: 0 | P27: 0 | Q27: 1 | R27: 0 | S27: =SUM(G27:R27) -> 7
B28: T4.9 | C28: Business Support Service #8 Investor rounds | D28: MNU | E28: 1 | F28: 32 | G28: 2.5 | H28: 0.5 | I28: 0.5 | J28: 0.5 | K28: 0.5 | L28: 0.5 | M28: 0.5 | N28: 0.5 | O28: 2 | P28: 0.5 | Q28: 0.5 | R28: 0.5 | S28: =SUM(G28:R28) -> 9.5
B29: WP5 | C29: Large-scale Demonstrator (LSD) setup, validation, and impact assessment | D29: SCA | E29: 1 | F29: 36 | G29: =SUM(G30:G32) -> 0.75 | H29: =SUM(H30:H32) -> 0.75 | I29: =SUM(I30:I32) -> 0.75 | J29: =SUM(J30:J32) -> 0.75 | K29: =SUM(K30:K32) -> 0.75 | L29: =SUM(L30:L32) -> 0.75 | M29: =SUM(M30:M32) -> 0.75 | N29: =SUM(N30:N32) -> 0.75 | ... S29: =SUM(S30:S32) -> 14.25 | T29: =S29/ S$41 -> 0.064044944
B30: T5.1 | C30: Set-up of the GreenOffshoreTech LSD in GreenOffshoreTech regions | D30: SCA | E30: 1 | F30: 36 | G30: 0.25 | H30: 0.25 | I30: 0.25 | J30: 0.25 | K30: 0.25 | L30: 0.25 | M30: 0.25 | N30: 0.25 | O30: 0.25 | P30: 0.25 | Q30: 2.5 | R30: 0.25 | S30: =SUM(G30:R30) -> 5.25
B31: T5.2 | C31: Validation & Impact assessment of GreenOffshoreTech LSD | D31: SCA | E31: 1 | F31: 36 | G31: 0.25 | H31: 0.25 | I31: 0.25 | J31: 0.25 | K31: 0.25 | L31: 0.25 | M31: 0.25 | N31: 0.25 | O31: 0.25 | P31: 0.25 | Q31: 2.5 | R31: 0.25 | S31: =SUM(G31:R31) -> 5.25
B32: T5.3 | C32: Guidelines of Best Practice to foster cross-sector/-border collaboration and technology transfer through Clusters | D32: SCA | E32: 35 | F32: 36 | G32: 0.25 | H32: 0.25 | I32: 0.25 | J32: 0.25 | K32: 0.25 | L32: 0.25 | M32: 0.25 | N32: 0.25 | O32: 0.25 | P32: 0.25 | Q32: 1 | R32: 0.25 | S32: =SUM(G32:R32) -> 3.75
B33: WP6 | C33: Communication, Dissemination, Exploitation & Sustainability | D33: FOC | E33: 1 | F33: 36 | G33: =SUM(G34:G36) -> 2 | H33: =SUM(H34:H36) -> 7.5 | I33: =SUM(I34:I36) -> 2 | J33: =SUM(J34:J36) -> 2 | K33: =SUM(K34:K36) -> 3 | L33: =SUM(L34:L36) -> 2 | M33: =SUM(M34:M36) -> 2 | N33: =SUM(N34:N36) -> 2 | ... S33: =SUM(S34:S36) -> 27.5 | T33: =S33/ S$41 -> 0.12359551
B34: T6.1 | C34: Communication plan and Communication activities | D34: FOC | E34: 1 | F34: 36 | G34: 0.5 | H34: 4 | I34: 0.5 | J34: 0.5 | K34: 0.5 | L34: 0.5 | M34: 0.5 | N34: 0.5 | O34: 0.5 | P34: 0 | Q34: 0 | R34: 0 | S34: =SUM(G34:R34) -> 8
B35: T6.2 | C35: Dissemination strategy and Dissemination activities | D35: FOC | E35: 1 | F35: 36 | G35: 1 | H35: 3 | I35: 1 | J35: 1 | K35: 1 | L35: 1 | M35: 1 | N35: 1 | O35: 1 | P35: 0.5 | Q35: 0.5 | R35: 0.5 | S35: =SUM(G35:R35) -> 12.5
B36: T6.3 | C36: Exploitation strategy, IPR and Sustainability | D36: MAI | E36: 1 | F36: 36 | G36: 0.5 | H36: 0.5 | I36: 0.5 | J36: 0.5 | K36: 1.5 | L36: 0.5 | M36: 0.5 | N36: 0.5 | O36: 0.5 | P36: 0.5 | Q36: 0.5 | R36: 0.5 | S36: =SUM(G36:R36) -> 7
B37: WP7 | C37: Project Management and Coordination | D37: MNU | E37: 1 | F37: 36 | G37: =SUM(G38:G40) -> 16 | H37: =SUM(H38:H40) -> 0 | I37: =SUM(I38:I40) -> 0 | J37: =SUM(J38:J40) -> 0 | K37: =SUM(K38:K40) -> 0 | L37: =SUM(L38:L40) -> 0 | M37: =SUM(M38:M40) -> 0 | N37: =SUM(N38:N40) -> 0 | ... S37: =SUM(S38:S40) -> 16 | T37: =S37/ S$41 -> 0.071910112
B38: T7.1 | C38: Project coordination | D38: MNU | E38: 1 | F38: 36 | G38: 11 | H38: 0 | I38: 0 | J38: 0 | K38: 0 | L38: 0 | M38: 0 | N38: 0 | O38: 0 | P38: 0 | Q38: 0 | R38: 0 | S38: =SUM(G38:R38) -> 11
B39: T7.2 | C39: Project administration & Financial Management | D39: MNU | E39: 1 | F39: 36 | G39: 3.5 | H39: 0 | I39: 0 | J39: 0 | K39: 0 | L39: 0 | M39: 0 | N39: 0 | O39: 0 | P39: 0 | Q39: 0 | R39: 0 | S39: =SUM(G39:R39) -> 3.5
B40: T7.3 | C40: Quality Assurance | D40: MNU | E40: 1 | F40: 36 | G40: 1.5 | H40: 0 | I40: 0 | J40: 0 | K40: 0 | L40: 0 | M40: 0 | N40: 0 | O40: 0 | P40: 0 | Q40: 0 | R40: 0 | S40: =SUM(G40:R40) -> 1.5
...

Sheet Efforth per task PM
F1: B1 | G1: B2 | H1: B3 | I1: B4 | J1: B5 | K1: B6 | L1: B7 | M1: B8 | N1: B9 | O1: B10 | P1: B11 | Q1: B12
A2: No | B2: Work Packages (WP) & Tasks (T) | C2: Lead | D2: Start | E2: End | F2: MNU | G2: FOC | H2: CTLV | I2: CKR | J2: MAI | K2: BIN | L2: IOC | M2: HIE | N2: MCN | O2: MEERI | P2: SCA | Q2: BAL | R2: TOTAL PMs | S2: =S3+S7+S12+S19+S29+S33+S37 -> 1
A3: WP1 | B3: Assessment of potential new value chains and selection of Topics for Call of Proposals | C3: MEERI | D3: 1 | E3: 6 | F3: =SUM( F4:F6) -> 1.5 | G3: =SUM(G4:G6) -> 2.25 | H3: =SUM(H4:H6) -> 2.25 | I3: =SUM(I4:I6) -> 3.25 | J3: =SUM(J4:J6) -> 3.25 | K3: =SUM(K4:K6) -> 3.25 | L3: =SUM(L4:L6) -> 1.5 | M3: =SUM(M4:M6) -> 2.25 | N3: =SUM(N4:N6) -> 1.5 | ... Q3: =SUM(Q4:Q6) -> 1 | R3: =SUM(F3:Q3) -> 26.75 | S3: =R3/ R$41 -> 0.12022472
A4: T1.1 | B4: Sustainable challenges, needs and trends of four industrial offshore sectors | C4: HIE | D4: 1 | E4: 3 | F4: 1 | G4: 1 | H4: 0.25 | I4: 0.25 | J4: 0.25 | K4: 0.25 | L4: 1 | M4: 1.75 | N4: 1 | O4: 0 | P4: 0.5 | Q4: 0.5 | R4: =SUM(F4:Q4) -> 7.75
A5: T1.2 | B5: Assessment of emerging technology trends and solutions | C5: MEERI | D5: 1 | E5: 4 | F5: 0.25 | G5: 0.25 | H5: 1 | I5: 1 | J5: 1 | K5: 1 | L5: 0.25 | M5: 0.25 | N5: 0.25 | O5: 1.75 | P5: 0.25 | Q5: 0.25 | R5: =SUM(F5:Q5) -> 7.5
A6: T1.3 | B6: Potential new value chains and selection of Call Topics | C6: MEERI | D6: 3 | E6: 6 | F6: 0.25 | G6: 1 | H6: 1 | I6: 2 | J6: 2 | K6: 2 | L6: 0.25 | M6: 0.25 | N6: 0.25 | O6: 2 | P6: 0.25 | Q6: 0.25 | R6: =SUM(F6:Q6) -> 11.5
A7: WP2 | B7: Methodologies and tools for cross-sectoral/-border collaboration and technology transfer | C7: HIE | D7: 1 | E7: 36 | F7: =SUM(F8:F11) -> 0.5 | G7: =SUM(G8:G11) -> 2.5 | H7: =SUM(H8:H11) -> 2.5 | I7: =SUM(I8:I11) -> 2 | J7: =SUM(J8:J11) -> 0.5 | K7: =SUM(K8:K11) -> 0.5 | L7: =SUM(L8:L11) -> 0.5 | M7: =SUM(M8:M11) -> 3.5 | ... R7: =SUM(R8:R11) -> 17.75 | S7: =R7/ R$41 -> 0.079775281
A8: T2.1 | B8: Methologies and tools for cross-sectoral/-border collaboration and technology transfer | C8: HIE | D8: 1 | E8: 36 | F8: 0.25 | G8: 1.25 | H8: 1.25 | I8: 0.75 | J8: 0.25 | K8: 0.25 | L8: 0.25 | M8: 3.25 | N8: 0.25 | O8: 0.25 | P8: 0.25 | Q8: 0 | R8: =SUM(F8:Q8) -> 8.25
A9: T2.2 | B9: Establishment of a Collaborative Virtual Environment | C9: MNU | D9: 1 | E9: 36 | F9: 0.25 | G9: 0 | H9: 0 | I9: 0 | J9: 0 | K9: 0 | L9: 0 | M9: 0 | N9: 0 | O9: 0 | P9: 0 | Q9: 0 | R9: =SUM(F9:Q9) -> 0.25
A10: T2.3 | B10: Establishment of a Survey tool | C10: CKR | D10: 1 | E10: 36 | F10: 0 | G10: 1 | H10: 1 | I10: 1 | J10: 0 | K10: 0 | L10: 0 | M10: 0 | N10: 0 | O10: 0 | P10: 0 | Q10: 0 | R10: =SUM(F10:Q10) -> 3
A11: T2.4 | B11: Establishment of the GreenOffshoreTech Cluster Collaboration Platform | C11: BAL | D11: 1 | E11: 36 | F11: 0 | G11: 0.25 | H11: 0.25 | I11: 0.25 | J11: 0.25 | K11: 0.25 | L11: 0.25 | M11: 0.25 | N11: 0.25 | O11: 0.25 | P11: 0.25 | Q11: 3.75 | R11: =SUM(F11:Q11) -> 6.25
A12: WP3 | B12: Direct financial support to SMEs through a competitive Call for Proposals | C12: CKR | D12: 1 | E12: 36 | F12: =SUM(F13:F18) -> 7 | G12: =SUM(G13:G18) -> 2.5 | H12: =SUM(H13:H18) -> 3.5 | I12: =SUM(I13:I18) -> 6 | J12: =SUM(J13:J18) -> 3.5 | K12: =SUM(K13:K18) -> 3.5 | L12: =SUM(L13:L18) -> 2.5 | M12: =SUM(M13:M18) -> 2.5 | ... R12: =SUM(R13:R18) -> 45.5 | S12: =R12/ R$41 -> 0.20449438
A13: T3.1 | B13: Preparation of the Call for Proposals | C13: CKR | D13: 1 | E13: 7 | F13: 0.5 | G13: 0.5 | H13: 0.5 | I13: 3 | J13: 0.5 | K13: 0.5 | L13: 0.5 | M13: 0.5 | N13: 0.5 | O13: 0.5 | P13: 0.5 | Q13: 0.5 | R13: =SUM(F13:Q13) -> 8.5
A14: T3.2 | B14: Publication of the Call for Proposals and Proposal reception. | C14: BAL | D14: 8 | E14: 18 | F14: 0.5 | G14: 0 | H14: 0 | I14: 0 | J14: 0 | K14: 0 | L14: 0 | M14: 0 | N14: 0 | O14: 0 | P14: 0 | Q14: 1 | R14: =SUM(F14:Q14) -> 1.5
A15: T3.3 | B15: Evaluation and Selection of SMEs Proposals | C15: BAL | D15: 11 | E15: 20 | F15: 1 | G15: 1 | H15: 1 | I15: 1 | J15: 1 | K15: 1 | L15: 1 | M15: 1 | N15: 1 | O15: 1 | P15: 1 | Q15: 1.5 | R15: =SUM(F15:Q15) -> 12.5
A16: T3.4 | B16: Contracting with winner SMEs Projects | C16: MNU | D16: 13 | E16: 22 | F16: 2 | G16: 0 | H16: 0 | I16: 0 | J16: 0 | K16: 0 | L16: 0 | M16: 0 | N16: 0 | O16: 0 | P16: 0 | Q16: 0 | R16: =SUM(F16:Q16) -> 2
A17: T3.5 | B17: Payments and financial monitoring of winner SMEs Projects | C17: MNU | D17: 13 | E17: 36 | F17: 2 | G17: 0 | H17: 0 | I17: 0 | J17: 0 | K17: 0 | L17: 0 | M17: 0 | N17: 0 | O17: 0 | P17: 0 | Q17: 0 | R17: =SUM(F17:Q17) -> 2
A18: T3.6 | B18: Technical monitoring of winner SMEs Projects | C18: SCA | D18: 13 | E18: 36 | F18: 1 | G18: 1 | H18: 2 | I18: 2 | J18: 2 | K18: 2 | L18: 1 | M18: 1 | N18: 1 | O18: 2 | P18: 3 | Q18: 1 | R18: =SUM(F18:Q18) -> 19
A19: WP4 | B19: Business Support Services to winner SMEs | C19: MAI | D19: 1 | E19: 36 | F19: =SUM(F20:F28) -> 5.5 | G19: =SUM(G20:G28) -> 8.5 | H19: =SUM(H20:H28) -> 7 | I19: =SUM(I20:I28) -> 3 | J19: =SUM(J20:J28) -> 8 | K19: =SUM(K20:K28) -> 9 | L19: =SUM(L20:L28) -> 3 | M19: =SUM(M20:M28) -> 7 | ... R19: =SUM(R20:R28) -> 74.75 | S19: =R19/ R$41 -> 0.33595506
A20: T4.1 | B20: Programme of Business Support Services to winner SMEs | C20: MAI | D20: 1 | E20: 36 | F20: 0 | G20: 0 | H20: 0 | I20: 0 | J20: 2.5 | K20: 0 | L20: 0 | M20: 0 | N20: 0 | O20: 0 | P20: 0 | Q20: 0 | R20: =SUM(F20:Q20) -> 2.5
A21: T4.2 | B21: Business Support Service #1 Business & Tech Academy | C21: MAI | D21: 1 | E21: 24 | F21: 1 | G21: 1 | H21: 1 | I21: 1 | J21: 3 | K21: 3.5 | L21: 1 | M21: 1 | N21: 1 | O21: 1.5 | P21: 1 | Q21: 1.5 | R21: =SUM(F21:Q21) -> 17.5
A22: T4.3 | B22: Business Support Service #2 Brokerage & B2B matchmaking events | C22: CMAB | D22: 1 | E22: 24 | F22: 0.5 | G22: 4 | H22: 0.5 | I22: 0.5 | J22: 1 | K22: 4 | L22: 0.5 | M22: 0.5 | N22: 0.5 | O22: 0.5 | P22: 0.5 | Q22: 0.5 | R22: =SUM(F22:Q22) -> 13.5
A23: T4.4 | B23: Business Support Service #3 Access to Finance | C23: HIE | D23: 1 | E23: 24 | F23: 0.5 | G23: 0.5 | H23: 0.5 | I23: 0.5 | J23: 0.5 | K23: 0.5 | L23: 0.5 | M23: 3 | N23: 0.5 | O23: 0 | P23: 0 | Q23: 0 | R23: =SUM(F23:Q23) -> 7
A24: T4.5 | B24: Business Support Service #4 One-to-One Mentoring and Coaching | C24: SCA | D24: 1 | E24: 32 | F24: 0 | G24: 0 | H24: 0 | I24: 0 | J24: 0 | K24: 0 | L24: 0 | M24: 0 | N24: 0 | O24: 0 | P24: 9.75 | Q24: 0 | R24: =SUM(F24:Q24) -> 9.75
A25: T4.6 | B25: Business Support Service #5 Branding | C25: FOC | D25: 1 | E25: 32 | F25: 0 | G25: 2 | H25: 0 | I25: 0 | J25: 0 | K25: 0 | L25: 0 | M25: 0 | N25: 0 | O25: 0 | P25: 0 | Q25: 0 | R25: =SUM(F25:Q25) -> 2
A26: T4.7 | B26: Business Support Service #6 Internationalisation | C26: MCN | D26: 1 | E26: 32 | F26: 0.5 | G26: 0.5 | H26: 0.5 | I26: 0.5 | J26: 0.5 | K26: 0.5 | L26: 0.5 | M26: 0.5 | N26: 2 | O26: 0 | P26: 0 | Q26: 0 | R26: =SUM(F26:Q26) -> 6
A27: T4.8 | B27: Business Support Service #7 Investor pitching | C27: CTLV | D27: 1 | E27: 32 | F27: 0.5 | G27: 0 | H27: 4 | I27: 0 | J27: 0 | K27: 0 | L27: 0 | M27: 1.5 | N27: 0 | O27: 0 | P27: 1 | Q27: 0 | R27: =SUM(F27:Q27) -> 7
A28: T4.9 | B28: Business Support Service #8 Investor rounds | C28: MNU | D28: 1 | E28: 32 | F28: 2.5 | G28: 0.5 | H28: 0.5 | I28: 0.5 | J28: 0.5 | K28: 0.5 | L28: 0.5 | M28: 0.5 | N28: 2 | O28: 0.5 | P28: 0.5 | Q28: 0.5 | R28: =SUM(F28:Q28) -> 9.5
A29: WP5 | B29: Large-scale Demonstrator (LSD) setup, validation, and impact assessment | C29: SCA | D29: 1 | E29: 36 | F29: =SUM(F30:F32) -> 0.75 | G29: =SUM(G30:G32) -> 0.75 | H29: =SUM(H30:H32) -> 0.75 | I29: =SUM(I30:I32) -> 0.75 | J29: =SUM(J30:J32) -> 0.75 | K29: =SUM(K30:K32) -> 0.75 | L29: =SUM(L30:L32) -> 0.75 | M29: =SUM(M30:M32) -> 0.75 | ... R29: =SUM(R30:R32) -> 14.25 | S29: =R29/ R$41 -> 0.064044944
A30: T5.1 | B30: Set-up of the GreenOffshoreTech LSD in GreenOffshoreTech regions | C30: SCA | D30: 1 | E30: 36 | F30: 0.25 | G30: 0.25 | H30: 0.25 | I30: 0.25 | J30: 0.25 | K30: 0.25 | L30: 0.25 | M30: 0.25 | N30: 0.25 | O30: 0.25 | P30: 2.5 | Q30: 0.25 | R30: =SUM(F30:Q30) -> 5.25
A31: T5.2 | B31: Validation & Impact assessment of GreenOffshoreTech LSD | C31: SCA | D31: 1 | E31: 36 | F31: 0.25 | G31: 0.25 | H31: 0.25 | I31: 0.25 | J31: 0.25 | K31: 0.25 | L31: 0.25 | M31: 0.25 | N31: 0.25 | O31: 0.25 | P31: 2.5 | Q31: 0.25 | R31: =SUM(F31:Q31) -> 5.25
A32: T5.3 | B32: Guidelines of Best Practice to foster cross-sector/-border collaboration and technology transfer through Clusters | C32: SCA | D32: 35 | E32: 36 | F32: 0.25 | G32: 0.25 | H32: 0.25 | I32: 0.25 | J32: 0.25 | K32: 0.25 | L32: 0.25 | M32: 0.25 | N32: 0.25 | O32: 0.25 | P32: 1 | Q32: 0.25 | R32: =SUM(F32:Q32) -> 3.75
A33: WP6 | B33: Communication, Dissemination, Exploitation & Sustainability | C33: FOC | D33: 1 | E33: 36 | F33: =SUM(F34:F36) -> 2 | G33: =SUM(G34:G36) -> 7.5 | H33: =SUM(H34:H36) -> 2 | I33: =SUM(I34:I36) -> 2 | J33: =SUM(J34:J36) -> 3 | K33: =SUM(K34:K36) -> 2 | L33: =SUM(L34:L36) -> 2 | M33: =SUM(M34:M36) -> 2 | ... R33: =SUM(R34:R36) -> 27.5 | S33: =R33/ R$41 -> 0.12359551
A34: T6.1 | B34: Communication plan and Communication activities | C34: FOC | D34: 1 | E34: 36 | F34: 0.5 | G34: 4 | H34: 0.5 | I34: 0.5 | J34: 0.5 | K34: 0.5 | L34: 0.5 | M34: 0.5 | N34: 0.5 | O34: 0 | P34: 0 | Q34: 0 | R34: =SUM(F34:Q34) -> 8
A35: T6.2 | B35: Dissemination strategy and Dissemination activities | C35: FOC | D35: 1 | E35: 36 | F35: 1 | G35: 3 | H35: 1 | I35: 1 | J35: 1 | K35: 1 | L35: 1 | M35: 1 | N35: 1 | O35: 0.5 | P35: 0.5 | Q35: 0.5 | R35: =SUM(F35:Q35) -> 12.5
A36: T6.3 | B36: Exploitation strategy, IPR and Sustainability | C36: MAI | D36: 1 | E36: 36 | F36: 0.5 | G36: 0.5 | H36: 0.5 | I36: 0.5 | J36: 1.5 | K36: 0.5 | L36: 0.5 | M36: 0.5 | N36: 0.5 | O36: 0.5 | P36: 0.5 | Q36: 0.5 | R36: =SUM(F36:Q36) -> 7
A37: WP7 | B37: Project Management and Coordination | C37: MNU | D37: 1 | E37: 36 | F37: =SUM(F38:F40) -> 16 | G37: =SUM(G38:G40) -> 0 | H37: =SUM(H38:H40) -> 0 | I37: =SUM(I38:I40) -> 0 | J37: =SUM(J38:J40) -> 0 | K37: =SUM(K38:K40) -> 0 | L37: =SUM(L38:L40) -> 0 | M37: =SUM(M38:M40) -> 0 | ... R37: =SUM(R38:R40) -> 16 | S37: =R37/ R$41 -> 0.071910112
A38: T7.1 | B38: Project coordination | C38: MNU | D38: 1 | E38: 36 | F38: 11 | G38: 0 | H38: 0 | I38: 0 | J38: 0 | K38: 0 | L38: 0 | M38: 0 | N38: 0 | O38: 0 | P38: 0 | Q38: 0 | R38: =SUM(F38:Q38) -> 11
A39: T7.2 | B39: Project administration & Financial Management | C39: MNU | D39: 1 | E39: 36 | F39: 3.5 | G39: 0 | H39: 0 | I39: 0 | J39: 0 | K39: 0 | L39: 0 | M39: 0 | N39: 0 | O39: 0 | P39: 0 | Q39: 0 | R39: =SUM(F39:Q39) -> 3.5
A40: T7.3 | B40: Quality Assurance | C40: MNU | D40: 1 | E40: 36 | F40: 1.5 | G40: 0 | H40: 0 | I40: 0 | J40: 0 | K40: 0 | L40: 0 | M40: 0 | N40: 0 | O40: 0 | P40: 0 | Q40: 0 | R40: =SUM(F40:Q40) -> 1.5
...

Sheet MONITORING TABLE 75%
A2: INNOSUP 1: Monitoring Table 75% requirement
A3: version 23/03/2018
A4: Project: GreenOffshoreTech - GA 101005541
A5: Period covered: from project start date (01/09/2021) to 31/05/2022 - M1-M9 | B5: Deliverable D7.5
A7: ***Please read the instructions in Sheet 2 and look at the example in Sheet 3 before completing the table*** | J7: automatic filling
A9: Section 1 - Direct financial support to SMEs to support innovation | B9: Related WP task | C9: N° of beneficiary SMEs for country 1: (specify country) for period covered | D9: N° of beneficiary SMEs for country 2: (specify country) for period covered | E9: N° of beneficiary SMEs for country 3: (specify country) for period covered | F9: N° of beneficiary SMEs for country 4: (specify country) for period covered | G9: N° of beneficiary SMEs for country 5: (specify country) for period covered | H9: TOTAL n° of beneficiary SMEs for period covered | I9: TOTAL n° of beneficiary SMEs for whole project duration (target) | J9: (Average) cost per individual service (in €) | K9: Total costs for all beneficiary SMEs for period covered | L9: Total budget for all beneficiary SMEs for whole project duration (target) | M9: Beneficiaries: country distribution (for period covered) | N9: Partners involved (in period covered) | O9: Additional information
A10: CALL - cutoff 1: | B10: --- | H10: --- | I10: --- | J10: --- | K10: --- | L10: --- | M10: --- | N10: --- | O10: ---
A11: Direct funding (lump sums) - PHASE 1 | B11: T3.5 | H11: 0 | I11: 50 | J11: 5000 | K11: 0 | L11: =I11*J11 -> 250000 | M11: xx SMEs: 10x NO, 8x PL, 6x UK, etc | N11: MNU | O11: Payments done to SMEs.
A12: Direct funding (lump sums) - PHASE 2 | B12: T3.5 | H12: 0 | I12: 25 | J12: 45000 | K12: 0 | L12: =I12*J12 -> 1125000 | M12: xx SMEs: 5x NO, 4x PL, 3x UK, etc | N12: MNU | O12: Payments done to SMEs.
A13: Direct funding (lump sums) - PHASE 3 | B13: T3.5 | H13: 0 | I13: 12 | J13: 10000 | K13: 0 | L13: =I13*J13 -> 120000 | M13: xx SMEs: 1x NO, 1x PL, 1x UK, etc | N13: MNU | O13: Payments done to SMEs.
A14: CALL - cutoff 2: | B14: --- | H14: --- | I14: --- | J14: --- | K14: --- | L14: --- | M14: --- | N14: --- | O14: ---
A15: Direct funding (lump sums) - PHASE 1 | B15: T3.5 | H15: 0 | I15: 50 | J15: 5000 | K15: 0 | L15: =I15*J15 -> 250000 | M15: xx SMEs: 8x NO, 6x PL, 4x UK, etc | N15: MNU | O15: Payments done to SMEs.
A16: Direct funding (lump sums) - PHASE 2 | B16: T3.5 | H16: 0 | I16: 25 | J16: 45000 | K16: 0 | L16: =I16*J16 -> 1125000 | M16: xx SMEs: 4x NO, 3x PL, 2x UK, etc | N16: MNU | O16: Payments done to SMEs.
A17: Direct funding (lump sums) - PHASE 3 | B17: T3.5 | H17: 0 | I17: 13 | J17: 10000 | K17: 0 | L17: =I17*J17 -> 130000 | M17: xx SMEs: 1x NO, 1x PL, 1x UK, etc | N17: MNU | O17: Payments done to SMEs.
A18: Total amounts - section 1 | H18: =SUM(H10:H17) -> 0 | I18: =I11+I15 -> 100 | K18: =SUM(K10:K17) -> 0 | L18: =SUM(L10:L17) -> 3000000
A20: Total of unique SMEs directly assisted (section 1) | H20: =H11+H15 -> 0 | I20: =I11+I15 -> 100 | M20: xx SMEs: 18x NO, 14x PL, 10x UK, etc.
A22: Section 2 - Direct innovation support (non financial) to individual SMEs | B22: Related WP task | C22: N° of beneficiary SMEs for country 1: (specify country) for period covered | D22: N° of beneficiary SMEs for country 2: (specify country) for period covered | E22: N° of beneficiary SMEs for country 3: (specify country) for period covered | F22: N° of beneficiary SMEs for country 4: (specify country) for period covered | G22: N° of beneficiary SMEs for country 5: (specify country) for period covered | H22: TOTAL n° of beneficiary SMEs for period covered | I22: TOTAL n° of beneficiary SMEs for whole project duration (target) | J22: (Average) cost per individual service (in €) | K22: Total costs for all beneficiary SMEs for period covered | L22: Total budget for all beneficiary SMEs for whole project duration (target) | M22: Beneficiaries: country distribution (for period covered) | N22: Partners involved (in period covered) | O22: Additional information
A23: CALL - cutoff 1+2: | B23: --- | H23: --- | I23: --- | J23: --- | K23: --- | L23: --- | M23: --- | N23: --- | O23: ---
A24: Delivery of Business Support Service #1 Business & Tech Academy | B24: T4.2 | H24: 0 | I24: 100 | K24: 0 | L24: 104189 | M24: xx SMEs: 18x NO, 14x PL, 10x UK, etc. | N24: MAI (lead), MNU, FOC, CTLV, CKR, CMAB, IOC, HIE, MCN, MEERI, SCA, BAL | O24: Staff costs (direct + indirect)
A25: Delivery of Business Support Service #2 Brokerage & B2B matchmaking events | B25: T4.3 | H25: 0 | I25: 100 | K25: 0 | L25: 81036 | M25: xx SMEs: 18x NO, 14x PL, 10x UK, etc. | N25: CMAB (lead), MNU, FOC, CTLV, CKR, CMAB, IOC, HIE, MCN, MEERI, SCA, BAL | O25: Staff costs (direct + indirect)
A26: Delivery of Business Support Service #3 Access to Finance | B26: T4.4 | H26: 0 | I26: 100 | K26: 0 | L26: 43412 | M26: xx SMEs: 18x NO, 14x PL, 10x UK, etc. | N26: HIE (lead), MNU, FOC, CTLV, CKR, MAI, CMAB, IOC, HIE, MCN | O26: Staff costs (direct + indirect)
A27: Delivery of Business Support Service #4 One-to-One Mentoring and Coaching | B27: T4.5 | H27: 0 | I27: 50 | K27: 0 | L27: 59330 | M27: xx SMEs: 9x NO, 7x PL, 5x UK, etc. | N27: SCA (lead) | O27: Staff costs (direct + indirect)
A28: Delivery of Business Support Service #5 Branding | B28: T4.6 | H28: 0 | I28: 50 | K28: 0 | L28: 14471 | M28: xx SMEs: 9x NO, 7x PL, 5x UK, etc. | N28: FOC (lead) | O28: Staff costs (direct + indirect)
A29: Delivery of Business Support Service #6 Internationalisation | B29: T4.7 | H29: 0 | I29: 50 | K29: 0 | L29: 34730 | M29: xx SMEs: 9x NO, 7x PL, 5x UK, etc. | N29: MCN (lead), MNU, FOC, CTLV, CKR, MAI, CMAB, IOC, HIE | O29: Staff costs (direct + indirect)
A30: Delivery of Business Support Service #7 Investor pitching | B30: T4.8 | H30: 0 | I30: 50 | K30: 0 | L30: 40518 | M30: xx SMEs: 9x NO, 7x PL, 5x UK, etc. | N30: CTLV (lead), MNU, HIE, SCA | O30: Staff costs (direct + indirect)
A31: Delivery of Business Support Service #8 Investor rounds | B31: T4.9 | H31: 0 | I31: 50 | K31: 0 | L31: 54989 | M31: xx SMEs: 9x NO, 7x PL, 5x UK, etc. | N31: MNU (lead), FOC, CTLV, CKR, MAI, CMAB, IOC, HIE, MCN, MEERI, SCA, BAL | O31: Staff costs (direct + indirect)
A32: Total amounts - section 2 | H32: =SUM(H23:H31) -> 0 | I32: =I24 -> 100 | K32: =SUM(K23:K31) -> 0 | L32: =SUM(L23:L31) -> 432675
A34: Total of unique SMEs directly assisted (section 2) | H34: =H24 -> 0 | I34: =I24 -> 100 | M34: xx SMEs: 18x NO, 14x PL, 10x UK, etc.
A36: Total of unique SMEs directly assisted (sections 1 + 2) | H36: =H20 -> 0 | I36: =I20 -> 100 | M36: xx SMEs: 18x NO, 14x PL, 10x UK, etc.
A38: Section 3 - other innovation services provided to SMEs | B38: Related WP task | H38: TOTAL n° of SMEs for period covered | I38: TOTAL n° of SMEs for whole project duration (target) | K38: Total costs for period covered | L38: Total budget for whole project duration (target) | M38: Number of services (for period covered) | N38: Partners involved (in period covered) | O38: Additional information
A39: Virtual Brockerage Event (?) | B39: T6.2 | H39: 0 | I39: 100 | J39: --- | K39: 0 | L39: 0 | M39: 1x virtual brockerage event | N39: FOC (lead), MNU, CTLV, CKR, MAI, CMAB, IOC, HIE, MCN, MEERI, SCA, BAL | O39: ---
A40: --- | B40: --- | H40: --- | I40: --- | J40: --- | K40: --- | L40: --- | M40: --- | N40: --- | O40: ---
A41: --- | B41: --- | H41: --- | I41: --- | J41: --- | K41: --- | L41: --- | M41: --- | N41: --- | O41: ---
A43: Total amounts - section 3 | H43: =SUM(H37:H42) -> 0 | I43: =SUM(I37:I42) -> 100 | K43: =SUM(K37:K42) -> 0 | L43: =SUM(L37:L42) -> 0
A45: Section 4 - costs for preparation / management / monitoring of services in other sections | B45: Related WP task | H45: --- | I45: --- | J45: --- | K45: Total costs for period covered | L45: Total budget for whole project duration (target) | M45: --- | N45: Partners involved (in period covered) | O45: Additional information
A46: Costs for preparation/ management/ monitoring of services in Section 1+2: | B46: --- | H46: --- | I46: --- | J46: --- | K46: --- | L46: --- | M46: --- | N46: --- | O46: ---
A47: Costs for preparation of the Topics for the Call for Proposals | B47: T1.1, T1.2, T1.3 | H47: --- | I47: --- | J47: --- | K47: 110616 | L47: 213716 | M47: --- | N47: MEERI (lead), HIE (lead), MNU, FOC, CTLV, CKR, MAI, CMAB, IOC, MCN, SCA, BAL | O47: Staff costs (direct + indirect)
A48: Cost for preparation of the Cluster Collaboration Platform for managing the open Call, the development of the new Virtual Matchmaking tool, and the estbalishment of a Virtual Collaboration Environment | B48: T2.1, T2.2, T2.3, T2.4 | H48: --- | I48: --- | J48: --- | K48: 67975 | L48: 145038 | M48: --- | N48: HIE (lead), BAL (lead), CKR (lead), MNU, FOC, CTLV, MAI, CMAB, IOC, MCN, SCA | O48: Staff costs (direct + indirect)
A49: Costs for preparation, evaluation and monitoring of the Call for Proposals and the winner SMEs Projects | B49: T3.1, T3.2, T3.3, T3.4, T3.5, T3.6 | H49: --- | I49: --- | J49: --- | K49: 87880 | L49: 423719 | M49: --- | N49: CKR (lead), BAL (lead), MNU (lead), SCA (lead), FOC, CTLV, MAI, CMAB, ICO, HIE, MCN, MEERI | O49: Staff costs (direct + indirect)
A50: Costs for preparation and monitoring of the Business Support Services | B50: T4.1, T4.2, T4.3, T4.4, T4.5, T4.6, T4.7, T4.8, T4.9 | H50: --- | I50: --- | J50: --- | K50: 21953 | L50: 332827 | M50: --- | N50: MAI (lead), MNU (lead), FOC (lead), CTLV(lead), CMAB (lead), HIE (lead), MCN (lead), SCA (lead), IOC, CKR, MEERI, BAL | O50: Staff costs (direct + indirect)
...

Sheet Direct &Indirect Personnal Cost
A2: ALL DIRECT & INDIRECT COST CALCULATIONS PER PARTNER | AA2: 7266
A3: TOTAL BUDGET IS NOT EQUAL TO EC CONTRIBUTION DUE TO THE SME PARTNERS
A4: 70%. Delivered Hourly cost estimate and Budget allocation.
A5: GreenOfshoreTech TOTAL (Period M1 to M9) | B5: Task/ WP | C5: TOTAL COST | D5: Other Dir. Cost Budget | E5: TOTAL BUDGET | F5: % spend | G5: MNU COST | H5: Other Dir. Cost Budget | J5: % spend | K5: SCA COST | L5: Other Dir. Cost Budget | M5: SCA BUDGET | N5: % spend | O5: FOC COST | P5: Other Dir. Cost Budget | Q5: FOC BUDGET | R5: % spend | S5: CTLV COST | T5: Other Dir. Cost Budget | U5: CTLV BUDGET | V5: % spend | W5: MAI COST | X5: Other Dir. Cost | Y5: Revised MAI BUDGET | Z5: MAI BUDGET | AA5: % spend | AB5: BIN COST | AC5: Other Dir. Cost | AD5: BIN BUDGET | AE5: % spend | AF5: IOC COST | AG5: Other Dir. Cost | AH5: IOC BUDGET | AI5: % spend | AJ5: HIE COST | AK5: Other Dir. Cost | AL5: HIE BUDGET | AM5: % spend | AN5: BAL COST | AO5: Other Dir. Cost | AP5: BAL BUDGET | AQ5: % spend | AR5: MEERI COST | AS5: Other Dir. Cost | AT5: MEERI BUDGET | AU5: % spend | AV5: MCN COST | AW5: Other Dir. Cost | AX5: MCN BUDGET | AY5: % spend | AZ5: CKR COST | BA5: Other Dir. Cost | BB5: CKR BUDGET | BC5: % spend
A6: Otherdirect Cost ( travel, equipment & Other goods and services)(ODC) | B6: ODC | C6: =SUM(G6+K6+O6+S6+W6+AB6+AF6+AJ6+AN6+AR6+AV6+AZ6) -> 5763.75 | E6: =SUM(I6+M6+Q6+U6+Z6+AD6+AH6+AL6+AP6+AT6+AX6+BB6) -> 343929 | F6: =100/E6*C6 -> 1.6758546 | G6: 0 | I6: 39500 | J6: =100/I6*G6 -> 0 | K6: 0 | M6: 20750 | N6: =100/M6*K6 -> 0 | O6: 0 | Q6: 42500 | R6: =100/Q6*O6 -> 0 | S6: 0 | U6: 20750 | V6: =100/U6*S6 -> 0 | W6: 0 | Y6: 20750 | Z6: 20750 | AA6: =100/Z6*W6 -> 0 | AB6: 0 | AD6: 56429 | AE6: =100/AD6*AB6 -> 0 | AF6: =SUM(IOC!K9) -> 0 | AH6: 20750 | AI6: =100/AH6*AF6 -> 0 | AJ6: =SUM(HIE!L9) -> 5763.75 | AL6: 20750 | AM6: =100/AL6*AJ6 -> 27.777108 | AN6: 0 | AP6: 20750 | AQ6: =100/AP6*AN6 -> 0 | AR6: 0 | AT6: =SUM(MEERI!M1*MEERI!$O$1) -> 20750 | AU6: =100/AT6*AR6 -> 0 | AV6: 0 | AX6: =SUM(MCN!V1*MCN!$T$1) -> 39500 | AY6: =100/AX6*AV6 -> 0 | AZ6: 0 | BB6: 20750 | BC6: =100/BB6*AZ6 -> 0
A7: Assessment of potential new value chains and selection of Topics for Call of Proposals | B7: WP1 | C7: =SUM(G7+K7+O7+S7+W7+AB7+AF7+AJ7+AN7+AR7+AV7+AZ7) -> 104301.99 | D7: =SUM(H7+L7+P7+T7+X7+AC7+AG7+AK7+AO7+AS7+AW7+BA7) -> 31600 | E7: =SUM(I7+M7+Q7+U7+Z7+AD7+AH7+AH7+AL7+AP7+AT7+AX7+BB7) -> 226991.17 | F7: =100/E7*C7 -> 45.949802 | G7: {=MNU!C7:C45} -> 8024.875 | H7: =SUM(H8:H10) -> 31600 | I7: =SUM(I8:I10) -> 20062.5 | J7: =100/I7*G7 -> 39.999377 | K7: =SUM(SCA!W12) -> 13497.165 | L7: =SUM(L8:L10) -> 0 | M7: =SUM(M8:M10) -> 11712.46 | N7: =100/M7*K7 -> 115.23766 | O7: {=FOC!D8:D46} -> 1875.625 | P7: =SUM(P8:P10) -> 0 | Q7: =SUM(Q8:Q10) -> 7790.62 | R7: =100/Q7*O7 -> 24.075427 | S7: {=CLTV!AQ8:AQ46} -> 6823.4177 | T7: =SUM(T8:T10) -> 0 | U7: =SUM(U8:U10) -> 10546.88 | V7: =100/U7*S7 -> 64.696078 | W7: =SUM(MAI!X10) -> 12627.337 | X7: =SUM(X8:X10) -> 0 | Y7: =SUM(Y8:Y10) -> 31484.38 | Z7: =SUM(Z8:Z10) -> 31484.38 | AA7: =100/Z7*W7 -> 40.106674 | AB7: {=BIN!S8:S46} -> 13000.737 | AC7: =SUM(AC8:AC10) -> 0 | AD7: =SUM(AD8:AD10) -> 36562.5 | AE7: =100/AD7*AB7 -> 35.557573 | AF7: =SUM(IOC!K10) -> 2402.5312 | AG7: =SUM(AG8:AG10) -> 0 | AH7: =SUM(AH8:AH10) -> 17306.54 | AI7: =100/AH7*AF7 -> 13.882216 | AJ7: =SUM(HIE!L10) -> 12255.246 | AK7: =SUM(AK8:AK10) -> 0 | AL7: =SUM(AL8:AL10) -> 23906.25 | AM7: =100/AL7*AJ7 -> 51.263774 | AN7: {=BAL!V9:V47} -> 13402.888 | AO7: =SUM(AO8:AO10) -> 0 | AP7: =SUM(AP8:AP10) -> 12375 | AQ7: =100/AP7*AN7 -> 108.30616 | AR7: {=MEERI!G10:G48} -> 8319.05 | AS7: =SUM(AS8:AS10) -> 0 | AT7: =SUM(AT8:AT10) -> 13406.25 | AU7: =100/AT7*AR7 -> 62.05352 | AV7: {=MCN!C7:C45} -> 7696.99 | AW7: =SUM(AW8:AW10) -> 0 | AX7: =SUM(AX8:AX10) -> 10312.5 | AY7: =100/AX7*AV7 -> 74.637479 | AZ7: ='CKR '!C6 -> 4376.13 | BA7: =SUM(BA8:BA10) -> 0 | BB7: =SUM(BB8:BB10) -> 14218.75 | BC7: =100/BB7*AZ7 -> 30.777178
A8: Sustainable challenges, needs and trends of four industrial offshore sectors | B8: T1.1 | C8: =SUM(G8+K8+O8+S8+W8+AB8+AF8+AJ8+AN8+AR8+AV8+AZ8) -> 41306.53 | D8: =SUM(H8+L8+P8+T8+X8+AC8+AG8+AK8+AO8+AS8+AW8+BA8) -> 31600 | E8: =SUM(I8+M8+Q8+U8+Z8+AD8+AH8+AH8+AL8+AP8+AT8+AX8+BB8) -> 88440.74 | F8: =100/E8*C8 -> 46.705319 | G8: 3265.9375 | H8: 31600 | I8: 13375 | J8: =100/I8*G8 -> 24.418224 | K8: =SUM(SCA!W13) -> 6648.4552 | M8: 5856.22 | N8: =100/M8*K8 -> 113.5281 | O8: 780.13 | Q8: 3462.5 | R8: =100/Q8*O8 -> 22.53083 | S8: 508.68068 | U8: 4687.5 | V8: =100/U8*S8 -> 10.851855 | W8: =SUM(MAI!X11) -> 0 | Y8: 2421.88 | Z8: 2421.88 | AA8: =100/Z8*W8 -> 0 | AB8: 2578.095 | AD8: 2812.5 | AE8: =100/AD8*AB8 -> 91.6656 | AF8: =SUM(IOC!K11) -> 310.53125 | AH8: 11537.57 | AI8: =100/AH8*AF8 -> 2.6914788 | AJ8: =SUM(HIE!L11) -> 11586.268 | AL8: 18593.75 | AM8: =100/AL8*AJ8 -> 62.312701 | AN8: 7215.3875 | AP8: 6187.5 | AQ8: =100/AP8*AN8 -> 116.61232 | AR8: 307.44 | AT8: 0 | AU8: =100/AT8*AR8 -> #DIV/0! | AV8: 6508.745 | AX8: 6875 | AY8: =100/AX8*AV8 -> 94.672655 | AZ8: ='CKR '!C7 -> 1596.86 | BB8: 1093.75 | BC8: =100/BB8*AZ8 -> 145.99863
A9: Assessment of emerging technology trends and solutions | B9: T1.2 | C9: =SUM(G9+K9+O9+S9+W9+AB9+AF9+AJ9+AN9+AR9+AV9+AZ9) -> 29037.419 | D9: =SUM(H9+L9+P9+T9+X9+AC9+AG9+AK9+AO9+AS9+AW9+BA9) -> 0 | E9: =SUM(I9+M9+Q9+U9+Z9+AD9+AH9+AH9+AL9+AP9+AT9+AX9+BB9) -> 53116.01 | F9: =100/E9*C9 -> 54.667922 | G9: 1399.6875 | I9: 3343.75 | J9: =100/I9*G9 -> 41.859813 | K9: =SUM(SCA!W14) -> 3484.4313 | M9: 2928.12 | N9: =100/M9*K9 -> 118.99893 | O9: 194.2 | Q9: 865.62 | R9: =100/Q9*O9 -> 22.434787 | S9: 2541.4263 | U9: 1171.88 | V9: =100/U9*S9 -> 216.86745 | W9: =SUM(MAI!X12) -> 5070.8375 | Y9: 9687.5 | Z9: 9687.5 | AA9: =100/Z9*W9 -> 52.344129 | AB9: 5960.02 | AD9: 11250 | AE9: =100/AD9*AB9 -> 52.977956 | AF9: =SUM(IOC!K12) -> 1470.9375 | AH9: 2884.57 | AI9: =100/AH9*AF9 -> 50.993302 | AJ9: =SUM(HIE!L12) -> 411.67883 | AL9: 2656.25 | AM9: =100/AL9*AJ9 -> 15.498497 | AN9: 3093.75 | AP9: 3093.75 | AQ9: =100/AP9*AN9 -> 100 | AR9: 4060.45 | AT9: 6256.25 | AU9: =100/AT9*AR9 -> 64.902298 | AV9: 0 | AX9: 1718.75 | AY9: =100/AX9*AV9 -> 0 | AZ9: ='CKR '!C8 -> 1350 | BB9: 4375 | BC9: =100/BB9*AZ9 -> 30.857143
A10: Potential new value chains and selection of Call Topics | B10: T1.3 | C10: =SUM(G10+K10+O10+S10+W10+AB10+AF10+AJ10+AN10+AR10+AV10+AZ10) -> 30982.771 | D10: =SUM(H10+L10+P10+T10+X10+AC10+AG10+AK10+AO10+AS10+AW10+BA10) -> 0 | E10: =SUM(I9+M10+Q10+U10+Z10+AD10+AH10+AH10+AL10+AP10+AT10+AX10+BB10) -> 85434.42 | F10: =100/E10*C10 -> 36.264975 | G10: 3359.25 | I10: 3343.75 | J10: =100/I10*G10 -> 100.46355 | K10: =SUM(SCA!W15) -> 3364.2785 | M10: 2928.12 | N10: =100/M10*K10 -> 114.89551 | O10: 526.17 | Q10: 3462.5 | R10: =100/Q10*O10 -> 15.196245 | S10: 3773.3108 | U10: 4687.5 | V10: =100/U10*S10 -> 80.497296 | W10: =SUM(MAI!X13) -> 7556.5 | Y10: 19375 | Z10: 19375 | AA10: =100/Z10*W10 -> 39.00129 | AB10: 1862.475 | AD10: 22500 | AE10: =100/AD10*AB10 -> 8.2776667 | AF10: =SUM(IOC!K13) -> 621.0625 | AH10: 2884.4 | AI10: =100/AH10*AF10 -> 21.531774 | AJ10: =SUM(HIE!L13) -> 257.29927 | AL10: 2656.25 | AM10: =100/AL10*AJ10 -> 9.6865606 | AN10: 3093.75 | AP10: 3093.75 | AQ10: =100/AP10*AN10 -> 100 | AR10: 3951.16 | AT10: 7150 | AU10: =100/AT10*AR10 -> 55.260979 | AV10: 1188.245 | AX10: 1718.75 | AY10: =100/AX10*AV10 -> 69.134255 | AZ10: ='CKR '!C9 -> 1429.27 | BB10: 8750 | BC10: =100/BB10*AZ10 -> 16.334514
A11: Methodologies and tools for cross-sectoral/-border collaboration and technology transfer | B11: WP2 | C11: =SUM(G11+K11+O11+S11+W11+AB11+AF11+AJ11+AN11+AR11+AV11+AZ11) -> 67811.891 | D11: =SUM(H11+L11+P11+T11+X11+AC11+AG11+AK11+AO11+AS11+AW11+BA11) -> 0 | E11: =SUM(I11+M11+Q11+U11+Z11+AD11+AH11+AH11+AL11+AP11+AT11+AX11+BB11) -> 153493.81 | F11: =100/E11*C11 -> 44.178909 | G11: 5346.8063 | H11: =SUM(H12:H15) -> 0 | I11: =SUM(I12:I15) -> 6687.5 | J11: =100/I11*G11 -> 79.952243 | K11: =SUM(SCA!W16) -> 3123.9729 | L11: =SUM(L12:L15) -> 0 | M11: =SUM(M12:M15) -> 5856.22 | N11: =100/M11*K11 -> 53.344528 | O11: 174.2875 | P11: =SUM(P12:P15) -> 0 | Q11: =SUM(Q12:Q15) -> 8656.24 | R11: =100/Q11*O11 -> 2.0134319 | S11: 3711.9305 | T11: =SUM(T12:T15) -> 0 | U11: =SUM(U12:U15) -> 11718.76 | V11: =100/U11*S11 -> 31.675113 | W11: =SUM(MAI!X14) -> 0 | X11: =SUM(X12:X15) -> 0 | Y11: =SUM(Y12:Y15) -> 4843.76 | Z11: =SUM(Z12:Z15) -> 4843.76 | AA11: =100/Z11*W11 -> 0 | AB11: 653.5 | AC11: =SUM(AC12:AC15) -> 0 | AD11: =SUM(AD12:AD15) -> 5625 | AE11: =100/AD11*AB11 -> 11.617778 | AF11: =SUM(IOC!K14) -> 555.6875 | AG11: =SUM(AG12:AG15) -> 0 | AH11: =SUM(AH12:AH15) -> 5768.79 | AI11: =100/AH11*AF11 -> 9.6326526 | AJ11: =SUM(HIE!L14) -> 15281.059 | AK11: =SUM(AK12:AK15) -> 0 | AL11: =SUM(AL12:AL15) -> 37187.5 | AM11: =100/AL11*AJ11 -> 41.091923 | AN11: 30049.188 | AO11: =SUM(AO12:AO15) -> 0 | AP11: =SUM(AP12:AP15) -> 47406.25 | AQ11: =100/AP11*AN11 -> 63.386552 | AR11: 1776.61 | AS11: =SUM(AS12:AS15) -> 0 | AT11: =SUM(AT12:AT15) -> 1787.5 | AU11: =100/AT11*AR11 -> 99.390769 | AV11: 565.24 | AW11: =SUM(AW12:AW15) -> 0 | AX11: =SUM(AX12:AX15) -> 3437.5 | AY11: =100/AX11*AV11 -> 16.443345 | AZ11: ='CKR '!C10 -> 6573.6097 | BA11: =SUM(BA12:BA15) -> 0 | BB11: =SUM(BB12:BB15) -> 8750 | BC11: =100/BB11*AZ11 -> 75.126968
A12: Methologies and tools for cross-sectoral/-border collaboration and technology transfer | B12: T2.1 | C12: =SUM(G12+K12+O12+S12+W12+AB12+AF12+AJ12+AN12+AR12+AV12+AZ12) -> 19605.459 | D12: =SUM(H12+L12+P12+T12+X12+AC12+AG12+AK12+AO12+AS12+AW12+BA12) -> 0 | E12: =SUM(I12+M12+Q12+U12+Z12+AD12+AH12+AH12+AL12+AP12+AT12+AX12+BB12) -> 67887.51 | F12: =100/E12*C12 -> 28.879331 | G12: 1306.375 | I12: 3343.75 | J12: =100/I12*G12 -> 39.069159 | K12: =SUM(SCA!W17) -> 40.050935 | M12: 2928.1 | N12: =100/M12*K12 -> 1.3678131 | O12: 0 | Q12: 4328.12 | R12: =100/Q12*O12 -> 0 | S12: 1816.2619 | U12: 5859.38 | V12: =100/U12*S12 -> 30.997511 | W12: =SUM(MAI!X15) -> 0 | Y12: 2421.88 | Z12: 2421.88 | AA12: =100/Z12*W12 -> 0 | AB12: 130.7 | AD12: 2812.5 | AE12: =100/AD12*AB12 -> 4.6471111 | AF12: =SUM(IOC!K15) -> 0 | AH12: 2884.39 | AI12: =100/AH12*AF13 -> 0 | AJ12: =SUM(HIE!L15) -> 14637.811 | AL12: 34531.25 | AM12: =100/AL12*AJ12 -> 42.390041 | AN12: 0 | AP12: 0 | AQ12: =100/AP12*AN12 -> #DIV/0! | AR12: 1115.02 | AT12: 893.75 | AU12: =100/AT12*AR12 -> 124.75748 | AV12: 559.24 | AX12: 1718.75 | AY12: =100/AX12*AV12 -> 32.5376 | AZ12: ='CKR '!C11 -> 0 | BB12: 3281.25 | BC12: =100/BB12*AZ12 -> 0
A13: Establishment of a Collaborative Virtual Environment | B13: T2.2 | C13: =SUM(G13+K13+O13+S13+W13+AB13+AF13+AJ13+AN13+AR13+AV13+AZ13) -> 5204.3416 | D13: =SUM(H13+L13+P13+T13+X13+AC13+AG13+AK13+AO13+AS13+AW13+BA13) -> 0 | E13: =SUM(I13+M13+Q13+U13+Z13+AD13+AH13+AH13+AL13+AP13+AT13+AX13+BB13) -> 3343.75 | F13: =100/E13*C13 -> 155.64386 | G13: 4040.4313 | I13: 3343.75 | J13: =100/I13*G13 -> 120.83533 | K13: =SUM(SCA!W18) -> 520.66216 | M13: 0 | N13: =100/M13*K13 -> #DIV/0! | O13: 0 | Q13: 0 | R13: =100/Q13*O13 -> #DIV/0! | S13: 0 | U13: 0 | V13: =100/U13*S13 -> #DIV/0! | W13: =SUM(MAI!X16) -> 0 | Y13: 0 | Z13: 0 | AA13: =100/Z13*W13 -> #DIV/0! | AB13: 0 | AD13: 0 | AE13: =100/AD13*AB13 -> #DIV/0! | AF13: =SUM(IOC!K16) -> 0 | AH13: 0 | AI13: =100/AH13*#REF! -> #DIV/0! | AJ13: =SUM(HIE!L16) -> 643.24817 | AL13: 0 | AM13: =100/AL13*AJ13 -> #DIV/0! | AN13: 0 | AP13: 0 | AQ13: =100/AP13*AN13 -> #DIV/0! | AR13: 0 | AT13: 0 | AU13: =100/AT13*AR13 -> #DIV/0! | AV13: 0 | AX13: 0 | AY13: =100/AX13*AV13 -> #DIV/0! | AZ13: ='CKR '!C12 -> 0 | BB13: 0 | BC13: =100/BB13*AZ13 -> #DIV/0!
A14: Establishment of a Survey tool | B14: T2.3 | C14: =SUM(G14+K14+O14+S14+W14+AB14+AF14+AJ14+AN14+AR14+AV14+AZ14) -> 10794.029 | D14: =SUM(H14+L14+P14+T14+X14+AC14+AG14+AK14+AO14+AS14+AW14+BA14) -> 0 | E14: =SUM(I14+M14+Q14+U14+Z14+AD14+AH14+AH14+AL14+AP14+AT14+AX14+BB14) -> 12525 | F14: =100/E14*C14 -> 86.179876 | G14: 0 | I14: 0 | J14: =100/I14*G14 -> #DIV/0! | K14: =SUM(SCA!W19) -> 1321.6809 | M14: 0 | N14: =100/M14*K14 -> #DIV/0! | O14: 139.43 | Q14: 3462.5 | R14: =100/Q14*O14 -> 4.0268592 | S14: 1895.6686 | U14: 4687.5 | V14: =100/U14*S14 -> 40.440929 | W14: =SUM(MAI!X17) -> 0 | Y14: 0 | Z14: 0 | AA14: =100/Z14*W14 -> #DIV/0! | AB14: 196.05 | AD14: 0 | AE14: =100/AD14*AB14 -> #DIV/0! | AF14: =SUM(IOC!K17) -> 0 | AH14: 0 | AI14: =100/AH14*AF14 -> #DIV/0! | AJ14: =SUM(HIE!L17) -> 0 | AL14: 0 | AM14: =100/AL14*AJ14 -> #DIV/0! | AN14: 0 | AP14: 0 | AQ14: =100/AP14*AN14 -> #DIV/0! | AR14: 661.59 | AT14: 0 | AU14: =100/AT14*AR14 -> #DIV/0! | AV14: 6 | AX14: 0 | AY14: =100/AX14*AV14 -> #DIV/0! | AZ14: ='CKR '!C13 -> 6573.61 | BB14: 4375 | BC14: =100/BB14*AZ14 -> 150.25394
A15: Establishment of the GreenOffshoreTech Cluster Collaboration Platform | B15: T2.4 | C15: =SUM(G15+K15+O15+S15+W15+AB15+AF15+AJ15+AN15+AR15+AV15+AZ15) -> 32291.647 | D15: =SUM(H15+L15+P15+T15+X15+AC15+AG15+AK15+AO15+AS15+AW15+BA15) -> 0 | E15: =SUM(I15+M15+Q15+U15+Z15+AD15+AH15+AH15+AL15+AP15+AT15+AX15+BB15) -> 69737.55 | F15: =100/E15*C15 -> 46.304533 | G15: 0 | I15: 0 | J15: =100/I15*G15 -> #DIV/0! | K15: =SUM(SCA!W20) -> 1241.579 | M15: 2928.12 | N15: =100/M15*K15 -> 42.401916 | O15: 0 | Q15: 865.62 | R15: =100/Q15*O15 -> 0 | S15: 249.14268 | U15: 1171.88 | V15: =100/U15*S15 -> 21.260085 | W15: =SUM(MAI!X18) -> 0 | Y15: 2421.88 | Z15: 2421.88 | AA15: =100/Z15*W15 -> 0 | AB15: 196.05 | AD15: 2812.5 | AE15: =100/AD15*AB15 -> 6.9706667 | AF15: =SUM(IOC!K18) -> 555.6875 | AH15: 2884.4 | AI15: =100/AH15*AF15 -> 19.265272 | AJ15: =SUM(HIE!L18) -> 0 | AL15: 2656.25 | AM15: =100/AL15*AJ15 -> 0 | AN15: 30049.188 | AP15: 47406.25 | AQ15: =100/AP15*AN15 -> 63.386552 | AR15: 0 | AT15: 893.75 | AU15: =100/AT15*AR15 -> 0 | AV15: 0 | AX15: 1718.75 | AY15: =100/AX15*AV15 -> 0 | AZ15: ='CKR '!C14 -> 0 | BB15: 1093.75 | BC15: =100/BB15*AZ15 -> 0
A16: Direct financial support to SMEs through a competitive Call for Proposals | B16: WP3 | C16: =SUM(G16+K16+O16+S16+W16+AB16+AF16+AJ16+AN16+AR16+AV16+AZ16) -> 84177.462 | D16: =SUM(H16+L16+P16+T16+X16+AC16+AG16+AK16+AO16+AS16+AW16+BA16) -> 91428.57 | E16: =SUM(I16+M16+Q16+U16+Z16+AD16+AH16+AH16+AL16+AP16+AT16+AX16+BB16) -> 3434125.1 | F16: =100/E16*C16 -> 2.4512054 | G16: 1306.375 | H16: =SUM(H17:H22) -> 0 | I16: =SUM(I17:I22) -> 3094375 | J16: =100/I16*G16 -> 0.042217734 | K16: =SUM(SCA!W21) -> 11374.466 | L16: =SUM(L17:L22) -> 8000 | M16: =SUM(M17:M22) -> 52706.11 | N16: =100/M16*K16 -> 21.580924 | O16: 2002.375 | P16: =SUM(P17:P22) -> 8000 | Q16: =SUM(Q17:Q22) -> 8656.25 | R16: =100/Q16*O16 -> 23.13213 | S16: 962.41046 | T16: =SUM(T17:T22) -> 8000 | U16: =SUM(U17:U22) -> 16406.25 | V16: =100/U16*S16 -> 5.8661209 | W16: =SUM(MAI!X19) -> 0 | X16: =SUM(X17:X22) -> 8000 | Y16: =SUM(Y17:Y22) -> 33906.25 | Z16: =SUM(Z17:Z22) -> 33906.25 | AA16: =100/Z16*W16 -> 0 | AB16: 1364.2125 | AC16: =SUM(AC17:AC22) -> 11428.57 | AD16: =SUM(AD17:AD22) -> 39375 | AE16: =100/AD16*AB16 -> 3.4646667 | AF16: =SUM(IOC!K19) -> 1307.5 | AG16: =SUM(AG17:AG22) -> 8000 | AH16: =SUM(AH17:AH22) -> 28843.88 | AI16: =100/AH16*AF16 -> 4.533024 | AJ16: =SUM(HIE!L19) -> 6539.2514 | AK16: =SUM(AK17:AK22) -> 8000 | AL16: =SUM(AL17:AL22) -> 26562.5 | AM16: =100/AL16*AJ16 -> 24.618358 | AN16: 34570.488 | AO16: =SUM(AO17:AO22) -> 8000 | AP16: =SUM(AP17:AP22) -> 48500 | AQ16: =100/AP16*AN16 -> 71.279356 | AR16: 2131.5 | AS16: =SUM(AS17:AS22) -> 8000 | AT16: =SUM(AT17:AT22) -> 12512.5 | AU16: =100/AT16*AR16 -> 17.034965 | AV16: 2898.055 | AW16: =SUM(AW17:AW22) -> 8000 | AX16: =SUM(AX17:AX22) -> 17187.5 | AY16: =100/AX16*AV16 -> 16.861411 | AZ16: ='CKR '!C15 -> 19720.829 | BA16: =SUM(BA17:BA22) -> 8000 | BB16: =SUM(BB17:BB22) -> 26250 | BC16: =100/BB16*AZ16 -> 75.126968
A17: Preparation of the Call for Proposals | B17: T3.1 | C17: =SUM(G17+K17+O17+S17+W17+AB17+AF17+AJ17+AN17+AR17+AV17+AZ17) -> 47109.12 | D17: =SUM(H17+L17+P17+T17+X17+AC17+AG17+AK17+AO17+AS17+AW17+BA17) -> 19000 | E17: =SUM(I17+M17+Q17+U17+Z17+AD17+AH17+AH17+AL17+AP17+AT17+AX17+BB17) -> 68475.03 | F17: =100/E17*C17 -> 68.797516 | G17: 559.875 | H17: 0 | I17: 6687.5 | J17: =100/I17*G17 -> 8.3719626 | K17: =SUM(SCA!W22) -> 10613.498 | L17: 1000 | M17: 5856.22 | N17: =100/M17*K17 -> 181.23462 | O17: 1601.9 | P17: 2000 | Q17: 1731.25 | R17: =100/Q17*O17 -> 92.52852 | S17: 962.41046 | T17: 1000 | U17: 2343.75 | V17: =100/U17*S17 -> 41.062846 | W17: =SUM(MAI!X20) -> 0 | X17: 1000 | Y17: 4843.75 | Z17: 4843.75 | AA17: =100/Z17*W17 -> 0 | AB17: 653.5 | AC17: 2000 | AD17: 5625 | AE17: =100/AD17*AB17 -> 11.617778 | AF17: =SUM(IOC!K20) -> 1046 | AG17: 2000 | AH17: 5768.78 | AI17: =100/AH17*AF17 -> 18.132083 | AJ17: =SUM(HIE!L20) -> 1628.0514 | AK17: 2000 | AL17: 5312.5 | AM17: =100/AL17*AJ17 -> 30.645674 | AN17: 6187.5 | AO17: 1000 | AP17: 6187.5 | AQ17: =100/AP17*AN17 -> 100 | AR17: 2131.5 | AS17: 2000 | AT17: 1787.5 | AU17: =100/AT17*AR17 -> 119.24476 | AV17: 2004.055 | AW17: 2000 | AX17: 3437.5 | AY17: =100/AX17*AV17 -> 58.299782 | AZ17: ='CKR '!C16 -> 19720.83 | BA17: 3000 | BB17: 13125 | BC17: =100/BB17*AZ17 -> 150.25394
A18: Publication of the Call for Proposals and Proposal reception. | B18: T3.2 | C18: =SUM(G18+K18+O18+S18+W18+AB18+AF18+AJ18+AN18+AR18+AV18+AZ18) -> 14557.76 | D18: =SUM(H18+L18+P18+T18+X18+AC18+AG18+AK18+AO18+AS18+AW18+BA18) -> 2000 | E18: =SUM(I18+M18+Q18+U18+Z18+AD18+AH18+AH18+AL18+AP18+AT18+AX18+BB18) -> 18562.5 | F18: =100/E18*C18 -> 78.425645 | G18: 466.5625 | H18: 0 | I18: 6687.5 | J18: =100/I18*G18 -> 6.9766355 | K18: =SUM(SCA!W23) -> 760.96777 | M18: 0 | N18: =100/M18*K18 -> #DIV/0! | O18: 0 | Q18: 0 | R18: =100/Q18*O18 -> #DIV/0! | S18: 0 | U18: 0 | V18: =100/U18*S18 -> #DIV/0! | W18: =SUM(MAI!X21) -> 0 | Y18: 0 | Z18: 0 | AA18: =100/Z18*W18 -> #DIV/0! | AB18: 673.13 | AD18: 0 | AE18: =100/AD18*AB18 -> #DIV/0! | AF18: =SUM(IOC!K21) -> 261.5 | AH18: 0 | AI18: =100/AH18*AF18 -> #DIV/0! | AJ18: =SUM(HIE!L21) -> 4911.2 | AL18: 0 | AM18: =100/AL18*AJ18 -> #DIV/0! | AN18: 7484.4 | AO18: 2000 | AP18: 11875 | AQ18: =100/AP18*AN18 -> 63.026526 | AR18: 0 | AT18: 0 | AU18: =100/AT18*AR18 -> #DIV/0! | AV18: 0 | AX18: 0 | AY18: =100/AX18*AV18 -> #DIV/0! | AZ18: ='CKR '!C17 -> 0 | BB18: 0 | BC18: =100/BB18*AZ18 -> #DIV/0!
A19: Evaluation and Selection of SMEs Proposals | B19: T3.3 | C19: =SUM(G19+K19+O19+S19+W19+AB19+AF19+AJ19+AN19+AR19+AV19+AZ19) -> 15885.025 | D19: =SUM(H19+L19+P19+T19+X19+AC19+AG19+AK19+AO19+AS19+AW19+BA19) -> 33000 | E19: =SUM(I19+M19+Q19+U19+Z19+AD19+AH19+AH19+AL19+AP19+AT19+AX19+BB19) -> 121637.57 | F19: =100/E19*C19 -> 13.059308 | G19: 279.9375 | H19: 0 | I19: 13750 | J19: =100/I19*G19 -> 2.0359091 | K19: =SUM(SCA!W24) -> 0 | L19: 2000 | M19: 11712.47 | N19: =100/M19*K19 -> 0 | O19: 0 | P19: 3000 | Q19: 3462.5 | R19: =100/Q19*O19 -> 0 | S19: 0 | T19: 3000 | U19: 4687.5 | V19: =100/U19*S19 -> 0 | W19: =SUM(MAI!X22) -> 0 | X19: 3000 | Y19: 9687.5 | Z19: 9687.5 | AA19: =100/Z19*W19 -> 0 | AB19: 0 | AC19: 5000 | AD19: 11250 | AE19: =100/AD19*AB19 -> 0 | AF19: =SUM(IOC!K22) -> 0 | AG19: 3000 | AH19: 11537.55 | AI19: =100/AH19*AF19 -> 0 | AJ19: =SUM(HIE!L22) -> 0 | AK19: 3000 | AL19: 10625 | AM19: =100/AL19*AJ19 -> 0 | AN19: 14711.088 | AO19: 3000 | AP19: 18562.5 | AQ19: =100/AP19*AN19 -> 79.25165 | AR19: 0 | AS19: 3000 | AT19: 3575 | AU19: =100/AT19*AR19 -> 0 | AV19: 894 | AW19: 3000 | AX19: 6875 | AY19: =100/AX19*AV19 -> 13.003636 | AZ19: ='CKR '!C18 -> 0 | BA19: 2000 | BB19: 4375 | BC19: =100/BB19*AZ19 -> 0
A20: Contracting with winner SMEs Projects | B20: T3.4 | C20: =SUM(G20+K20+O20+S20+W20+AB20+AF20+AJ20+AN20+AR20+AV20+AZ20) -> 0 | D20: =SUM(H20+L20+P20+T20+X20+AC20+AG20+AK20+AO20+AS20+AW20+BA20) -> 0 | E20: =SUM(I20+M20+Q20+U20+Z20+AD20+AH20+AH20+AL20+AP20+AT20+AX20+BB20) -> 26750 | F20: =100/E20*C20 -> 0 | G20: 0 | H20: 0 | I20: 26750 | J20: =100/I20*G20 -> 0 | K20: =SUM(SCA!W25) -> 0 | M20: 0 | N20: =100/M20*K20 -> #DIV/0! | O20: 0 | Q20: 0 | R20: =100/Q20*O20 -> #DIV/0! | S20: 0 | U20: 0 | V20: =100/U20*S20 -> #DIV/0! | W20: =SUM(MAI!X23) -> 0 | Y20: 0 | Z20: 0 | AA20: =100/Z20*W20 -> #DIV/0! | AB20: 0 | AD20: 0 | AE20: =100/AD20*AB20 -> #DIV/0! | AF20: =SUM(IOC!K23) -> 0 | AH20: 0 | AI20: =100/AH20*AF20 -> #DIV/0! | AJ20: =SUM(HIE!L23) -> 0 | AL20: 0 | AM20: =100/AL20*AJ20 -> #DIV/0! | AN20: 0 | AP20: 0 | AQ20: =100/AP20*AN20 -> #DIV/0! | AR20: 0 | AT20: 0 | AU20: =100/AT20*AR20 -> #DIV/0! | AV20: 0 | AX20: 0 | AY20: =100/AX20*AV20 -> #DIV/0! | AZ20: ='CKR '!C19 -> 0 | BB20: 0 | BC20: =100/BB20*AZ20 -> #DIV/0!
A21: Payments and financial monitoring of winner SMEs Projects | B21: T3.5 | C21: =SUM(G21+K21+O21+S21+W21+AB21+AF21+AJ21+AN21+AR21+AV21+AZ21) -> 0 | D21: =SUM(H21+L21+P21+T21+X21+AC21+AG21+AK21+AO21+AS21+AW21+BA21) -> 0 | E21: =SUM(I21+M21+Q21+U21+Z21+AD21+AH21+AH21+AL21+AP21+AT21+AX21+BB21) -> 3026750 | F21: =100/E21*C21 -> 0 | G21: 0 | H21: 0 | I21: 3026750 | J21: =100/I21*G21 -> 0 | K21: =SUM(SCA!W26) -> 0 | M21: 0 | N21: =100/M21*K21 -> #DIV/0! | O21: 0 | Q21: 0 | R21: =100/Q21*O21 -> #DIV/0! | S21: 0 | U21: 0 | V21: =100/U21*S21 -> #DIV/0! | W21: =SUM(MAI!X24) -> 0 | Y21: 0 | Z21: 0 | AA21: =100/Z21*W21 -> #DIV/0! | AB21: 0 | AC21: 0 | AD21: 0 | AE21: =100/AD21*AB21 -> #DIV/0! | AF21: =SUM(IOC!K24) -> 0 | AH21: 0 | AI21: =100/AH21*AF21 -> #DIV/0! | AJ21: =SUM(HIE!L24) -> 0 | AL21: 0 | AM21: =100/AL21*AJ21 -> #DIV/0! | AN21: 0 | AP21: 0 | AQ21: =100/AP21*AN21 -> #DIV/0! | AR21: 0 | AT21: 0 | AU21: =100/AT21*AR21 -> #DIV/0! | AV21: 0 | AX21: 0 | AY21: =100/AX21*AV21 -> #DIV/0! | AZ21: ='CKR '!C20 -> 0 | BB21: 0 | BC21: =100/BB21*AZ21 -> #DIV/0!
A22: Technical monitoring of winner SMEs Projects | B22: T3.6 | C22: =SUM(G22+K22+O22+S22+W22+AB22+AF22+AJ22+AN22+AR22+AV22+AZ22) -> 6187.5 | D22: =SUM(H22+L22+P22+T22+X22+AC22+AG22+AK22+AO22+AS22+AW22+BA22) -> 37428.57 | E22: =SUM(I22+M22+Q22+U22+Z22+AD22+AH22+AH22+AL22+AP22+AT22+AX22+BB22) -> 171950.02 | F22: =100/E22*C22 -> 3.5984294 | G22: 0 | H22: 0 | I22: 13750 | J22: =100/I22*G22 -> 0 | K22: =SUM(SCA!W27) -> 0 | L22: 5000 | M22: 35137.42 | N22: =100/M22*K22 -> 0 | O22: 0 | P22: 3000 | Q22: 3462.5 | R22: =100/Q22*O22 -> 0 | S22: 0 | T22: 4000 | U22: 9375 | V22: =100/U22*S22 -> 0 | W22: =SUM(MAI!X25) -> 0 | X22: 4000 | Y22: 19375 | Z22: 19375 | AA22: =100/Z22*W22 -> 0 | AB22: 0 | AC22: 4428.57 | AD22: 22500 | AE22: =100/AD22*AB22 -> 0 | AF22: =SUM(IOC!K25) -> 0 | AG22: 3000 | AH22: 11537.55 | AI22: =100/AH22*AF22 -> 0 | AJ22: =SUM(HIE!L25) -> 0 | AK22: 3000 | AL22: 10625 | AM22: =100/AL22*AJ22 -> 0 | AN22: 6187.5 | AO22: 2000 | AP22: 11875 | AQ22: =100/AP22*AN22 -> 52.105263 | AR22: 0 | AS22: 3000 | AT22: 7150 | AU22: =100/AT22*AR22 -> 0 | AV22: 0 | AW22: 3000 | AX22: 6875 | AY22: =100/AX22*AV22 -> 0 | AZ22: ='CKR '!C21 -> 0 | BA22: 3000 | BB22: 8750 | BC22: =100/BB22*AZ22 -> 0
