Workbook

Sheet Shareholder Book
B4: Founding / Issue of shares - Ferdocean Shipping AS (FOS)
B7: Step 1 - Founding FOS
B9: Number of shares: | D9: 93515
B10: Subscription price Norwegian Krone: | D10: 0.32080415
B11: Total share capital Norwegian Krone: | D11: 30000
B14: Subsription - founding the company | D14: Number of shares | E14: amount
B15: Ferdocean AS | D15: 64980 | E15: =D11*78% -> 23400
B16: Shield International Ltd | D16: 25940 | E16: =D11*20% -> 6000
B17: T-E Invest AS | D17: 2595 | E17: =D11*2% -> 600
D18: =SUM(D15:D17) -> 93515 | E18: =SUM(E15:E17) -> 30000
B20: Share issue 1 - (Morcidea AS)
B21: Number of shares | D21: 3761
B22: Face value | D22: 0.32080415
B23: Subscription price Norwegian Krone: | D23: =+D24/D21 -> 192.23611
B24: Subscription amount Norwegian Krone: | D24: 723000
B25: Share Premium | D25: =+(D23-D22)*D21 -> 721793.46
B26: Share Capital | D26: =D21*D22 -> 1206.5444
B28: Ownership after 1st share issue
B29: Ferdocean AS | D29: 64980 | E29: =+D29/$D$33 -> 0.66799622
B30: Shield International Ltd | D30: =+D16 -> 25940 | E30: =+D30/$D$33 -> 0.26666393
B31: T-E Invest AS | D31: 2595 | E31: =+D31/$D$33 -> 0.026676673
B32: Morcidea AS | D32: =+D21 -> 3761 | E32: =+D32/$D$33 -> 0.038663185
B33: Total | D33: =SUM(D29:D32) -> 97276 | E33: =SUM(E29:E32) -> 1
B36: Share issue 2 - (MA'MOR HOLDINGS SDN BHD)
B37: Number of shares | D37: 29724
B38: Face value | D38: 0.32080415
B39: Subscription price Norwegian Krone: | D39: 351.31379
B40: Subscription amount Norwegian Krone: | D40: =D37*D39 -> 10442451
B41: Share Premium | D41: =+(D39-D38)*D37 -> 10432915
B42: Share Capital | D42: =D37*D38 -> 9535.5825
B44: Shareholder Book
B45: Ownership after 2nd share issue | D45: Number of shares | E45: Ownership
B46: Shares 1 - 64.980 | D46: =+D15 -> 64980 | E46: =+D46/D$51 -> 0.51165354 | F46: Ferdocean AS
B47: Shares 64.981 - 90.920 | D47: =+D16 -> 25940 | E47: =+D47/D$51 -> 0.20425197 | F47: Shield International Ltd
B48: Shares 90.921 - 93.515 | D48: =+D17 -> 2595 | E48: =+D48/D$51 -> 0.020433071 | F48: T-E Invest AS
B49: Shares 93.516 - 97.276 | D49: =+D21 -> 3761 | E49: =+D49/D$51 -> 0.029614173 | F49: Morcidea AS
B50: Shares 97.277 - 127.000 | D50: =+D37 -> 29724 | E50: =+D50/D$51 -> 0.23404724 | F50: MA'MOR HOLDINGS SDN BHD
B51: Total | D51: =SUM(D46:D50) -> 127000 | E51: =SUM(E46:E50) -> 1 | F51: SUM
B53: Total Share Premium | D53: =D25+D41 -> 11154709
B54: Total Share Capital | D54: =D11+D26+D42 -> 40742.127
...

Sheet Share capital history
A1: Share Capital History Ferdocean Shipping AS
A2: FOS AS | B2: Date of reg. | C2: Type of change | D2: Change in share capital (NOK) | E2: New share capital (NOK) | F2: New shares | G2: New Number of total issued shares | H2: Subscription NOK | I2: Nom. Value (NOK) | J2: Subscription price per share (NOK)
A3: History- F | B3: 43802 | C3: Incorporation | D3: 30000 | E3: 30000 | F3: 93515 | G3: 93515 | H3: =F3*J3 -> 30000 | I3: 0.32080415 | J3: 0.32080415
A4: History - 1 | B4: 43830 | C4: Share Capital Increase | D4: 1206.54 | E4: 31206.54 | F4: 4361 | G4: 97276 | H4: =F4*J4 -> 838341.66 | I4: 0.32080415 | J4: 192.23611
A5: History - 2 | B5: 44097 | C5: Share Capital Increase | D5: 9535.58 | E5: 40742.12 | F5: 29724 | G5: 127000 | H5: =F5*J5 -> 10442451 | I5: 0.32080415 | J5: 351.31379
A6: History - 3 | B6: 44175 | C6: Share Capital Increase | D6: 12832.16 | E6: 53574.29 | F6: 40000 | G6: 167000 | H6: =F6*J6 -> 8000000 | I6: 0.32080415 | J6: 200
A7: History - 4 | B7: 44977 | C7: Share Capital Increase | D7: 3208.0415 | E7: =E6+D7 -> 56782.331 | F7: 10000 | G7: 177000 | H7: 5000000 | I7: 0.32080415 | J7: =H7/F7 -> 500
A8: History - 5 | B8: 45078 | C8: Share Capital Increase | D8: =E8-E7 -> 968.82851 | E8: 57751.16 | F8: 3020 | G8: 180020 | H8: 1510000 | I8: 0.32080415 | J8: =H8/F8 -> 500
H9: =SUM(H3:H8) -> 25820793

Sheet Sits and capitalraise 5 simul
A1: Shareholder Book as of 01.06.2023 | E1: Calculations Shareholder sits after simulation | H1: = Commitment
A2: Ownership | B2: Number of shares | C2: Owner sits | E2: Ownership | F2: Nr.of shares | G2: Nr.of new shares | H2: Commited Capital | I2: Total shares | J2: New owner sits | K2: Market Cap Post Money
A3: Ferdocean AS | B3: 64980 | C3: =B3/$B$15 -> 0.36711864 | E3: Ferdocean AS | F3: =B3 -> 64980 | G3: =H3/$B$22 -> 0 | H3: 0 | I3: =F3+G3 -> 64980 | J3: =I3/$I$15 -> 0.36095989 | K3: =$B$26*J3 -> 32490000
A4: Gunnar Nordbø ENK | B4: 33200 | C4: =B4/$B$15 -> 0.18757062 | E4: Gunnar Nordbø ENK | F4: =B4 -> 33200 | G4: =H4/$B$22 -> 560 | H4: 280000 | I4: =F4+G4 -> 33760 | J4: =I4/$I$15 -> 0.18753472 | K4: =$B$26*J4 -> 16880000
A5: MA`MOR Holdings SDN BHD | B5: 29724 | C5: =B5/$B$15 -> 0.1679322 | E5: MA`MOR Holdings SDN BHD | F5: =B5 -> 29724 | G5: =H5/$B$22 -> 0 | H5: 0 | I5: =F5+G5 -> 29724 | J5: =I5/$I$15 -> 0.16511499 | K5: =$B$26*J5 -> 14862000
A6: Shield International Ltd | B6: 29740 | C6: =B6/$B$15 -> 0.1680226 | E6: Shield International Ltd | F6: =B6 -> 29740 | G6: =H6/$B$22 -> 1300 | H6: 650000 | I6: =F6+G6 -> 31040 | J6: =I6/$I$15 -> 0.17242529 | K6: =$B$26*J6 -> 15520000
A7: Wilmar AS | B7: 12000 | C7: =B7/$B$15 -> 0.06779661 | E7: Wilmar AS | F7: =B7 -> 12000 | G7: =H7/$B$22 -> 0 | H7: 0 | I7: =F7+G7 -> 12000 | J7: =I7/$I$15 -> 0.06665926 | K7: =$B$26*J7 -> 6000000
A8: Morcidea AS | B8: 3761 | C8: =B8/$B$15 -> 0.021248588 | E8: Morcidea AS | F8: =B8 -> 3761 | G8: =H8/$B$22 -> 200 | H8: 100000 | I8: =F8+G8 -> 3961 | J8: =I8/$I$15 -> 0.022003111 | K8: =$B$26*J8 -> 1980500
A9: T-E Invest AS | B9: 2595 | C9: =B9/$B$15 -> 0.014661017 | E9: T-E Invest AS | F9: =B9 -> 2595 | G9: =H9/$B$22 -> 100 | H9: 50000 | I9: =F9+G9 -> 2695 | J9: =I9/$I$15 -> 0.014970559 | K9: =$B$26*J9 -> 1347500
A10: Quality Group Invest AS | B10: 400 | C10: =B10/$B$15 -> 0.002259887 | E10: Quality Group Invest AS (from FO AS) | F10: =B10 -> 400 | G10: =H10/$B$22 -> 120 | H10: 60000 | I10: =F10+G10 -> 520 | J10: =I10/$I$15 -> 0.0028885679 | K10: =$B$26*J10 -> 260000
A11: Mosby Holding Ltd | B11: 200 | C11: =B11/$B$15 -> 0.0011299435 | E11: Mosby Holding Ltd(from FO as) | F11: =B11 -> 200 | G11: =H11/$B$22 -> 120 | H11: 60000 | I11: =F11+G11 -> 320 | J11: =I11/$I$15 -> 0.0017775803 | K11: =$B$26*J11 -> 160000
A12: Haugjegla Invest AS | B12: 200 | C12: =B12/$B$15 -> 0.0011299435 | E12: Haugjegla Invest AS (from FO as) | F12: =B12 -> 200 | G12: =H12/$B$22 -> 0 | H12: 0 | I12: =F12+G12 -> 200 | J12: =I12/$I$15 -> 0.0011109877 | K12: =$B$26*J12 -> 100000
A13: Superiore Capital AS | B13: 200 | C13: =B13/$B$15 -> 0.0011299435 | E13: Superiore Capital AS (from FO as) | F13: =B13 -> 200 | G13: =H13/$B$22 -> 120 | H13: 60000 | I13: =F13+G13 -> 320 | J13: =I13/$I$15 -> 0.0017775803 | K13: =$B$26*J13 -> 160000
E14: New: Proco AS | F14: =B14 -> 0 | G14: =H14/$B$22 -> 500 | H14: 250000 | I14: =F14+G14 -> 500 | J14: =I14/$I$15 -> 0.0027774692 | K14: =$B$26*J14 -> 250000
A15: Total | B15: =SUM(B3:B14) -> 177000 | C15: =SUM(C3:C14) -> 1 | E15: Total | F15: =SUM(F3:F14) -> 177000 | G15: =SUM(G3:G14) -> 3020 | H15: =SUM(H3:H14) -> 1510000 | I15: =SUM(I3:I14) -> 180020 | J15: =SUM(J3:J14) -> 1 | K15: =SUM(K3:K14) -> 90010000
A18: Calculations upcoming capital raise:
A19: Simulation inputs
A20: Shares | B20: =B15 -> 177000
A21: Pre money valuation | B21: 88500000
A22: Valuation per share | B22: =B21/B20 -> 500
A24: Target gross proceeds | B24: 1510000
A25: New shares if valuation equals per share pre money | B25: =B24/B22 -> 3020
A26: Post money valuation | B26: =B24+B21 -> 90010000
A27: Total outstanding shares in the company | B27: =B20+B25 -> 180020
A28: Offering % of the company outstanding shares | B28: =B25/B27 -> 0.016775914

Sheet Konvertibelt lån - 1 - 45.4
A1: Shareholder Book as of 03.07.2024 | E1: Calculations Shareholder sits after simulation | H1: = Commitment
A2: Ownership | B2: Number of shares | C2: Owner sits | E2: Ownership - After converting to Pre-money MNOK 45,4`` | F2: Nr.of shares | G2: Nr.of new shares | H2: Commited Capital | I2: Total shares | J2: New owner sits | K2: Market Cap Post Money
A3: Ferdocean AS | B3: 64980 | C3: 0.361 | E3: Ferdocean AS | F3: =B3 -> 64980 | G3: =H3/$B$25 -> 0 | H3: 0 | I3: =F3+G3 -> 64980 | J3: =I3/$I$18 -> 0.34596308 | K3: =$B$29*J3 -> 16560561
A4: Gunnar Nordbø ENK | B4: 33760 | C4: 0.1875 | E4: Gunnar Nordbø ENK | F4: =B4 -> 33760 | G4: =H4/$B$25 -> 2973.8987 | H4: 750000 | I4: =F4+G4 -> 36733.899 | J4: =I4/$I$18 -> 0.19557668 | K4: =$B$29*J4 -> 9361864.6
A5: MA`MOR Holdings SDN BHD | B5: 29724 | C5: 0.1651 | E5: MA`MOR Holdings SDN BHD | F5: =B5 -> 29724 | G5: =H5/$B$25 -> 0 | H5: 0 | I5: =F5+G5 -> 29724 | J5: =I5/$I$18 -> 0.15825495 | K5: =$B$29*J5 -> 7575347.9
A6: Shield International Ltd | B6: 31040 | C6: 0.1724 | E6: Shield International Ltd | F6: =B6 -> 31040 | G6: =H6/$B$25 -> 1594.0097 | H6: 402000 | I6: =F6+G6 -> 32634.01 | J6: =I6/$I$18 -> 0.17374827 | K6: =$B$29*J6 -> 8316982.1
A7: Wilmar AS | B7: 12000 | C7: 0.0667 | E7: Wilmar AS | F7: =B7 -> 12000 | G7: =H7/$B$25 -> 0 | H7: 0 | I7: =F7+G7 -> 12000 | J7: =I7/$I$18 -> 0.063889765 | K7: =$B$29*J7 -> 3058275.3
A8: Morcidea AS | B8: 3961 | C8: 0.022 | E8: Morcidea AS | F8: =B8 -> 3961 | G8: =H8/$B$25 -> 991.29956 | H8: 250000 | I8: =F8+G8 -> 4952.2996 | J8: =I8/$I$18 -> 0.026366771 | K8: =$B$29*J8 -> 1262124.6
A9: T-E Invest AS | B9: 2695 | C9: 0.015 | E9: T-E Invest AS | F9: =B9 -> 2695 | G9: =H9/$B$25 -> 0 | H9: 0 | I9: =F9+G9 -> 2695 | J9: =I9/$I$18 -> 0.014348576 | K9: =$B$29*J9 -> 686837.66
A10: Quality Group Invest AS | B10: 520 | C10: 0.0029 | E10: Quality Group Invest AS (from FO AS) | F10: =B10 -> 520 | G10: =H10/$B$25 -> 396.51982 | H10: 100000 | I10: =F10+G10 -> 916.51982 | J10: =I10/$I$18 -> 0.0048796864 | K10: =$B$29*J10 -> 233580.83
A11: Mosby Holding Ltd | B11: 320 | C11: 0.0018 | E11: Mosby Holding Ltd(from FO as) | F11: =B11 -> 320 | G11: =H11/$B$25 -> 0 | H11: 0 | I11: =F11+G11 -> 320 | J11: =I11/$I$18 -> 0.0017037271 | K11: =$B$29*J11 -> 81554.008
A12: Haugjegla Invest AS | B12: 200 | C12: 0.0011 | E12: Haugjegla Invest AS (from FO as) | F12: =B12 -> 200 | G12: =H12/$B$25 -> 396.51982 | H12: 100000 | I12: =F12+G12 -> 596.51982 | J12: =I12/$I$18 -> 0.0031759593 | K12: =$B$29*J12 -> 152026.82
A13: Superiore Capital AS | B13: 320 | C13: 0.0018 | E13: Superiore Capital AS (from FO as) | F13: =B13 -> 320 | G13: =H13/$B$25 -> 396.51982 | H13: 100000 | I13: =F13+G13 -> 716.51982 | J13: =I13/$I$18 -> 0.003814857 | K13: =$B$29*J13 -> 182609.57
E14: New: Hinfra Invest AS | F14: 0 | G14: =H14/$B$25 -> 0 | H14: 0 | I14: =F14+G14 -> 0 | J14: =I14/$I$18 -> 0 | K14: =$B$29*J14 -> 0
E15: New: Preben Gulliksen | G15: =H15/$B$25 -> 1054.7427 | H15: 266000 | I15: =F15+G15 -> 1054.7427 | J15: =I15/$I$18 -> 0.0056156055 | K15: =$B$29*J15 -> 268807.8
A16: Proco as | B16: 500 | C16: 0.0028 | E16: New: Proco AS | F16: =B16 -> 500 | G16: =H16/$B$25 -> 0 | H16: 0 | I16: =F16+G16 -> 500 | J16: =I16/$I$18 -> 0.0026620736 | K16: =$B$29*J16 -> 127428.14
F17: =B17 -> 0 | G17: =H17/$B$25 -> 0 | I17: =F17+G17 -> 0 | J17: =I17/$I$18 -> 0 | K17: =$B$29*J17 -> 0
A18: Total | B18: =SUM(B3:B17) -> 180020 | C18: =SUM(C3:C17) -> 1.0001 | E18: Total | F18: =SUM(F3:F17) -> 180020 | G18: =SUM(G3:G17) -> 7803.5101 | H18: =SUM(H3:H17) -> 1968000 | I18: =SUM(I3:I17) -> 187823.51 | J18: =SUM(J3:J17) -> 1 | K18: =SUM(K3:K17) -> 47868000
A21: Calculations upcoming capital raise:
A22: Simulation inputs
A23: Shares | B23: =B18 -> 180020
A24: Pre money valuation | B24: 45400000
A25: Valuation per share | B25: =B24/B23 -> 252.1942
A27: Target gross proceeds | B27: 2468000
A28: New shares if valuation equals per share pre money | B28: =B27/B25 -> 9786.1093
A29: Post money valuation | B29: =B27+B24 -> 47868000
A30: Total outstanding shares in the company | B30: =B23+B28 -> 189806.11
A31: Offering % of the company outstanding shares | B31: =B28/B30 -> 0.051558452

Sheet Konvertibelt lån - 2 - 22.7
A1: Shareholder Book as of 18.10.2023 | E1: Calculations Shareholder sits after simulation | H1: = Commitment
A2: Ownership - Before converting to Pre-money MNOK 22,7`` | B2: Number of shares | C2: Owner sits | E2: Ownership - After converting to Pre-money MNOK 22,7`` | F2: Nr.of shares | G2: Nr.of new shares | H2: Commited Capital | I2: Total shares | J2: New owner sits | K2: Market Cap Post Money
A3: Ferdocean AS | B3: ='Konvertibelt lån - 1 - 45.4'!I3 -> 64980 | C3: ='Konvertibelt lån - 1 - 45.4'!J3 -> 0.34596308 | E3: Ferdocean AS | F3: =B3 -> 64980 | G3: =H3/$B$24 -> 0 | H3: 0 | I3: =F3+G3 -> 64980 | J3: =I3/$I$17 -> 0.33489816 | K3: =$B$28*J3 -> 7853361.9
A4: Gunnar Nordbø ENK | B4: ='Konvertibelt lån - 1 - 45.4'!I4 -> 36733.899 | C4: ='Konvertibelt lån - 1 - 45.4'!J4 -> 0.19557668 | E4: Gunnar Nordbø ENK | F4: =B4 -> 36733.899 | G4: =H4/$B$24 -> 6205.6226 | H4: 750000 | I4: =F4+G4 -> 42939.521 | J4: =I4/$I$17 -> 0.22130451 | K4: =$B$28*J4 -> 5189590.7
A5: MA`MOR Holdings SDN BHD | B5: ='Konvertibelt lån - 1 - 45.4'!I5 -> 29724 | C5: ='Konvertibelt lån - 1 - 45.4'!J5 -> 0.15825495 | E5: MA`MOR Holdings SDN BHD | F5: =B5 -> 29724 | G5: =H5/$B$24 -> 0 | H5: 0 | I5: =F5+G5 -> 29724 | J5: =I5/$I$17 -> 0.15319349 | K5: =$B$28*J5 -> 3592387.3
A6: Shield International Ltd | B6: ='Konvertibelt lån - 1 - 45.4'!I6 -> 32634.01 | C6: ='Konvertibelt lån - 1 - 45.4'!J6 -> 0.17374827 | E6: Shield International Ltd | F6: =B6 -> 32634.01 | G6: =H6/$B$24 -> 0 | H6: 0 | I6: =F6+G6 -> 32634.01 | J6: =I6/$I$17 -> 0.16819129 | K6: =$B$28*J6 -> 3944085.7
A7: Wilmar AS | B7: ='Konvertibelt lån - 1 - 45.4'!I7 -> 12000 | C7: ='Konvertibelt lån - 1 - 45.4'!J7 -> 0.063889765 | E7: Wilmar AS | F7: =B7 -> 12000 | G7: =H7/$B$24 -> 0 | H7: 0 | I7: =F7+G7 -> 12000 | J7: =I7/$I$17 -> 0.061846383 | K7: =$B$28*J7 -> 1450297.7
A8: Morcidea AS | B8: ='Konvertibelt lån - 1 - 45.4'!I8 -> 4952.2996 | C8: ='Konvertibelt lån - 1 - 45.4'!J8 -> 0.026366771 | E8: Morcidea AS | F8: =B8 -> 4952.2996 | G8: =H8/$B$24 -> 0 | H8: 0 | I8: =F8+G8 -> 4952.2996 | J8: =I8/$I$17 -> 0.025523484 | K8: =$B$28*J8 -> 598525.71
A9: T-E Invest AS | B9: ='Konvertibelt lån - 1 - 45.4'!I9 -> 2695 | C9: ='Konvertibelt lån - 1 - 45.4'!J9 -> 0.014348576 | E9: T-E Invest AS | F9: =B9 -> 2695 | G9: =H9/$B$24 -> 0 | H9: 0 | I9: =F9+G9 -> 2695 | J9: =I9/$I$17 -> 0.013889667 | K9: =$B$28*J9 -> 325712.69
A10: Quality Group Invest AS | B10: ='Konvertibelt lån - 1 - 45.4'!I10 -> 916.51982 | C10: ='Konvertibelt lån - 1 - 45.4'!J10 -> 0.0048796864 | E10: Quality Group Invest AS (from FO AS) | F10: =B10 -> 916.51982 | G10: =H10/$B$24 -> 0 | H10: 0 | I10: =F10+G10 -> 916.51982 | J10: =I10/$I$17 -> 0.0047236196 | K10: =$B$28*J10 -> 110768.88
A11: Mosby Holding Ltd | B11: ='Konvertibelt lån - 1 - 45.4'!I11 -> 320 | C11: ='Konvertibelt lån - 1 - 45.4'!J11 -> 0.0017037271 | E11: Mosby Holding Ltd(from FO as) | F11: =B11 -> 320 | G11: =H11/$B$24 -> 0 | H11: 0 | I11: =F11+G11 -> 320 | J11: =I11/$I$17 -> 0.0016492369 | K11: =$B$28*J11 -> 38674.605
A12: Haugjegla Invest AS | B12: ='Konvertibelt lån - 1 - 45.4'!I12 -> 596.51982 | C12: ='Konvertibelt lån - 1 - 45.4'!J12 -> 0.0031759593 | E12: Haugjegla Invest AS (from FO as) | F12: =B12 -> 596.51982 | G12: =H12/$B$24 -> 0 | H12: 0 | I12: =F12+G12 -> 596.51982 | J12: =I12/$I$17 -> 0.0030743828 | K12: =$B$28*J12 -> 72094.276
A13: Superiore Capital AS | B13: ='Konvertibelt lån - 1 - 45.4'!I13 -> 716.51982 | C13: ='Konvertibelt lån - 1 - 45.4'!J13 -> 0.003814857 | E13: Superiore Capital AS (from FO as) | F13: =B13 -> 716.51982 | G13: =H13/$B$24 -> 0 | H13: 0 | I13: =F13+G13 -> 716.51982 | J13: =I13/$I$17 -> 0.0036928466 | K13: =$B$28*J13 -> 86597.253
A14: Hinfra Invest AS | B14: ='Konvertibelt lån - 1 - 45.4'!I14 -> 0 | C14: ='Konvertibelt lån - 1 - 45.4'!J14 -> 0 | E14: New: Hinfra Invest AS(from FO as) | F14: =B14 -> 0 | G14: =H14/$B$24 -> 0 | H14: 0 | I14: =F14+G14 -> 0 | J14: =I14/$I$17 -> 0 | K14: =$B$28*J14 -> 0
... A16: Proco as | B16: ='Konvertibelt lån - 1 - 45.4'!I16 -> 500 | C16: ='Konvertibelt lån - 1 - 45.4'!J16 -> 0.0026620736 | E16: New: Proco AS (from FO AS) | F16: =B16 -> 500 | G16: =H16/$B$24 -> 0 | H16: 0 | I16: =F16+G16 -> 500 | J16: =I16/$I$17 -> 0.0025769326 | K16: =$B$28*J16 -> 60429.07
A17: Total | B17: =SUM(B3:B16) -> 187823.51 | C17: =SUM(C3:C16) -> 1 | E17: Total | F17: =SUM(F3:F16) -> 187823.51 | G17: =SUM(G3:G16) -> 6205.6226 | H17: =SUM(H3:H16) -> 750000 | I17: =SUM(I3:I16) -> 194029.13 | J17: =SUM(J3:J16) -> 1 | K17: =SUM(K3:K16) -> 23450000
A20: Calculations upcoming capital raise:
A21: Simulation inputs
A22: Shares | B22: =B17 -> 187823.51
A23: If Pre money valuation | B23: 22700000
A24: Valuation per share | B24: =B23/B22 -> 120.85814
A26: Target gross proceeds | B26: 750000
A27: New shares if valuation equals per share pre money | B27: =B26/B24 -> 6205.6226
A28: Post money valuation | B28: =B26+B23 -> 23450000
A29: Total outstanding shares in the company | B29: =B22+B27 -> 194029.13
A30: Offering % of the company outstanding shares | B30: =B27/B29 -> 0.031982942

Sheet Konvertibelt lån -  - 44.5
A1: Shareholder Book as of 18.10.2023 | E1: Calculations Shareholder sits after simulation | H1: = Commitment
A2: Ownership - Before converting to Pre-money MNOK 44,5`` | B2: Number of shares | C2: Owner sits | E2: Ownership - After converting to Pre-money MNOK 44,5`` | F2: Nr.of shares | G2: Nr.of new shares | H2: Commited Capital | I2: Total shares | J2: New owner sits | K2: Market Cap Post Money
A3: Ferdocean AS | B3: ='Konvertibelt lån - 1 - 45.4'!I3 -> 64980 | C3: ='Konvertibelt lån - 2 - 22.7'!J3 -> 0.33489816 | E3: Ferdocean AS | F3: =B3 -> 64980 | G3: =H3/$B$29 -> 0 | H3: 0 | I3: =F3+G3 -> 64980 | J3: =I3/$I$22 -> 0.33280063 | K3: =$B$33*J3 -> 15059228
A4: Gunnar Nordbø ENK | B4: ='Konvertibelt lån - 1 - 45.4'!I4 -> 36733.899 | C4: ='Konvertibelt lån - 2 - 22.7'!J4 -> 0.22130451 | E4: Gunnar Nordbø ENK | F4: =B4 -> 36733.899 | G4: =H4/$B$29 -> 1266.2259 | H4: ='Komitert Kap oversikt'!E22 -> 300000 | I4: =F4+G4 -> 38000.125 | J4: =I4/$I$22 -> 0.19462089 | K4: =$B$33*J4 -> 8806595.2
A5: MA`MOR Holdings SDN BHD | B5: ='Konvertibelt lån - 1 - 45.4'!I5 -> 29724 | C5: ='Konvertibelt lån - 2 - 22.7'!J5 -> 0.15319349 | E5: MA`MOR Holdings SDN BHD | F5: =B5 -> 29724 | G5: =H5/$B$29 -> 0 | H5: 0 | I5: =F5+G5 -> 29724 | J5: =I5/$I$22 -> 0.15223401 | K5: =$B$33*J5 -> 6888588.9
A6: Shield International Ltd | B6: ='Konvertibelt lån - 1 - 45.4'!I6 -> 32634.01 | C6: ='Konvertibelt lån - 2 - 22.7'!J6 -> 0.16819129 | E6: Shield International Ltd | F6: =B6 -> 32634.01 | G6: =H6/$B$29 -> 2110.3765 | H6: ='Komitert Kap oversikt'!E20 -> 500000 | I6: =F6+G6 -> 34744.386 | J6: =I6/$I$22 -> 0.17794635 | K6: =$B$33*J6 -> 8052072.1
A7: Wilmar AS | B7: ='Konvertibelt lån - 1 - 45.4'!I7 -> 12000 | C7: ='Konvertibelt lån - 2 - 22.7'!J7 -> 0.061846383 | E7: Wilmar AS | F7: =B7 -> 12000 | G7: =H7/$B$29 -> 0 | H7: 0 | I7: =F7+G7 -> 12000 | J7: =I7/$I$22 -> 0.061459026 | K7: =$B$33*J7 -> 2781020.9
A8: Morcidea AS | B8: ='Konvertibelt lån - 1 - 45.4'!I8 -> 4952.2996 | C8: ='Konvertibelt lån - 2 - 22.7'!J8 -> 0.025523484 | E8: Morcidea AS | F8: =B8 -> 4952.2996 | G8: =H8/$B$29 -> 1266.2259 | H8: ='Komitert Kap oversikt'!E21 -> 300000 | I8: =F8+G8 -> 6218.5255 | J8: =I8/$I$22 -> 0.03184871 | K8: =$B$33*J8 -> 1441154.1
A9: T-E Invest AS | B9: ='Konvertibelt lån - 1 - 45.4'!I9 -> 2695 | C9: ='Konvertibelt lån - 2 - 22.7'!J9 -> 0.013889667 | E9: T-E Invest AS | F9: =B9 -> 2695 | G9: =H9/$B$29 -> 0 | H9: 0 | I9: =F9+G9 -> 2695 | J9: =I9/$I$22 -> 0.013802673 | K9: =$B$33*J9 -> 624570.95
A10: Quality Group Invest AS | B10: ='Konvertibelt lån - 1 - 45.4'!I10 -> 916.51982 | C10: ='Konvertibelt lån - 2 - 22.7'!J10 -> 0.0047236196 | E10: Quality Group Invest AS (from FO AS) | F10: =B10 -> 916.51982 | G10: =H10/$B$29 -> 337.66024 | H10: ='Komitert Kap oversikt'!E24 -> 80000 | I10: =F10+G10 -> 1254.1801 | J10: =I10/$I$22 -> 0.0064233905 | K10: =$B$33*J10 -> 290658.42
A11: Mosby Holding Ltd | B11: ='Konvertibelt lån - 1 - 45.4'!I11 -> 320 | C11: ='Konvertibelt lån - 2 - 22.7'!J11 -> 0.0016492369 | E11: Mosby Holding Ltd(from FO as) | F11: =B11 -> 320 | G11: =H11/$B$29 -> 253.24518 | H11: ='Komitert Kap oversikt'!E27 -> 60000 | I11: =F11+G11 -> 573.24518 | J11: =I11/$I$22 -> 0.0029359242 | K11: =$B$33*J11 -> 132850.57
A12: Haugjegla Invest AS | B12: ='Konvertibelt lån - 1 - 45.4'!I12 -> 596.51982 | C12: ='Konvertibelt lån - 2 - 22.7'!J12 -> 0.0030743828 | E12: Haugjegla Invest AS (from FO as) | F12: =B12 -> 596.51982 | G12: =H12/$B$29 -> 253.24518 | H12: ='Komitert Kap oversikt'!E25 -> 60000 | I12: =F12+G12 -> 849.76501 | J12: =I12/$I$22 -> 0.0043521442 | K12: =$B$33*J12 -> 196934.52
A13: Superiore Capital AS | B13: ='Konvertibelt lån - 1 - 45.4'!I13 -> 716.51982 | C13: ='Konvertibelt lån - 2 - 22.7'!J13 -> 0.0036928466 | E13: Superiore Capital AS (from FO as) | F13: =B13 -> 716.51982 | G13: =H13/$B$29 -> 253.24518 | H13: ='Komitert Kap oversikt'!E26 -> 60000 | I13: =F13+G13 -> 969.76501 | J13: =I13/$I$22 -> 0.0049667344 | K13: =$B$33*J13 -> 224744.73
A14: Hinfra Invest AS | B14: ='Konvertibelt lån - 1 - 45.4'!I14 -> 0 | C14: ='Konvertibelt lån - 2 - 22.7'!C14 -> 0 | E14: New: Hinfra Invest AS | F14: =B14 -> 0 | G14: =H14/$B$29 -> 1266.2259 | H14: ='Komitert Kap oversikt'!E31 -> 300000 | I14: =F14+G14 -> 1266.2259 | J14: =I14/$I$22 -> 0.0064850843 | K14: =$B$33*J14 -> 293450.06
A15: Gulp Invest AS | B15: ='Konvertibelt lån - 1 - 45.4'!I15 -> 1054.7427 | C15: ='Konvertibelt lån - 2 - 22.7'!C15 -> 0.0056156055 | E15: Gulp Invest AS | F15: =B15 -> 1054.7427 | G15: =H15/$B$29 -> 0 | H15: 0 | I15: =F15+G15 -> 1054.7427 | J15: =I15/$I$22 -> 0.0054019551 | K15: =$B$33*J15 -> 244438.47
A16: Proco as | B16: ='Konvertibelt lån - 1 - 45.4'!I16 -> 500 | C16: ='Konvertibelt lån - 2 - 22.7'!C16 -> 0.0026620736 | E16: Proco AS (from FO as) | F16: =B16 -> 500 | G16: =H16/$B$29 -> 422.0753 | H16: ='Komitert Kap oversikt'!E23 -> 100000 | I16: =F16+G16 -> 922.0753 | J16: =I16/$I$22 -> 0.0047224875 | K16: =$B$33*J16 -> 213692.56
E17: ='Komitert Kap oversikt'!B28 -> New: Soleklar Holding (FO AS) | G17: =H17/$B$29 -> 422.0753 | H17: ='Komitert Kap oversikt'!E28 -> 100000 | I17: =F17+G17 -> 422.0753 | J17: =I17/$I$22 -> 0.0021616948 | K17: =$B$33*J17 -> 97816.688
E18: ='Komitert Kap oversikt'!B29 -> New: Havi Invest AS | G18: =H18/$B$29 -> 303.89422 | H18: ='Komitert Kap oversikt'!E29 -> 72000 | I18: =F18+G18 -> 303.89422 | J18: =I18/$I$22 -> 0.0015564202 | K18: =$B$33*J18 -> 70428.016
E19: ='Komitert Kap oversikt'!B30 -> New: Holme Holding AS (FO AS) | G19: =H19/$B$29 -> 422.0753 | H19: ='Komitert Kap oversikt'!E30 -> 100000 | I19: =F19+G19 -> 422.0753 | J19: =I19/$I$22 -> 0.0021616948 | K19: =$B$33*J19 -> 97816.688
E20: ='Komitert Kap oversikt'!B32 -> New: Fivel Holding AS (FO AS) | G20: =H20/$B$29 -> 2110.3765 | H20: ='Komitert Kap oversikt'!E32 -> 500000 | I20: =F20+G20 -> 2110.3765 | J20: =I20/$I$22 -> 0.010808474 | K20: =$B$33*J20 -> 489083.44
E21: ='Komitert Kap oversikt'!B33 -> New: Stanjo AS (FO AS) | G21: =H21/$B$29 -> 1055.1883 | H21: ='Komitert Kap oversikt'!E33 -> 250000 | I21: =F21+G21 -> 1055.1883 | J21: =I21/$I$22 -> 0.0054042369 | K21: =$B$33*J21 -> 244541.72
A22: Total | B22: =SUM(B3:B16) -> 187823.51 | C22: =SUM(C3:C16) -> 1.0002647 | E22: Total | F22: =SUM(F3:F16) -> 187823.51 | G22: =SUM(G3:G16) -> 7428.5253 | H22: =SUM(H3:H21) -> 2782000 | I22: =SUM(I3:I16) -> 195252.04 | J22: =SUM(J3:J16) -> 1 | K22: =SUM(K3:K16) -> 45250000
A25: Calculations upcoming capital raise:
A26: Simulation inputs
A27: Shares | B27: =B22 -> 187823.51
A28: If Pre money valuation | B28: 44500000
A29: Valuation per share | B29: =B28/B27 -> 236.92455
A31: Target gross proceeds | B31: 750000
A32: New shares if valuation equals per share pre money | B32: =B31/B29 -> 3165.5648
A33: Post money valuation | B33: =B31+B28 -> 45250000
A34: Total outstanding shares in the company | B34: =B27+B32 -> 190989.07
A35: Offering % of the company outstanding shares | B35: =B32/B34 -> 0.016574586

Sheet Konvertibelt lån - 10 
A1: Shareholder Book as of 18.10.2023 | E1: Calculations Shareholder sits after simulation | H1: = Commitment
A2: Ownership - Before converting to Pre-money MNOK 10`` | B2: Number of shares | C2: Owner sits | E2: Ownership - After converting to Pre-money MNOK 10`` | F2: Nr.of shares | G2: Nr.of new shares | H2: Commited Capital | I2: Total shares | J2: New owner sits | K2: Market Cap Post Money
A3: Ferdocean AS | B3: ='Konvertibelt lån - - 44.5'!I3 -> 64980 | C3: ='Konvertibelt lån - - 44.5'!J3 -> 0.33280063 | D3: 0 | E3: Ferdocean AS | F3: =B3 -> 64980 | G3: =H3/$B$29 -> 0 | H3: 0 | I3: =F3+G3 -> 64980 | J3: =I3/$I$22 -> 0.27733386 | K3: =$B$33*J3 -> 2981339
A4: Gunnar Nordbø ENK | B4: ='Konvertibelt lån - - 44.5'!I4 -> 38000.125 | C4: ='Konvertibelt lån - - 44.5'!J4 -> 0.19462089 | E4: Gunnar Nordbø ENK | F4: =B4 -> 38000.125 | G4: =H4/$B$29 -> 0 | H4: 0 | I4: =F4+G4 -> 38000.125 | J4: =I4/$I$22 -> 0.16218407 | K4: =$B$33*J4 -> 1743478.8
A5: MA`MOR Holdings SDN BHD | B5: ='Konvertibelt lån - - 44.5'!I5 -> 29724 | C5: ='Konvertibelt lån - - 44.5'!J5 -> 0.15223401 | D5: 0 | E5: MA`MOR Holdings SDN BHD | F5: =B5 -> 29724 | G5: =H5/$B$29 -> 0 | H5: 0 | I5: =F5+G5 -> 29724 | J5: =I5/$I$22 -> 0.12686167 | K5: =$B$33*J5 -> 1363763
A6: Shield International Ltd | B6: ='Konvertibelt lån - - 44.5'!I6 -> 34744.386 | C6: ='Konvertibelt lån - - 44.5'!J6 -> 0.17794635 | D6: 0 | E6: Shield International Ltd | F6: =B6 -> 34744.386 | G6: =H6/$B$29 -> 0 | H6: 0 | I6: =F6+G6 -> 34744.386 | J6: =I6/$I$22 -> 0.14828862 | K6: =$B$33*J6 -> 1594102.7
A7: Wilmar AS | B7: ='Konvertibelt lån - - 44.5'!I7 -> 12000 | C7: ='Konvertibelt lån - - 44.5'!J7 -> 0.061459026 | D7: 0 | E7: Wilmar AS | F7: =B7 -> 12000 | G7: =H7/$B$29 -> 0 | H7: 0 | I7: =F7+G7 -> 12000 | J7: =I7/$I$22 -> 0.051215855 | K7: =$B$33*J7 -> 550570.44
A8: Morcidea AS | B8: ='Konvertibelt lån - - 44.5'!I8 -> 6218.5255 | C8: ='Konvertibelt lån - - 44.5'!J8 -> 0.03184871 | E8: Morcidea AS | F8: =B8 -> 6218.5255 | G8: =H8/$B$29 -> 19525.204 | H8: 1000000 | I8: =F8+G8 -> 25743.729 | J8: =I8/$I$22 -> 0.10987393 | K8: =$B$33*J8 -> 1181144.7
A9: T-E Invest AS | B9: ='Konvertibelt lån - - 44.5'!I9 -> 2695 | C9: ='Konvertibelt lån - - 44.5'!J9 -> 0.013802673 | E9: T-E Invest AS | F9: =B9 -> 2695 | G9: =H9/$B$29 -> 0 | H9: 0 | I9: =F9+G9 -> 2695 | J9: =I9/$I$22 -> 0.011502228 | K9: =$B$33*J9 -> 123648.95
A10: Quality Group Invest AS | B10: ='Konvertibelt lån - - 44.5'!I10 -> 1254.1801 | C10: ='Konvertibelt lån - - 44.5'!J10 -> 0.0064233905 | D10: 0 | E10: Quality Group Invest AS (from FO AS) | F10: =B10 -> 1254.1801 | G10: =H10/$B$29 -> 19525.204 | H10: 1000000 | I10: =F10+G10 -> 20779.384 | J10: =I10/$I$22 -> 0.088686159 | K10: =$B$33*J10 -> 953376.21
A11: Mosby Holding Ltd | B11: ='Konvertibelt lån - - 44.5'!I11 -> 573.24518 | C11: ='Konvertibelt lån - - 44.5'!J11 -> 0.0029359242 | D11: 0 | E11: Mosby Holding Ltd(from FO as) | F11: =B11 -> 573.24518 | G11: =H11/$B$29 -> 0 | H11: 0 | I11: =F11+G11 -> 573.24518 | J11: =I11/$I$22 -> 0.0024466035 | K11: =$B$33*J11 -> 26300.988
A12: Haugjegla Invest AS | B12: ='Konvertibelt lån - - 44.5'!I12 -> 849.76501 | C12: ='Konvertibelt lån - - 44.5'!J11 -> 0.0029359242 | D12: 0 | E12: Haugjegla Invest AS (from FO as) | F12: =B12 -> 849.76501 | G12: =H12/$B$29 -> 0 | H12: 0 | I12: =F12+G12 -> 849.76501 | J12: =I12/$I$22 -> 0.0036267868 | K12: =$B$33*J12 -> 38987.958
A13: Superiore Capital AS | B13: ='Konvertibelt lån - - 44.5'!I13 -> 969.76501 | C13: ='Konvertibelt lån - - 44.5'!J13 -> 0.0049667344 | D13: 0 | E13: Superiore Capital AS (from FO as) | F13: =B13 -> 969.76501 | G13: =H13/$B$29 -> 0 | I13: =F13+G13 -> 969.76501 | J13: =I13/$I$22 -> 0.0041389454 | K13: =$B$33*J13 -> 44493.663
A14: Hinfra Invest AS | B14: ='Konvertibelt lån - - 44.5'!I14 -> 1266.2259 | C14: ='Konvertibelt lån - - 44.5'!J14 -> 0.0064850843 | D14: 0 | E14: New: Hinfra Invest AS | F14: =B14 -> 1266.2259 | G14: =H14/$B$29 -> 0 | H14: 0 | I14: =F14+G14 -> 1266.2259 | J14: =I14/$I$22 -> 0.0054042369 | K14: =$B$33*J14 -> 58095.547
A15: Gulp Invest AS | B15: ='Konvertibelt lån - - 44.5'!I15 -> 1054.7427 | C15: ='Konvertibelt lån - - 44.5'!J15 -> 0.0054019551 | D15: 0 | E15: Gulp Invest AS | F15: =B15 -> 1054.7427 | G15: =H15/$B$29 -> 0 | H15: 0 | I15: =F15+G15 -> 1054.7427 | J15: =I15/$I$22 -> 0.0045016293 | K15: =$B$33*J15 -> 48392.515
A16: Proco as | B16: ='Konvertibelt lån - - 44.5'!I16 -> 922.0753 | C16: ='Konvertibelt lån - - 44.5'!J16 -> 0.0047224875 | D16: 0 | E16: Proco AS (from FO as) | F16: =B16 -> 922.0753 | G16: =H16/$B$29 -> 0 | H16: 0 | I16: =F16+G16 -> 922.0753 | J16: =I16/$I$22 -> 0.0039354063 | K16: =$B$33*J16 -> 42305.617
A17: Soleklar Holding AS | B17: ='Konvertibelt lån - - 44.5'!I17 -> 422.0753 | C17: ='Konvertibelt lån - - 44.5'!J17 -> 0.0021616948 | E17: ='Komitert Kap oversikt'!B28 -> New: Soleklar Holding (FO AS) | F17: =B17 -> 422.0753 | G17: =H17/$B$29 -> 0 | H17: 0 | I17: =F17+G17 -> 422.0753 | J17: =I17/$I$22 -> 0.0018014123 | K17: =$B$33*J17 -> 19365.182
A18: Havi Invest AS | B18: ='Konvertibelt lån - - 44.5'!I18 -> 303.89422 | C18: ='Konvertibelt lån - - 44.5'!J18 -> 0.0015564202 | E18: ='Komitert Kap oversikt'!B29 -> New: Havi Invest AS | F18: =B18 -> 303.89422 | G18: =H18/$B$29 -> 0 | H18: 0 | I18: =F18+G18 -> 303.89422 | J18: =I18/$I$22 -> 0.0012970169 | K18: =$B$33*J18 -> 13942.931
A19: Holme Holding AS | B19: ='Konvertibelt lån - - 44.5'!I19 -> 422.0753 | C19: ='Konvertibelt lån - - 44.5'!J19 -> 0.0021616948 | E19: ='Komitert Kap oversikt'!B30 -> New: Holme Holding AS (FO AS) | F19: =B19 -> 422.0753 | G19: =H19/$B$29 -> 0 | H19: 0 | I19: =F19+G19 -> 422.0753 | J19: =I19/$I$22 -> 0.0018014123 | K19: =$B$33*J19 -> 19365.182
A20: Fivel Holding AS | B20: ='Konvertibelt lån - - 44.5'!I20 -> 2110.3765 | C20: ='Konvertibelt lån - - 44.5'!J20 -> 0.010808474 | E20: ='Komitert Kap oversikt'!B32 -> New: Fivel Holding AS (FO AS) | F20: =B20 -> 2110.3765 | G20: =H20/$B$29 -> 0 | H20: 0 | I20: =F20+G20 -> 2110.3765 | J20: =I20/$I$22 -> 0.0090070615 | K20: =$B$33*J20 -> 96825.912
A21: Stanjo AS | B21: ='Konvertibelt lån - - 44.5'!I21 -> 1055.1883 | C21: ='Konvertibelt lån - - 44.5'!J21 -> 0.0054042369 | E21: ='Komitert Kap oversikt'!B33 -> New: Stanjo AS (FO AS) | F21: =B21 -> 1055.1883 | G21: =H21/$B$29 -> 0 | H21: 0 | I21: =F21+G21 -> 1055.1883 | J21: =I21/$I$22 -> 0.0045035308 | K21: =$B$33*J21 -> 48412.956
A22: Total | B22: =SUM(B3:B16) -> 195252.04 | C22: =SUM(C3:C16) -> 0.99858378 | E22: Total | F22: =SUM(F3:F16) -> 195252.04 | G22: =SUM(G3:G16) -> 39050.407 | H22: =SUM(H3:H21) -> 2000000 | I22: =SUM(I3:I16) -> 234302.44 | J22: =SUM(J3:J16) -> 1 | K22: =SUM(K3:K16) -> 10750000
A25: Calculations upcoming capital raise:
A26: Simulation inputs
A27: Shares | B27: =B22 -> 195252.04
A28: If Pre money valuation | B28: 10000000
A29: Valuation per share | B29: =B28/B27 -> 51.215855
A31: Target gross proceeds | B31: 750000
A32: New shares if valuation equals per share pre money | B32: =B31/B29 -> 14643.903
A33: Post money valuation | B33: =B31+B28 -> 10750000
A34: Total outstanding shares in the company | B34: =B27+B32 -> 209895.94
A35: Offering % of the company outstanding shares | B35: =B32/B34 -> 0.069767442

Sheet Komitert Kap oversikt
B2: Låneramme | E2: 6000000
B4: Runde 1 - Nov 2023 | C4: Kommitert | D4: Signert | E4: Konvertering 44,5 MNOK
B5: Gunnar Nordbø ENK | C5: V | D5: V | E5: 1500000 | F5: 750K til konvertering 22.7MNOK
B6: Shield International Ltd | C6: V | D6: V | E6: 402000
B7: Morcidea AS | C7: V | D7: V | E7: 250000
B8: Quality Group Invest AS (from FO AS) | C8: V | D8: V | E8: 100000
B9: Haugjegla Invest AS (from FO as) | C9: V | D9: V | E9: 100000
B10: Superiore Capital AS (from FO as) | C10: V | D10: V | E10: 100000
B11: New: Gulp Invest AS | C11: V | D11: V | E11: 266000
B12: Sum runde 1 | E12: =SUM(E5:E11) -> 2718000
B14: Runde 2 - Mars 2024 | C14: Kommitert | D14: Signert | E14: Konvertering 44,5 MNOK
B15: Shield International Ltd | C15: V | D15: V | E15: 400000
B16: Quality Group Invest AS (from FO AS) | C16: V | D16: V | E16: 100000
B17: Sum runde 2 | E17: =SUM(E15:E16) -> 500000
B19: Juli 2024 | C19: Kommitert | D19: Signert | E19: Konvertering 44,5 MNOK
B20: Shield International Ltd | C20: V | D20: V | E20: 500000
B21: Morcidea AS | C21: V | D21: V | E21: 300000
B22: Gunnar Norbbø ENK | C22: V | D22: V | E22: 300000
B23: Proco AS | C23: V | D23: V | E23: 100000 | F23: Forbehold tegning 2.7MNOK minimum.
B24: Quality Group Invest AS (FO AS) | C24: V | D24: V | E24: 80000
B25: Haugjegla Invest AS (FO AS) | C25: V | D25: V | E25: 60000
B26: Superiore Capital AS (FO AS) | C26: V | D26: V | E26: 60000
B27: Mosby Holding ltd (FO AS) | C27: V | D27: V | E27: 60000
B28: New: Soleklar Holding (FO AS) | C28: V | D28: V | E28: 100000 | F28: Forbehold tegning 2.7MNOK minimum.
B29: New: Havi Invest AS | C29: V | D29: V | E29: 72000
B30: New: Holme Holding AS (FO AS) | C30: V | D30: V | E30: 100000 | F30: Forbehold tegning 2.7MNOK minimum.
B31: New: Hinfra Invest AS (FO AS) | C31: V | D31: V | E31: 300000 | F31: Forbehold tegning 2.7MNOK minimum.
B32: New: Fivel Holding AS (FO AS) | C32: V | D32: V | E32: 500000
B33: New: Stanjo AS (FO AS) | C33: V | D33: V | E33: 250000 | F33: Forbehold tegning 2.7MNOK minimum.
B34: Sum | E34: =SUM(E20:E33) -> 2782000
B36: Bro Kapital - Hjelp fra Rasmus Nordbø | C36: V
B37: Rasmus Nordbø | E37: 120000 | F37: Flyttes over til Brødrene Nordbø AS i neste runde (se under)
B40: Q3-Q4 2024 | C40: Kommitert | D40: Signert | E40: Lånekappital 1,12 MNOK
B41: Shield International Ltd | C41: V | D41: V | E41: 355000
B42: Morcidea AS | C42: V | E42: 100000
B43: Gunnar Norbbø ENK | C43: V | E43: 250000 | F43: Via Brødrene Nordbø AS - (120K skal tilbakebet Rasmus Nordbø)
B44: Proco AS | E44: 0
B45: Quality Group Invest AS (FO AS) | C45: V | D45: V | E45: 75000
B46: Haugjegla Invest AS (FO AS) | E46: 0
B47: Superiore Capital AS (FO AS) | C47: V | D47: V | E47: 75000
...

Sheet Kontaktinfo
A2: Ferdocean AS | B2: Bjørnar Iversen | C2: Bjornar@wefollowheroes.com Bjornar.Iversen@dolphindrilling.com | D2: 93240417
A3: Gunnar Nordbø ENK | B3: Rasmus Nordbø | C3: rasmus@fiska.no | D3: 41628515
A4: MA`MOR Holdings SDN BHD | B4: Musa Adinin | C4: musa@adinin.com | D4: +6738733111
A5: Shield International Ltd | B5: Musa Adinin | C5: musa@adinin.com
A6: Wilmar AS | B6: Preben Gulliksen | C6: preben.gulliksen@pizzabakeren.no | D6: 47203535
A7: Morcidea AS | B7: Arne Gåskjenn | C7: ag@morcidea.no | D7: 46131992
A8: T-E Invest AS | B8: Tor Axel Shwerdt | C8: tasc@svw.no | D8: 40639606
A9: Quality Group Invest AS (from FO AS) | B9: Tore Ausland | C9: ta@vikenklynge.no | D9: 90548048
A10: Mosby Holding Ltd(from FO as) | B10: Hans Erik Sæther | C10: hsaether@ferdocean.com | D10: 95181522
A11: Haugjegla Invest AS (from FO as) | B11: Bjørnar Iversen | C11: Bjornar@wefollowheroes.com Bjornar.Iversen@dolphindrilling.com | D11: 93240417
A12: Superiore Capital AS (from FO as) | B12: Runar Nilsen | C12: rnilsen@ferdocean.com | D12: 95243342
A13: Proco AS | B13: Jens Petter Røkenes | C13: jens.rokenes@gmail.com | D13: 91396125
