Workbook

Sheet %Cost vs Budget
A1: Partner | B1: Used of Budget
A2: GOT | B2: 20.498143
A3: MNU | B3: 29.334355
A4: SCA | B4: 22.228008
A5: FOC | B5: 23.329146
A6: CLTV | B6: 15.344396
A7: MAI | B7: 10.421054
A8: BIN | B8: 7.6098034
A9: IOC | B9: 6.7956784
A10: HIE | B10: 22.468177
A11: BAL | B11: 45.780785
A12: MEERI | B12: 23.913983
A13: MCN | B13: 11.289715
A14: CKR | B14: 33.117715

Sheet WP Cost VS Budget
B23: Task/WP | C23: TOTAL COST | D23: TOTAL BUDGET
B24: WP1 | C24: =SUM('Direct &Indirect Personnal Cost'!C7) -> 107552.18 | D24: =SUM('Direct &Indirect Personnal Cost'!E7) -> 226991.17
B25: T1.1 | C25: =SUM('Direct &Indirect Personnal Cost'!C8) -> 41951.054 | D25: =SUM('Direct &Indirect Personnal Cost'!E8) -> 88440.74
B26: T1.2 | C26: =SUM('Direct &Indirect Personnal Cost'!C9) -> 30527.424 | D26: =SUM('Direct &Indirect Personnal Cost'!E9) -> 53116.01
B27: T1.3 | C27: =SUM('Direct &Indirect Personnal Cost'!C10) -> 31448.39 | D27: =SUM('Direct &Indirect Personnal Cost'!E10) -> 85434.42
B38: Task/WP | C38: TOTAL COST | D38: TOTAL BUDGET
B39: WP2 | C39: =SUM('Direct &Indirect Personnal Cost'!C11) -> 67975.266 | D39: =SUM('Direct &Indirect Personnal Cost'!E11) -> 153493.81
B40: T2.1 | C40: =SUM('Direct &Indirect Personnal Cost'!C12) -> 19638.134 | D40: =SUM('Direct &Indirect Personnal Cost'!E12) -> 67887.51
B41: T2.2 | C41: =SUM('Direct &Indirect Personnal Cost'!C13) -> 5204.3416 | D41: =SUM('Direct &Indirect Personnal Cost'!E13) -> 3343.75
B42: T2.3 | C42: =SUM('Direct &Indirect Personnal Cost'!C14) -> 10843.042 | D42: =SUM('Direct &Indirect Personnal Cost'!E14) -> 12525
B43: T2.4 | C43: =SUM('Direct &Indirect Personnal Cost'!C15) -> 32340.659 | D43: =SUM('Direct &Indirect Personnal Cost'!E15) -> 69737.55
B53: Task/WP | C53: TOTAL COST | D53: TOTAL BUDGET
B54: WP3 | C54: =SUM('Direct &Indirect Personnal Cost'!C16) -> 84518.515 | D54: =SUM('Direct &Indirect Personnal Cost'!E16) -> 434125.12
B55: T3.1 | C55: =SUM('Direct &Indirect Personnal Cost'!C17) -> 47272.495 | D55: =SUM('Direct &Indirect Personnal Cost'!E17) -> 68475.03
B56: T3.2 | C56: =SUM('Direct &Indirect Personnal Cost'!C18) -> 14726.043 | D56: =SUM('Direct &Indirect Personnal Cost'!E18) -> 18562.5
B57: T3.3 | C57: =SUM('Direct &Indirect Personnal Cost'!C19) -> 15885.025 | D57: =SUM('Direct &Indirect Personnal Cost'!E19) -> 121637.57
B58: T3.4 | C58: =SUM('Direct &Indirect Personnal Cost'!C20) -> 0 | D58: =SUM('Direct &Indirect Personnal Cost'!E20) -> 26750
B59: T3.5 | C59: =SUM('Direct &Indirect Personnal Cost'!C21) -> 0 | D59: =SUM('Direct &Indirect Personnal Cost'!E21) -> 26750
B60: T3.6 | C60: =SUM('Direct &Indirect Personnal Cost'!C22) -> 6187.5 | D60: =SUM('Direct &Indirect Personnal Cost'!E22) -> 171950.02
B68: Task/WP | C68: TOTAL COST | D68: TOTAL BUDGET
B69: WP4 | C69: =SUM('Direct &Indirect Personnal Cost'!C23) -> 21952.603 | D69: =SUM('Direct &Indirect Personnal Cost'!E23) -> 700689.32
B70: T4.1 | C70: =SUM('Direct &Indirect Personnal Cost'!C24) -> 8347.2261 | D70: =SUM('Direct &Indirect Personnal Cost'!E24) -> 24218.75
B71: T4.2 | C71: =SUM('Direct &Indirect Personnal Cost'!C25) -> 5371.85 | D71: =SUM('Direct &Indirect Personnal Cost'!E25) -> 169499.08
B72: T4.3 | C72: =SUM('Direct &Indirect Personnal Cost'!C26) -> 326.75 | D72: =SUM('Direct &Indirect Personnal Cost'!E26) -> 113875.05
B73: T4.4 | C73: =SUM('Direct &Indirect Personnal Cost'!C27) -> 0 | D73: =SUM('Direct &Indirect Personnal Cost'!E27) -> 70268.81
B74: T4.5 | C74: =SUM('Direct &Indirect Personnal Cost'!C28) -> 359.90748 | D74: =SUM('Direct &Indirect Personnal Cost'!E28) -> 114196.76
B75: T4.6 | C75: =SUM('Direct &Indirect Personnal Cost'!C29) -> 230.555 | D75: =SUM('Direct &Indirect Personnal Cost'!E29) -> 6925
B76: T4.7 | C76: =SUM('Direct &Indirect Personnal Cost'!C30) -> 798.075 | D76: =SUM('Direct &Indirect Personnal Cost'!E30) -> 54018.33
B77: T4.8 | C77: =SUM('Direct &Indirect Personnal Cost'!C31) -> 595.19468 | D77: =SUM('Direct &Indirect Personnal Cost'!E31) -> 53087.47
B78: T4.9 | C78: =SUM('Direct &Indirect Personnal Cost'!C32) -> 5748.05 | D78: =SUM('Direct &Indirect Personnal Cost'!E32) -> 94600.07
B83: Task/WP | C83: TOTAL COST | D83: TOTAL BUDGET
B84: WP5 | C84: =SUM('Direct &Indirect Personnal Cost'!C33) -> 42546.324 | D84: =SUM('Direct &Indirect Personnal Cost'!E33) -> 148095.23
B85: T5.1 | C85: =SUM('Direct &Indirect Personnal Cost'!C34) -> 40961.187 | D85: =SUM('Direct &Indirect Personnal Cost'!E34) -> 55221.35
B86: T5.2 | C86: =SUM('Direct &Indirect Personnal Cost'!C35) -> 771.5 | D86: =SUM('Direct &Indirect Personnal Cost'!E35) -> 55221.35
B87: T5.3 | C87: =SUM('Direct &Indirect Personnal Cost'!C36) -> 796.20625 | D87: =SUM('Direct &Indirect Personnal Cost'!E36) -> 37652.53
B98: Task/WP | C98: TOTAL COST | D98: TOTAL BUDGET
B99: WP6 | C99: =SUM('Direct &Indirect Personnal Cost'!C37) -> 56508.95 | D99: =SUM('Direct &Indirect Personnal Cost'!E37) -> 231218.95
B100: T6.1 | C100: =SUM('Direct &Indirect Personnal Cost'!C38) -> 39463.093 | D100: =SUM('Direct &Indirect Personnal Cost'!E38) -> 55825.06
B101: T6.2 | C101: =SUM('Direct &Indirect Personnal Cost'!C39) -> 10860.063 | D101: =SUM('Direct &Indirect Personnal Cost'!E39) -> 108168.84
B102: T6.3 | C102: =SUM('Direct &Indirect Personnal Cost'!C40) -> 1066.5956 | D102: =SUM('Direct &Indirect Personnal Cost'!E40) -> 67225.05
...

Sheet Direct &Indirect Personnal Cost
A2: ALL DIRECT & INDIRECT COST CALCULATIONS PER PARTNER
A3: TOTAL BUDGET IS NOT EQUAL TO EC CONTRIBUTION DUE TO THE SME PARTNERS
A4: 70%.
A5: GreenOfshoreTech TOTAL (Period M1 to M9) | B5: Task/ WP | C5: TOTAL COST | D5: Other Dir. Cost Budget | E5: TOTAL BUDGET | F5: % spend | G5: MNU COST | H5: Other Dir. Cost Budget | I5: MNU BUDGET | J5: % spend | K5: SCA COST | L5: Other Dir. Cost Budget | M5: SCA BUDGET | N5: % spend | O5: FOC COST | P5: Other Dir. Cost Budget | Q5: FOC BUDGET | R5: % spend | S5: CTLV COST | T5: Other Dir. Cost Budget | U5: CTLV BUDGET | V5: % spend | W5: MAI COST | X5: Other Dir. Cost | Y5: MAI BUDGET | Z5: % spend | AA5: BIN COST | AB5: Other Dir. Cost | AC5: BIN BUDGET | AD5: % spend | AE5: IOC COST | AF5: Other Dir. Cost | AG5: IOC BUDGET | AH5: % spend | AI5: HIE COST | AJ5: Other Dir. Cost | AK5: HIE BUDGET | AL5: % spend | AM5: BAL COST | AN5: Other Dir. Cost | AO5: BAL BUDGET | AP5: % spend | AQ5: MEERI COST | AR5: Other Dir. Cost | AS5: MEERI BUDGET | AT5: % spend | AU5: MCN COST | AV5: Other Dir. Cost | AW5: MCN BUDGET | AX5: % spend | AY5: CKR COST | AZ5: Other Dir. Cost | BA5: CKR BUDGET | BB5: % spend
A6: Otherdirect Cost ( travel, equipment & Other goods and services)(ODC) | B6: ODC | C6: 0 | E6: =SUM(I6+M6+Q6+U6+Y6+AC6+AG6+AK6+AO6+AS6+AW6+BA6) -> 343929 | F6: =100/E6*C6 -> 0 | G6: 0 | I6: 39500 | J6: =100/I6*G6 -> 0 | K6: 0 | M6: 20750 | N6: =100/M6*K6 -> 0 | O6: 0 | Q6: 42500 | R6: =100/Q6*O6 -> 0 | S6: 0 | U6: 20750 | V6: =100/U6*S6 -> 0 | W6: =SUM(MAI!D6) -> 0 | Y6: 20750 | Z6: =100/Y6*W6 -> 0 | AA6: 0 | AC6: 56429 | AD6: =100/AC6*AA6 -> 0 | AE6: =SUM(IOC!K9) -> 0 | AG6: 20750 | AH6: =100/AG6*AE6 -> 0 | AI6: =SUM(HIE!L9) -> 5763.75 | AK6: 20750 | AL6: =100/AK6*AI6 -> 27.777108 | AM6: 0 | AO6: =SUM(BAL!Q1*BAL!$S$1) -> 20750 | AP6: =100/AO6*AM6 -> 0 | AQ6: 0 | AS6: =SUM(MEERI!M1*MEERI!$O$1) -> 20750 | AT6: =100/AS6*AQ6 -> 0 | AU6: 0 | AW6: =SUM(MCN!V1*MCN!$T$1) -> 39500 | AX6: =100/AW6*AU6 -> 0 | AY6: 0 | BA6: 20750 | BB6: =100/BA6*AY6 -> 0
A7: Assessment of potential new value chains and selection of Topics for Call of Proposals | B7: WP1 | C7: =SUM(G7+K7+O7+S7+W7+AA7+AE7+AI7+AM7+AQ7+AU7+AY7) -> 107552.18 | D7: =SUM(H7+L7+P7+T7+X7+AB7+AF7+AJ7+AN7+AR7+AV7+AZ7) -> 31600 | E7: =SUM(I7+M7+Q7+U7+Y7+AC7+AG7+AG7+AK7+AO7+AS7+AW7+BA7) -> 226991.17 | F7: =100/E7*C7 -> 47.381657 | G7: {=MNU!C7:C45} -> 8024.875 | H7: =SUM(H8:H10) -> 31600 | I7: =SUM(I8:I10) -> 20062.5 | J7: =100/I7*G7 -> 39.999377 | K7: {=SCA!D8:D46} -> 13497.165 | L7: =SUM(L8:L10) -> 0 | M7: =SUM(M8:M10) -> 11712.46 | N7: =100/M7*K7 -> 115.23766 | O7: {=FOC!D8:D46} -> 1875.625 | P7: =SUM(P8:P10) -> 0 | Q7: =SUM(Q8:Q10) -> 7790.62 | R7: =100/Q7*O7 -> 24.075427 | S7: {=CLTV!I10:I48} -> 6823.4177 | T7: =SUM(T8:T10) -> 0 | U7: =SUM(U8:U10) -> 10546.88 | V7: =100/U7*S7 -> 64.696078 | W7: =SUM(MAI!D7) -> 12627.337 | X7: =SUM(X8:X10) -> 0 | Y7: =SUM(Y8:Y10) -> 31484.38 | Z7: =100/Y7*W7 -> 40.106674 | AA7: {=BIN!C8:C46} -> 16250.922 | AB7: =SUM(AB8:AB10) -> 0 | AC7: =SUM(AC8:AC10) -> 36562.5 | AD7: =100/AC7*AA7 -> 44.446966 | AE7: =SUM(IOC!K10) -> 2402.5312 | AF7: =SUM(AF8:AF10) -> 0 | AG7: =SUM(AG8:AG10) -> 17306.54 | AH7: =100/AG7*AE7 -> 13.882216 | AI7: =SUM(HIE!L10) -> 12255.246 | AJ7: =SUM(AJ8:AJ10) -> 0 | AK7: =SUM(AK8:AK10) -> 23906.25 | AL7: =100/AK7*AI7 -> 51.263774 | AM7: {=BAL!G9:G47} -> 13402.888 | AN7: =SUM(AN8:AN10) -> 0 | AO7: =SUM(AO8:AO10) -> 12375 | AP7: =100/AO7*AM7 -> 108.30616 | AQ7: {=MEERI!G10:G48} -> 8319.05 | AR7: =SUM(AR8:AR10) -> 0 | AS7: =SUM(AS8:AS10) -> 13406.25 | AT7: =100/AS7*AQ7 -> 62.05352 | AU7: {=MCN!C7:C45} -> 7696.99 | AV7: =SUM(AV8:AV10) -> 0 | AW7: =SUM(AW8:AW10) -> 10312.5 | AX7: =100/AW7*AU7 -> 74.637479 | AY7: ='CKR '!C6 -> 4376.13 | AZ7: =SUM(AZ8:AZ10) -> 0 | BA7: =SUM(BA8:BA10) -> 14218.75 | BB7: =100/BA7*AY7 -> 30.777178
A8: Sustainable challenges, needs and trends of four industrial offshore sectors | B8: T1.1 | C8: =SUM(G8+K8+O8+S8+W8+AA8+AE8+AI8+AM8+AQ8+AU8+AY8) -> 41951.054 | D8: =SUM(H8+L8+P8+T8+X8+AB8+AF8+AJ8+AN8+AR8+AV8+AZ8) -> 31600 | E8: =SUM(I8+M8+Q8+U8+Y8+AC8+AG8+AG8+AK8+AO8+AS8+AW8+BA8) -> 88440.74 | F8: =100/E8*C8 -> 47.434083 | G8: 3265.9375 | H8: 31600 | I8: 13375 | J8: =100/I8*G8 -> 24.418224 | K8: 6648.4552 | M8: 5856.22 | N8: =100/M8*K8 -> 113.5281 | O8: 780.13 | Q8: 3462.5 | R8: =100/Q8*O8 -> 22.53083 | S8: 508.68068 | U8: 4687.5 | V8: =100/U8*S8 -> 10.851855 | W8: =SUM(MAI!D8) -> 0 | Y8: 2421.88 | Z8: =100/Y8*W8 -> 0 | AA8: 3222.6188 | AC8: 2812.5 | AD8: =100/AC8*AA8 -> 114.582 | AE8: =SUM(IOC!K11) -> 310.53125 | AG8: 11537.57 | AH8: =100/AG8*AE8 -> 2.6914788 | AI8: =SUM(HIE!L11) -> 11586.268 | AK8: 18593.75 | AL8: =100/AK8*AI8 -> 62.312701 | AM8: 7215.3875 | AO8: 6187.5 | AP8: =100/AO8*AM8 -> 116.61232 | AQ8: 307.44 | AS8: 0 | AT8: =100/AS8*AQ8 -> #DIV/0! | AU8: 6508.745 | AW8: 6875 | AX8: =100/AW8*AU8 -> 94.672655 | AY8: ='CKR '!C7 -> 1596.86 | BA8: 1093.75 | BB8: =100/BA8*AY8 -> 145.99863
A9: Assessment of emerging technology trends and solutions | B9: T1.2 | C9: =SUM(G9+K9+O9+S9+W9+AA9+AE9+AI9+AM9+AQ9+AU9+AY9) -> 30527.424 | D9: =SUM(H9+L9+P9+T9+X9+AB9+AF9+AJ9+AN9+AR9+AV9+AZ9) -> 0 | E9: =SUM(I9+M9+Q9+U9+Y9+AC9+AG9+AG9+AK9+AO9+AS9+AW9+BA9) -> 53116.01 | F9: =100/E9*C9 -> 57.473112 | G9: 1399.6875 | I9: 3343.75 | J9: =100/I9*G9 -> 41.859813 | K9: 3484.4313 | M9: 2928.12 | N9: =100/M9*K9 -> 118.99893 | O9: 194.2 | Q9: 865.62 | R9: =100/Q9*O9 -> 22.434787 | S9: 2541.4263 | U9: 1171.88 | V9: =100/U9*S9 -> 216.86745 | W9: =SUM(MAI!D9) -> 5070.8375 | Y9: 9687.5 | Z9: =100/Y9*W9 -> 52.344129 | AA9: 7450.025 | AC9: 11250 | AD9: =100/AC9*AA9 -> 66.222444 | AE9: =SUM(IOC!K12) -> 1470.9375 | AG9: 2884.57 | AH9: =100/AG9*AE9 -> 50.993302 | AI9: =SUM(HIE!L12) -> 411.67883 | AK9: 2656.25 | AL9: =100/AK9*AI9 -> 15.498497 | AM9: 3093.75 | AO9: 3093.75 | AP9: =100/AO9*AM9 -> 100 | AQ9: 4060.45 | AS9: 6256.25 | AT9: =100/AS9*AQ9 -> 64.902298 | AU9: 0 | AW9: 1718.75 | AX9: =100/AW9*AU9 -> 0 | AY9: ='CKR '!C8 -> 1350 | BA9: 4375 | BB9: =100/BA9*AY9 -> 30.857143
A10: Potential new value chains and selection of Call Topics | B10: T1.3 | C10: =SUM(G10+K10+O10+S10+W10+AA10+AE10+AI10+AM10+AQ10+AU10+AY10) -> 31448.39 | D10: =SUM(H10+L10+P10+T10+X10+AB10+AF10+AJ10+AN10+AR10+AV10+AZ10) -> 0 | E10: =SUM(I9+M10+Q10+U10+Y10+AC10+AG10+AG10+AK10+AO10+AS10+AW10+BA10) -> 85434.42 | F10: =100/E10*C10 -> 36.809976 | G10: 3359.25 | I10: 3343.75 | J10: =100/I10*G10 -> 100.46355 | K10: 3364.2785 | M10: 2928.12 | N10: =100/M10*K10 -> 114.89551 | O10: 526.17 | Q10: 3462.5 | R10: =100/Q10*O10 -> 15.196245 | S10: 3773.3108 | U10: 4687.5 | V10: =100/U10*S10 -> 80.497296 | W10: =SUM(MAI!D10) -> 7556.5 | Y10: 19375 | Z10: =100/Y10*W10 -> 39.00129 | AA10: 2328.0938 | AC10: 22500 | AD10: =100/AC10*AA10 -> 10.347083 | AE10: =SUM(IOC!K13) -> 621.0625 | AG10: 2884.4 | AH10: =100/AG10*AE10 -> 21.531774 | AI10: =SUM(HIE!L13) -> 257.29927 | AK10: 2656.25 | AL10: =100/AK10*AI10 -> 9.6865606 | AM10: 3093.75 | AO10: 3093.75 | AP10: =100/AO10*AM10 -> 100 | AQ10: 3951.16 | AS10: 7150 | AT10: =100/AS10*AQ10 -> 55.260979 | AU10: 1188.245 | AW10: 1718.75 | AX10: =100/AW10*AU10 -> 69.134255 | AY10: ='CKR '!C9 -> 1429.27 | BA10: 8750 | BB10: =100/BA10*AY10 -> 16.334514
A11: Methodologies and tools for cross-sectoral/-border collaboration and technology transfer | B11: WP2 | C11: =SUM(G11+K11+O11+S11+W11+AA11+AE11+AI11+AM11+AQ11+AU11+AY11) -> 67975.266 | D11: =SUM(H11+L11+P11+T11+X11+AB11+AF11+AJ11+AN11+AR11+AV11+AZ11) -> 0 | E11: =SUM(I11+M11+Q11+U11+Y11+AC11+AG11+AG11+AK11+AO11+AS11+AW11+BA11) -> 153493.81 | F11: =100/E11*C11 -> 44.285347 | G11: 5346.8063 | H11: =SUM(H12:H15) -> 0 | I11: =SUM(I12:I15) -> 6687.5 | J11: =100/I11*G11 -> 79.952243 | K11: 3123.9729 | L11: =SUM(L12:L15) -> 0 | M11: =SUM(M12:M15) -> 5856.22 | N11: =100/M11*K11 -> 53.344528 | O11: 174.2875 | P11: =SUM(P12:P15) -> 0 | Q11: =SUM(Q12:Q15) -> 8656.24 | R11: =100/Q11*O11 -> 2.0134319 | S11: 3711.9305 | T11: =SUM(T12:T15) -> 0 | U11: =SUM(U12:U15) -> 11718.76 | V11: =100/U11*S11 -> 31.675113 | W11: =SUM(MAI!D11) -> 0 | X11: =SUM(X12:X15) -> 0 | Y11: =SUM(Y12:Y15) -> 4843.76 | Z11: =100/Y11*W11 -> 0 | AA11: 816.875 | AB11: =SUM(AB12:AB15) -> 0 | AC11: =SUM(AC12:AC15) -> 5625 | AD11: =100/AC11*AA11 -> 14.522222 | AE11: =SUM(IOC!K14) -> 555.6875 | AF11: =SUM(AF12:AF15) -> 0 | AG11: =SUM(AG12:AG15) -> 5768.79 | AH11: =100/AG11*AE11 -> 9.6326526 | AI11: =SUM(HIE!L14) -> 15281.059 | AJ11: =SUM(AJ12:AJ15) -> 0 | AK11: =SUM(AK12:AK15) -> 37187.5 | AL11: =100/AK11*AI11 -> 41.091923 | AM11: 30049.188 | AN11: =SUM(AN12:AN15) -> 0 | AO11: =SUM(AO12:AO15) -> 47406.25 | AP11: =100/AO11*AM11 -> 63.386552 | AQ11: 1776.61 | AR11: =SUM(AR12:AR15) -> 0 | AS11: =SUM(AS12:AS15) -> 1787.5 | AT11: =100/AS11*AQ11 -> 99.390769 | AU11: 565.24 | AV11: =SUM(AV12:AV15) -> 0 | AW11: =SUM(AW12:AW15) -> 3437.5 | AX11: =100/AW11*AU11 -> 16.443345 | AY11: ='CKR '!C10 -> 6573.6097 | AZ11: =SUM(AZ12:AZ15) -> 0 | BA11: =SUM(BA12:BA15) -> 8750 | BB11: =100/BA11*AY11 -> 75.126968
A12: Methologies and tools for cross-sectoral/-border collaboration and technology transfer | B12: T2.1 | C12: =SUM(G12+K12+O12+S12+W12+AA12+AE12+AI12+AM12+AQ12+AU12+AY12) -> 19638.134 | D12: =SUM(H12+L12+P12+T12+X12+AB12+AF12+AJ12+AN12+AR12+AV12+AZ12) -> 0 | E12: =SUM(I12+M12+Q12+U12+Y12+AC12+AG12+AG12+AK12+AO12+AS12+AW12+BA12) -> 67887.51 | F12: =100/E12*C12 -> 28.927462 | G12: 1306.375 | I12: 3343.75 | J12: =100/I12*G12 -> 39.069159 | K12: 40.050935 | M12: 2928.1 | N12: =100/M12*K12 -> 1.3678131 | O12: 0 | Q12: 4328.12 | R12: =100/Q12*O12 -> 0 | S12: 1816.2619 | U12: 5859.38 | V12: =100/U12*S12 -> 30.997511 | W12: =SUM(MAI!D12) -> 0 | Y12: 2421.88 | Z12: =100/Y12*W12 -> 0 | AA12: 163.375 | AC12: 2812.5 | AD12: =100/AC12*AA12 -> 5.8088889 | AE12: =SUM(IOC!K15) -> 0 | AG12: 2884.39 | AH12: =100/AG12*AE13 -> 0 | AI12: =SUM(HIE!L15) -> 14637.811 | AK12: 34531.25 | AL12: =100/AK12*AI12 -> 42.390041 | AM12: 0 | AO12: 0 | AP12: =100/AO12*AM12 -> #DIV/0! | AQ12: 1115.02 | AS12: 893.75 | AT12: =100/AS12*AQ12 -> 124.75748 | AU12: 559.24 | AW12: 1718.75 | AX12: =100/AW12*AU12 -> 32.5376 | AY12: ='CKR '!C11 -> 0 | BA12: 3281.25 | BB12: =100/BA12*AY12 -> 0
A13: Establishment of a Collaborative Virtual Environment | B13: T2.2 | C13: =SUM(G13+K13+O13+S13+W13+AA13+AE13+AI13+AM13+AQ13+AU13+AY13) -> 5204.3416 | D13: =SUM(H13+L13+P13+T13+X13+AB13+AF13+AJ13+AN13+AR13+AV13+AZ13) -> 0 | E13: =SUM(I13+M13+Q13+U13+Y13+AC13+AG13+AG13+AK13+AO13+AS13+AW13+BA13) -> 3343.75 | F13: =100/E13*C13 -> 155.64386 | G13: 4040.4313 | I13: 3343.75 | J13: =100/I13*G13 -> 120.83533 | K13: 520.66216 | M13: 0 | N13: =100/M13*K13 -> #DIV/0! | O13: 0 | Q13: 0 | R13: =100/Q13*O13 -> #DIV/0! | S13: 0 | U13: 0 | V13: =100/U13*S13 -> #DIV/0! | W13: =SUM(MAI!D13) -> 0 | Y13: 0 | Z13: =100/Y13*W13 -> #DIV/0! | AA13: 0 | AC13: 0 | AD13: =100/AC13*AA13 -> #DIV/0! | AE13: =SUM(IOC!K16) -> 0 | AG13: 0 | AH13: =100/AG13*#REF! -> #DIV/0! | AI13: =SUM(HIE!L16) -> 643.24817 | AK13: 0 | AL13: =100/AK13*AI13 -> #DIV/0! | AM13: 0 | AO13: 0 | AP13: =100/AO13*AM13 -> #DIV/0! | AQ13: 0 | AS13: 0 | AT13: =100/AS13*AQ13 -> #DIV/0! | AU13: 0 | AW13: 0 | AX13: =100/AW13*AU13 -> #DIV/0! | AY13: ='CKR '!C12 -> 0 | BA13: 0 | BB13: =100/BA13*AY13 -> #DIV/0!
A14: Establishment of a Survey tool | B14: T2.3 | C14: =SUM(G14+K14+O14+S14+W14+AA14+AE14+AI14+AM14+AQ14+AU14+AY14) -> 10843.042 | D14: =SUM(H14+L14+P14+T14+X14+AB14+AF14+AJ14+AN14+AR14+AV14+AZ14) -> 0 | E14: =SUM(I14+M14+Q14+U14+Y14+AC14+AG14+AG14+AK14+AO14+AS14+AW14+BA14) -> 12525 | F14: =100/E14*C14 -> 86.571193 | G14: 0 | I14: 0 | J14: =100/I14*G14 -> #DIV/0! | K14: 1321.6809 | M14: 0 | N14: =100/M14*K14 -> #DIV/0! | O14: 139.43 | Q14: 3462.5 | R14: =100/Q14*O14 -> 4.0268592 | S14: 1895.6686 | U14: 4687.5 | V14: =100/U14*S14 -> 40.440929 | W14: =SUM(MAI!D14) -> 0 | Y14: 0 | Z14: =100/Y14*W14 -> #DIV/0! | AA14: 245.0625 | AC14: 0 | AD14: =100/AC14*AA14 -> #DIV/0! | AE14: =SUM(IOC!K17) -> 0 | AG14: 0 | AH14: =100/AG14*AE14 -> #DIV/0! | AI14: =SUM(HIE!L17) -> 0 | AK14: 0 | AL14: =100/AK14*AI14 -> #DIV/0! | AM14: 0 | AO14: 0 | AP14: =100/AO14*AM14 -> #DIV/0! | AQ14: 661.59 | AS14: 0 | AT14: =100/AS14*AQ14 -> #DIV/0! | AU14: 6 | AW14: 0 | AX14: =100/AW14*AU14 -> #DIV/0! | AY14: ='CKR '!C13 -> 6573.61 | BA14: 4375 | BB14: =100/BA14*AY14 -> 150.25394
A15: Establishment of the GreenOffshoreTech Cluster Collaboration Platform | B15: T2.4 | C15: =SUM(G15+K15+O15+S15+W15+AA15+AE15+AI15+AM15+AQ15+AU15+AY15) -> 32340.659 | D15: =SUM(H15+L15+P15+T15+X15+AB15+AF15+AJ15+AN15+AR15+AV15+AZ15) -> 0 | E15: =SUM(I15+M15+Q15+U15+Y15+AC15+AG15+AG15+AK15+AO15+AS15+AW15+BA15) -> 69737.55 | F15: =100/E15*C15 -> 46.374814 | G15: 0 | I15: 0 | J15: =100/I15*G15 -> #DIV/0! | K15: 1241.579 | M15: 2928.12 | N15: =100/M15*K15 -> 42.401916 | O15: 0 | Q15: 865.62 | R15: =100/Q15*O15 -> 0 | S15: 249.14268 | U15: 1171.88 | V15: =100/U15*S15 -> 21.260085 | W15: =SUM(MAI!D15) -> 0 | Y15: 2421.88 | Z15: =100/Y15*W15 -> 0 | AA15: 245.0625 | AC15: 2812.5 | AD15: =100/AC15*AA15 -> 8.7133333 | AE15: =SUM(IOC!K18) -> 555.6875 | AG15: 2884.4 | AH15: =100/AG15*AE15 -> 19.265272 | AI15: =SUM(HIE!L18) -> 0 | AK15: 2656.25 | AL15: =100/AK15*AI15 -> 0 | AM15: 30049.188 | AO15: 47406.25 | AP15: =100/AO15*AM15 -> 63.386552 | AQ15: 0 | AS15: 893.75 | AT15: =100/AS15*AQ15 -> 0 | AU15: 0 | AW15: 1718.75 | AX15: =100/AW15*AU15 -> 0 | AY15: ='CKR '!C14 -> 0 | BA15: 1093.75 | BB15: =100/BA15*AY15 -> 0
A16: Direct financial support to SMEs through a competitive Call for Proposals | B16: WP3 | C16: =SUM(G16+K16+O16+S16+W16+AA16+AE16+AI16+AM16+AQ16+AU16+AY16) -> 84518.515 | D16: =SUM(H16+L16+P16+T16+X16+AB16+AF16+AJ16+AN16+AR16+AV16+AZ16) -> 91428.57 | E16: =SUM(I16+M16+Q16+U16+Y16+AC16+AG16+AG16+AK16+AO16+AS16+AW16+BA16) -> 434125.12 | F16: =100/E16*C16 -> 19.468699 | G16: 1306.375 | H16: =SUM(H17:H22) -> 0 | I16: =SUM(I17:I22) -> 94375 | J16: =100/I16*G16 -> 1.3842384 | K16: 11374.466 | L16: =SUM(L17:L22) -> 8000 | M16: =SUM(M17:M22) -> 52706.11 | N16: =100/M16*K16 -> 21.580924 | O16: 2002.375 | P16: =SUM(P17:P22) -> 8000 | Q16: =SUM(Q17:Q22) -> 8656.25 | R16: =100/Q16*O16 -> 23.13213 | S16: 962.41046 | T16: =SUM(T17:T22) -> 8000 | U16: =SUM(U17:U22) -> 16406.25 | V16: =100/U16*S16 -> 5.8661209 | W16: =SUM(MAI!D16) -> 0 | X16: =SUM(X17:X22) -> 8000 | Y16: =SUM(Y17:Y22) -> 33906.25 | Z16: =100/Y16*W16 -> 0 | AA16: 1705.2656 | AB16: =SUM(AB17:AB22) -> 11428.57 | AC16: =SUM(AC17:AC22) -> 39375 | AD16: =100/AC16*AA16 -> 4.3308333 | AE16: =SUM(IOC!K19) -> 1307.5 | AF16: =SUM(AF17:AF22) -> 8000 | AG16: =SUM(AG17:AG22) -> 28843.88 | AH16: =100/AG16*AE16 -> 4.533024 | AI16: =SUM(HIE!L19) -> 6539.2514 | AJ16: =SUM(AJ17:AJ22) -> 8000 | AK16: =SUM(AK17:AK22) -> 26562.5 | AL16: =100/AK16*AI16 -> 24.618358 | AM16: 34570.488 | AN16: =SUM(AN17:AN22) -> 8000 | AO16: =SUM(AO17:AO22) -> 48500 | AP16: =100/AO16*AM16 -> 71.279356 | AQ16: 2131.5 | AR16: =SUM(AR17:AR22) -> 8000 | AS16: =SUM(AS17:AS22) -> 12512.5 | AT16: =100/AS16*AQ16 -> 17.034965 | AU16: 2898.055 | AV16: =SUM(AV17:AV22) -> 8000 | AW16: =SUM(AW17:AW22) -> 17187.5 | AX16: =100/AW16*AU16 -> 16.861411 | AY16: ='CKR '!C15 -> 19720.829 | AZ16: =SUM(AZ17:AZ22) -> 8000 | BA16: =SUM(BA17:BA22) -> 26250 | BB16: =100/BA16*AY16 -> 75.126968
A17: Preparation of the Call for Proposals | B17: T3.1 | C17: =SUM(G17+K17+O17+S17+W17+AA17+AE17+AI17+AM17+AQ17+AU17+AY17) -> 47272.495 | D17: =SUM(H17+L17+P17+T17+X17+AB17+AF17+AJ17+AN17+AR17+AV17+AZ17) -> 19000 | E17: =SUM(I17+M17+Q17+U17+Y17+AC17+AG17+AG17+AK17+AO17+AS17+AW17+BA17) -> 68475.03 | F17: =100/E17*C17 -> 69.036107 | G17: 559.875 | H17: 0 | I17: 6687.5 | J17: =100/I17*G17 -> 8.3719626 | K17: 10613.498 | L17: 1000 | M17: 5856.22 | N17: =100/M17*K17 -> 181.23462 | O17: 1601.9 | P17: 2000 | Q17: 1731.25 | R17: =100/Q17*O17 -> 92.52852 | S17: 962.41046 | T17: 1000 | U17: 2343.75 | V17: =100/U17*S17 -> 41.062846 | W17: =SUM(MAI!D17) -> 0 | X17: 1000 | Y17: 4843.75 | Z17: =100/Y17*W17 -> 0 | AA17: 816.875 | AB17: 2000 | AC17: 5625 | AD17: =100/AC17*AA17 -> 14.522222 | AE17: =SUM(IOC!K20) -> 1046 | AF17: 2000 | AG17: 5768.78 | AH17: =100/AG17*AE17 -> 18.132083 | AI17: =SUM(HIE!L20) -> 1628.0514 | AJ17: 2000 | AK17: 5312.5 | AL17: =100/AK17*AI17 -> 30.645674 | AM17: 6187.5 | AN17: 1000 | AO17: 6187.5 | AP17: =100/AO17*AM17 -> 100 | AQ17: 2131.5 | AR17: 2000 | AS17: 1787.5 | AT17: =100/AS17*AQ17 -> 119.24476 | AU17: 2004.055 | AV17: 2000 | AW17: 3437.5 | AX17: =100/AW17*AU17 -> 58.299782 | AY17: ='CKR '!C16 -> 19720.83 | AZ17: 3000 | BA17: 13125 | BB17: =100/BA17*AY17 -> 150.25394
A18: Publication of the Call for Proposals and Proposal reception. | B18: T3.2 | C18: =SUM(G18+K18+O18+S18+W18+AA18+AE18+AI18+AM18+AQ18+AU18+AY18) -> 14726.043 | D18: =SUM(H18+L18+P18+T18+X18+AB18+AF18+AJ18+AN18+AR18+AV18+AZ18) -> 2000 | E18: =SUM(I18+M18+Q18+U18+Y18+AC18+AG18+AG18+AK18+AO18+AS18+AW18+BA18) -> 18562.5 | F18: =100/E18*C18 -> 79.332217 | G18: 466.5625 | H18: 0 | I18: 6687.5 | J18: =100/I18*G18 -> 6.9766355 | K18: 760.96777 | M18: 0 | N18: =100/M18*K18 -> #DIV/0! | O18: 0 | Q18: 0 | R18: =100/Q18*O18 -> #DIV/0! | S18: 0 | U18: 0 | V18: =100/U18*S18 -> #DIV/0! | W18: =SUM(MAI!D18) -> 0 | Y18: 0 | Z18: =100/Y18*W18 -> #DIV/0! | AA18: 841.4125 | AC18: 0 | AD18: =100/AC18*AA18 -> #DIV/0! | AE18: =SUM(IOC!K21) -> 261.5 | AG18: 0 | AH18: =100/AG18*AE18 -> #DIV/0! | AI18: =SUM(HIE!L21) -> 4911.2 | AK18: 0 | AL18: =100/AK18*AI18 -> #DIV/0! | AM18: 7484.4 | AN18: 2000 | AO18: 11875 | AP18: =100/AO18*AM18 -> 63.026526 | AQ18: 0 | AS18: 0 | AT18: =100/AS18*AQ18 -> #DIV/0! | AU18: 0 | AW18: 0 | AX18: =100/AW18*AU18 -> #DIV/0! | AY18: ='CKR '!C17 -> 0 | BA18: 0 | BB18: =100/BA18*AY18 -> #DIV/0!
A19: Evaluation and Selection of SMEs Proposals | B19: T3.3 | C19: =SUM(G19+K19+O19+S19+W19+AA19+AE19+AI19+AM19+AQ19+AU19+AY19) -> 15885.025 | D19: =SUM(H19+L19+P19+T19+X19+AB19+AF19+AJ19+AN19+AR19+AV19+AZ19) -> 33000 | E19: =SUM(I19+M19+Q19+U19+Y19+AC19+AG19+AG19+AK19+AO19+AS19+AW19+BA19) -> 121637.57 | F19: =100/E19*C19 -> 13.059308 | G19: 279.9375 | H19: 0 | I19: 13750 | J19: =100/I19*G19 -> 2.0359091 | K19: 0 | L19: 2000 | M19: 11712.47 | N19: =100/M19*K19 -> 0 | O19: 0 | P19: 3000 | Q19: 3462.5 | R19: =100/Q19*O19 -> 0 | S19: 0 | T19: 3000 | U19: 4687.5 | V19: =100/U19*S19 -> 0 | W19: =SUM(MAI!D19) -> 0 | X19: 3000 | Y19: 9687.5 | Z19: =100/Y19*W19 -> 0 | AA19: 0 | AB19: 5000 | AC19: 11250 | AD19: =100/AC19*AA19 -> 0 | AE19: =SUM(IOC!K22) -> 0 | AF19: 3000 | AG19: 11537.55 | AH19: =100/AG19*AE19 -> 0 | AI19: =SUM(HIE!L22) -> 0 | AJ19: 3000 | AK19: 10625 | AL19: =100/AK19*AI19 -> 0 | AM19: 14711.088 | AN19: 3000 | AO19: 18562.5 | AP19: =100/AO19*AM19 -> 79.25165 | AQ19: 0 | AR19: 3000 | AS19: 3575 | AT19: =100/AS19*AQ19 -> 0 | AU19: 894 | AV19: 3000 | AW19: 6875 | AX19: =100/AW19*AU19 -> 13.003636 | AY19: ='CKR '!C18 -> 0 | AZ19: 2000 | BA19: 4375 | BB19: =100/BA19*AY19 -> 0
A20: Contracting with winner SMEs Projects | B20: T3.4 | C20: =SUM(G20+K20+O20+S20+W20+AA20+AE20+AI20+AM20+AQ20+AU20+AY20) -> 0 | D20: =SUM(H20+L20+P20+T20+X20+AB20+AF20+AJ20+AN20+AR20+AV20+AZ20) -> 0 | E20: =SUM(I20+M20+Q20+U20+Y20+AC20+AG20+AG20+AK20+AO20+AS20+AW20+BA20) -> 26750 | F20: =100/E20*C20 -> 0 | G20: 0 | H20: 0 | I20: 26750 | J20: =100/I20*G20 -> 0 | K20: 0 | M20: 0 | N20: =100/M20*K20 -> #DIV/0! | O20: 0 | Q20: 0 | R20: =100/Q20*O20 -> #DIV/0! | S20: 0 | U20: 0 | V20: =100/U20*S20 -> #DIV/0! | W20: =SUM(MAI!D20) -> 0 | Y20: 0 | Z20: =100/Y20*W20 -> #DIV/0! | AA20: 0 | AC20: 0 | AD20: =100/AC20*AA20 -> #DIV/0! | AE20: =SUM(IOC!K23) -> 0 | AG20: 0 | AH20: =100/AG20*AE20 -> #DIV/0! | AI20: =SUM(HIE!L23) -> 0 | AK20: 0 | AL20: =100/AK20*AI20 -> #DIV/0! | AM20: 0 | AO20: 0 | AP20: =100/AO20*AM20 -> #DIV/0! | AQ20: 0 | AS20: 0 | AT20: =100/AS20*AQ20 -> #DIV/0! | AU20: 0 | AW20: 0 | AX20: =100/AW20*AU20 -> #DIV/0! | AY20: ='CKR '!C19 -> 0 | BA20: 0 | BB20: =100/BA20*AY20 -> #DIV/0!
A21: Payments and financial monitoring of winner SMEs Projects | B21: T3.5 | C21: =SUM(G21+K21+O21+S21+W21+AA21+AE21+AI21+AM21+AQ21+AU21+AY21) -> 0 | D21: =SUM(H21+L21+P21+T21+X21+AB21+AF21+AJ21+AN21+AR21+AV21+AZ21) -> 0 | E21: =SUM(I21+M21+Q21+U21+Y21+AC21+AG21+AG21+AK21+AO21+AS21+AW21+BA21) -> 26750 | F21: =100/E21*C21 -> 0 | G21: 0 | H21: 0 | I21: 26750 | J21: =100/I21*G21 -> 0 | K21: 0 | M21: 0 | N21: =100/M21*K21 -> #DIV/0! | O21: 0 | Q21: 0 | R21: =100/Q21*O21 -> #DIV/0! | S21: 0 | U21: 0 | V21: =100/U21*S21 -> #DIV/0! | W21: =SUM(MAI!D21) -> 0 | Y21: 0 | Z21: =100/Y21*W21 -> #DIV/0! | AA21: 0 | AB21: 0 | AC21: 0 | AD21: =100/AC21*AA21 -> #DIV/0! | AE21: =SUM(IOC!K24) -> 0 | AG21: 0 | AH21: =100/AG21*AE21 -> #DIV/0! | AI21: =SUM(HIE!L24) -> 0 | AK21: 0 | AL21: =100/AK21*AI21 -> #DIV/0! | AM21: 0 | AO21: 0 | AP21: =100/AO21*AM21 -> #DIV/0! | AQ21: 0 | AS21: 0 | AT21: =100/AS21*AQ21 -> #DIV/0! | AU21: 0 | AW21: 0 | AX21: =100/AW21*AU21 -> #DIV/0! | AY21: ='CKR '!C20 -> 0 | BA21: 0 | BB21: =100/BA21*AY21 -> #DIV/0!
A22: Technical monitoring of winner SMEs Projects | B22: T3.6 | C22: =SUM(G22+K22+O22+S22+W22+AA22+AE22+AI22+AM22+AQ22+AU22+AY22) -> 6187.5 | D22: =SUM(H22+L22+P22+T22+X22+AB22+AF22+AJ22+AN22+AR22+AV22+AZ22) -> 37428.57 | E22: =SUM(I22+M22+Q22+U22+Y22+AC22+AG22+AG22+AK22+AO22+AS22+AW22+BA22) -> 171950.02 | F22: =100/E22*C22 -> 3.5984294 | G22: 0 | H22: 0 | I22: 13750 | J22: =100/I22*G22 -> 0 | K22: 0 | L22: 5000 | M22: 35137.42 | N22: =100/M22*K22 -> 0 | O22: 0 | P22: 3000 | Q22: 3462.5 | R22: =100/Q22*O22 -> 0 | S22: 0 | T22: 4000 | U22: 9375 | V22: =100/U22*S22 -> 0 | W22: =SUM(MAI!D22) -> 0 | X22: 4000 | Y22: 19375 | Z22: =100/Y22*W22 -> 0 | AA22: 0 | AB22: 4428.57 | AC22: 22500 | AD22: =100/AC22*AA22 -> 0 | AE22: =SUM(IOC!K25) -> 0 | AF22: 3000 | AG22: 11537.55 | AH22: =100/AG22*AE22 -> 0 | AI22: =SUM(HIE!L25) -> 0 | AJ22: 3000 | AK22: 10625 | AL22: =100/AK22*AI22 -> 0 | AM22: 6187.5 | AN22: 2000 | AO22: 11875 | AP22: =100/AO22*AM22 -> 52.105263 | AQ22: 0 | AR22: 3000 | AS22: 7150 | AT22: =100/AS22*AQ22 -> 0 | AU22: 0 | AV22: 3000 | AW22: 6875 | AX22: =100/AW22*AU22 -> 0 | AY22: ='CKR '!C21 -> 0 | AZ22: 3000 | BA22: 8750 | BB22: =100/BA22*AY22 -> 0
A23: Business Support Services to winner SMEs (preparation) | B23: WP4 | C23: =SUM(G23+K23+O23+S23+W23+AA23+AE23+AI23+AM23+AQ23+AU23+AY23) -> 21952.603 | D23: =SUM(H23+L23+P23+T23+X23+AB23+AF23+AJ23+AN23+AR23+AV23+AZ23) -> 151514.29 | E23: =SUM(I23+M23+Q23+U23+Y23+AC23+AG23+AG23+AK23+AO23+AS23+AW23+BA23) -> 700689.32 | F23: =100/E23*C23 -> 3.133001 | G23: 6681.175 | H23: =SUM(H24:H32) -> 0 | I23: =SUM(I24:I32) -> 72511.5 | J23: =100/I23*G23 -> 9.2139523 | K23: 2723.4636 | L23: =SUM(L24:L32) -> 8000 | M23: =SUM(M24:M32) -> 149334.17 | N23: =100/M23*K23 -> 1.8237377 | O23: 58.1 | P23: =SUM(P24:P32) -> 26000 | Q23: =SUM(Q24:Q32) -> 29431.25 | R23: =100/Q23*O23 -> 0.19740922 | S23: 595.19468 | T23: =SUM(T24:T32) -> 8600 | U23: =SUM(U24:U32) -> 32812.5 | V23: =100/U23*S23 -> 1.8139266 | W23: =SUM(MAI!D23) -> 4120.2875 | X23: =SUM(X24:X32) -> 8600 | Y23: =SUM(Y24:Y32) -> 77500 | Z23: =100/Y23*W23 -> 5.3165 | AA23: 816.875 | AB23: =SUM(AB24:AB32) -> 33714.29 | AC23: =SUM(AC24:AC32) -> 101250 | AD23: =100/AC23*AA23 -> 0.80679012 | AE23: =SUM(IOC!K26) -> 0 | AF23: =SUM(AF24:AF32) -> 8600 | AG23: =SUM(AG24:AG32) -> 34612.7 | AH23: =100/AG23*AE23 -> 0 | AI23: =SUM(HIE!L26) -> 0 | AJ23: =SUM(AJ24:AJ32) -> 8600 | AK23: =SUM(AK24:AK32) -> 74374.5 | AL23: =100/AK23*AI23 -> 0 | AM23: 5126.7875 | AN23: =SUM(AN24:AN32) -> 8600 | AO23: =SUM(AO24:AO32) -> 30937.5 | AP23: =100/AO23*AM23 -> 16.571434 | AQ23: 661.59 | AR23: =SUM(AR24:AR32) -> 8600 | AS23: =SUM(AS24:AS32) -> 8937.5 | AT23: =100/AS23*AQ23 -> 7.4024056 | AU23: 1169.13 | AV23: =SUM(AV24:AV32) -> 23600 | AW23: =SUM(AW24:AW32) -> 41250 | AX23: =100/AW23*AU23 -> 2.8342545 | AY23: ='CKR '!C22 -> 0 | AZ23: =SUM(AZ24:AZ32) -> 8600 | BA23: =SUM(BA24:BA32) -> 13125 | BB23: =100/BA23*AY23 -> 0
A24: Programme of Business Support Services to winner SMEs (prep) | B24: T4.1 | C24: =SUM(G24+K24+O24+S24+W24+AA24+AE24+AI24+AM24+AQ24+AU24+AY24) -> 8347.2261 | D24: =SUM(H24+L24+P24+T24+X24+AB24+AF24+AJ24+AN24+AR24+AV24+AZ24) -> 1000 | E24: =SUM(I24+M24+Q24+U24+Y24+AC24+AG24+AG24+AK24+AO24+AS24+AW24+BA24) -> 24218.75 | F24: =100/E24*C24 -> 34.465966 | G24: 933.125 | H24: 0 | I24: 0 | J24: =100/I24*G24 -> #DIV/0! | K24: 2403.0561 | M24: 0 | N24: =100/M24*K24 -> #DIV/0! | O24: 46.48 | Q24: 0 | R24: =100/Q24*O24 -> #DIV/0! | S24: 0 | U24: 0 | V24: =100/U24*S24 -> #DIV/0! | W24: =SUM(MAI!D24) -> 4120.2875 | X24: 1000 | Y24: 24218.75 | Z24: =100/Y24*W24 -> 17.0128 | AA24: 81.6875 | AC24: 0 | AD24: =100/AC24*AA24 -> #DIV/0! | AE24: =SUM(IOC!K27) -> 0 | AG24: 0 | AH24: =100/AG24*AE24 -> #DIV/0! | AI24: =SUM(HIE!L27) -> 0 | AK24: 0 | AL24: =100/AK24*AI24 -> #DIV/0! | AM24: 0 | AO24: 0 | AP24: =100/AO24*AM24 -> #DIV/0! | AQ24: 661.59 | AS24: 0 | AT24: =100/AS24*AQ24 -> #DIV/0! | AU24: 101 | AW24: 0 | AX24: =100/AW24*AU24 -> #DIV/0! | AY24: ='CKR '!C23 -> 0 | BA24: 0 | BB24: =100/BA24*AY24 -> #DIV/0!
A25: Business Support Service #1 Business & Tech Academy | B25: T4.2 | C25: =SUM(G25+K25+O25+S25+W25+AA25+AE25+AI25+AM25+AQ25+AU25+AY25) -> 5371.85 | D25: =SUM(H25+L25+P25+T25+X25+AB25+AF25+AJ25+AN25+AR25+AV25+AZ25) -> 44600 | E25: =SUM(I25+M25+Q25+U25+Y25+AC25+AG25+AG25+AK25+AO25+AS25+AW25+BA25) -> 169499.08 | F25: =100/E25*C25 -> 3.1692502 | G25: 0 | H25: 0 | I25: 12324 | J25: =100/I25*G25 -> 0 | K25: 0 | L25: 1000 | M25: 11712.46 | N25: =100/M25*K25 -> 0 | O25: 0 | P25: 5000 | Q25: 3462.5 | R25: =100/Q25*O25 -> 0 | S25: 0 | T25: 2000 | U25: 4687.5 | V25: =100/U25*S25 -> 0 | W25: =SUM(MAI!D25) -> 0 | X25: 5000 | Y25: 29062.5 | Z25: =100/Y25*W25 -> 0 | AA25: 245.0625 | AB25: 10000 | AC25: 39375 | AD25: =100/AC25*AA25 -> 0.62238095 | AE25: =SUM(IOC!K28) -> 0 | AF25: 3000 | AG25: 11537.56 | AH25: =100/AG25*AE25 -> 0 | AI25: =SUM(HIE!L28) -> 0 | AJ25: 1000 | AK25: 10625 | AL25: =100/AK25*AI25 -> 0 | AM25: 5126.7875 | AN25: 4600 | AO25: 18562.5 | AP25: =100/AO25*AM25 -> 27.619057 | AQ25: 0 | AR25: 6000 | AS25: 5362.5 | AT25: =100/AS25*AQ25 -> 0 | AU25: 0 | AV25: 5000 | AW25: 6875 | AX25: =100/AW25*AU25 -> 0 | AY25: ='CKR '!C24 -> 0 | AZ25: 2000 | BA25: 4375 | BB25: =100/BA25*AY25 -> 0
A26: Business Support Service #2 Brokerage & B2B matchmaking events | B26: T4.3 | C26: =SUM(G26+K26+O26+S26+W26+AA26+AE26+AI26+AM26+AQ26+AU26+AY26) -> 326.75 | D26: =SUM(H26+L26+P26+T26+X26+AB26+AF26+AJ26+AN26+AR26+AV26+AZ26) -> 34100 | E26: =SUM(I26+M26+Q26+U26+Y26+AC26+AG26+AG26+AK26+AO26+AS26+AW26+BA26) -> 113875.05 | F26: =100/E26*C26 -> 0.28693731 | G26: 0 | H26: 0 | I26: 6687.5 | J26: =100/I26*G26 -> 0 | K26: 0 | L26: 1000 | M26: 5856.24 | N26: =100/M26*K26 -> 0 | O26: 0 | P26: 10000 | Q26: 13850 | R26: =100/Q26*O26 -> 0 | S26: 0 | T26: 2000 | U26: 2343.75 | V26: =100/U26*S26 -> 0 | W26: =SUM(MAI!D26) -> 0 | X26: 500 | Y26: 9687.5 | Z26: =100/Y26*W26 -> 0 | AA26: 326.75 | AB26: 10000 | AC26: 45000 | AD26: =100/AC26*AA26 -> 0.72611111 | AE26: =SUM(IOC!K29) -> 0 | AF26: 1500 | AG26: 5768.78 | AH26: =100/AG26*AE26 -> 0 | AI26: =SUM(HIE!L29) -> 0 | AJ26: 1000 | AK26: 5312.5 | AL26: =100/AK26*AI26 -> 0 | AM26: 0 | AN26: 2000 | AO26: 6187.5 | AP26: =100/AO26*AM26 -> 0 | AQ26: 0 | AR26: 1600 | AS26: 1787.5 | AT26: =100/AS26*AQ26 -> 0 | AU26: 0 | AV26: 2500 | AW26: 3437.5 | AX26: =100/AW26*AU26 -> 0 | AY26: ='CKR '!C25 -> 0 | AZ26: 2000 | BA26: 2187.5 | BB26: =100/BA26*AY26 -> 0
A27: Business Support Service #3 Access to Finance | B27: T4.4 | C27: =SUM(G27+K27+O27+S27+W27+AA27+AE27+AI27+AM27+AQ27+AU27+AY27) -> 0 | D27: =SUM(H27+L27+P27+T27+X27+AB27+AF27+AJ27+AN27+AR27+AV27+AZ27) -> 10700 | E27: =SUM(I27+M27+Q27+U27+Y27+AC27+AG27+AG27+AK27+AO27+AS27+AW27+BA27) -> 70268.81 | F27: =100/E27*C27 -> 0 | G27: 0 | H27: 0 | I27: 6687.5 | J27: =100/I27*G27 -> 0 | K27: 0 | M27: 0 | N27: =100/M27*K27 -> #DIV/0! | O27: 0 | Q27: 1731.25 | R27: =100/Q27*O27 -> 0 | S27: 0 | U27: 2343.75 | V27: =100/U27*S27 -> 0 | W27: =SUM(MAI!D27) -> 0 | X27: 100 | Y27: 4843.75 | Z27: =100/Y27*W27 -> 0 | AA27: 0 | AB27: 4000 | AC27: 5625 | AD27: =100/AC27*AA27 -> 0 | AE27: =SUM(IOC!K30) -> 0 | AF27: 1500 | AG27: 5768.78 | AH27: =100/AG27*AE27 -> 0 | AI27: =SUM(HIE!L30) -> 0 | AJ27: 2600 | AK27: 31875 | AL27: =100/AK27*AI27 -> 0 | AM27: 0 | AO27: 0 | AP27: =100/AO27*AM27 -> #DIV/0! | AQ27: 0 | AS27: 0 | AT27: =100/AS27*AQ27 -> #DIV/0! | AU27: 0 | AV27: 2500 | AW27: 3437.5 | AX27: =100/AW27*AU27 -> 0 | AY27: ='CKR '!C26 -> 0 | BA27: 2187.5 | BB27: =100/BA27*AY27 -> 0
A28: Business Support Service #4 One-to-One Mentoring and Coaching (prep) | B28: T4.5 | C28: =SUM(G28+K28+O28+S28+W28+AA28+AE28+AI28+AM28+AQ28+AU28+AY28) -> 359.90748 | D28: =SUM(H28+L28+P28+T28+X28+AB28+AF28+AJ28+AN28+AR28+AV28+AZ28) -> 6000 | E28: =SUM(I28+M28+Q28+U28+Y28+AC28+AG28+AG28+AK28+AO28+AS28+AW28+BA28) -> 114196.76 | F28: =100/E28*C28 -> 0.31516435 | G28: 0 | H28: 0 | I28: 0 | J28: =100/I28*G28 -> #DIV/0! | K28: 320.40748 | L28: 6000 | M28: 114196.76 | N28: =100/M28*K28 -> 0.28057493 | O28: 0 | P28: 0 | Q28: 0 | R28: =100/Q28*O28 -> #DIV/0! | S28: 0 | T28: 0 | U28: 0 | V28: =100/U28*S28 -> #DIV/0! | W28: =SUM(MAI!D28) -> 0 | X28: 0 | Y28: 0 | Z28: =100/Y28*W28 -> #DIV/0! | AA28: 0 | AB28: 0 | AC28: 0 | AD28: =100/AC28*AA28 -> #DIV/0! | AE28: =SUM(IOC!K31) -> 0 | AF28: 0 | AG28: 0 | AH28: =100/AG28*AE28 -> #DIV/0! | AI28: =SUM(HIE!L31) -> 0 | AJ28: 0 | AK28: 0 | AL28: =100/AK28*AI28 -> #DIV/0! | AM28: 0 | AN28: 0 | AO28: 0 | AP28: =100/AO28*AM28 -> #DIV/0! | AQ28: 0 | AR28: 0 | AS28: 0 | AT28: =100/AS28*AQ28 -> #DIV/0! | AU28: 39.5 | AV28: 0 | AW28: 0 | AX28: =100/AW28*AU28 -> #DIV/0! | AY28: ='CKR '!C27 -> 0 | AZ28: 0 | BA28: 0 | BB28: =100/BA28*AY28 -> #DIV/0!
A29: Business Support Service #5 Branding | B29: T4.6 | C29: =SUM(G29+K29+O29+S29+W29+AA29+AE29+AI29+AM29+AQ29+AU29+AY29) -> 230.555 | D29: =SUM(H29+L29+P29+T29+X29+AB29+AF29+AJ29+AN29+AR29+AV29+AZ29) -> 4000 | E29: =SUM(I29+M29+Q29+U29+Y29+AC29+AG29+AG29+AK29+AO29+AS29+AW29+BA29) -> 6925 | F29: =100/E29*C29 -> 3.3293141 | G29: 0 | H29: 0 | I29: 0 | J29: =100/I29*G29 -> #DIV/0! | K29: 0 | M29: 0 | N29: =100/M29*K29 -> #DIV/0! | O29: 0 | P29: 4000 | Q29: 6925 | R29: =100/Q29*O29 -> 0 | S29: 0 | U29: 0 | V29: =100/U29*S29 -> #DIV/0! | W29: =SUM(MAI!D29) -> 0 | Y29: 0 | Z29: =100/Y29*W29 -> #DIV/0! | AA29: 0 | AC29: 0 | AD29: =100/AC29*AA29 -> #DIV/0! | AE29: =SUM(IOC!K32) -> 0 | AG29: 0 | AH29: =100/AG29*AE29 -> #DIV/0! | AI29: =SUM(HIE!L32) -> 0 | AK29: 0 | AL29: =100/AK29*AI29 -> #DIV/0! | AM29: 0 | AO29: 0 | AP29: =100/AO29*AM29 -> #DIV/0! | AQ29: 0 | AS29: 0 | AT29: =100/AS29*AQ29 -> #DIV/0! | AU29: 230.555 | AW29: 0 | AX29: =100/AW29*AU29 -> #DIV/0! | AY29: ='CKR '!C28 -> 0 | BA29: 0 | BB29: =100/BA29*AY29 -> #DIV/0!
A30: Business Support Service #6 Internationalisation | B30: T4.7 | C30: =SUM(G30+K30+O30+S30+W30+AA30+AE30+AI30+AM30+AQ30+AU30+AY30) -> 798.075 | D30: =SUM(H30+L30+P30+T30+X30+AB30+AF30+AJ30+AN30+AR30+AV30+AZ30) -> 19800 | E30: =SUM(I30+M30+Q30+U30+Y30+AC30+AG30+AG30+AK30+AO30+AS30+AW30+BA30) -> 54018.33 | F30: =100/E30*C30 -> 1.4774152 | G30: 0 | H30: 0 | I30: 6687.5 | J30: =100/I30*G30 -> 0 | K30: 0 | M30: 0 | N30: =100/M30*K30 -> #DIV/0! | O30: 0 | P30: 3000 | Q30: 1731.25 | R30: =100/Q30*O30 -> 0 | S30: 0 | T30: 1000 | U30: 2343.75 | V30: =100/U30*S30 -> 0 | W30: =SUM(MAI!D30) -> 0 | X30: 1000 | Y30: 4843.75 | Z30: =100/Y30*W30 -> 0 | AA30: 0 | AB30: 4000 | AC30: 5625 | AD30: =100/AC30*AA30 -> 0 | AE30: =SUM(IOC!K33) -> 0 | AF30: 1800 | AG30: 5768.79 | AH30: =100/AG30*AE30 -> 0 | AI30: =SUM(HIE!L33) -> 0 | AJ30: 1000 | AK30: 5312 | AL30: =100/AK30*AI30 -> 0 | AM30: 0 | AO30: 0 | AP30: =100/AO30*AM30 -> #DIV/0! | AQ30: 0 | AS30: 0 | AT30: =100/AS30*AQ30 -> #DIV/0! | AU30: 798.075 | AV30: 6000 | AW30: 13750 | AX30: =100/AW30*AU30 -> 5.8041818 | AY30: ='CKR '!C29 -> 0 | AZ30: 2000 | BA30: 2187.5 | BB30: =100/BA30*AY30 -> 0
A31: Business Support Service #7 Investor pitching | B31: T4.8 | C31: =SUM(G31+K31+O31+S31+W31+AA31+AE31+AI31+AM31+AQ31+AU31+AY31) -> 595.19468 | D31: =SUM(H31+L31+P31+T31+X31+AB31+AF31+AJ31+AN31+AR31+AV31+AZ31) -> 5000 | E31: =SUM(I31+M31+Q31+U31+Y31+AC31+AG31+AG31+AK31+AO31+AS31+AW31+BA31) -> 53087.47 | F31: =100/E31*C31 -> 1.1211585 | G31: 0 | H31: 0 | I31: 6687.5 | J31: =100/I31*G31 -> 0 | K31: 0 | M31: 11712.47 | N31: =100/M31*K31 -> 0 | O31: 0 | Q31: 0 | R31: =100/Q31*O31 -> #DIV/0! | S31: 595.19468 | T31: 3000 | U31: 18750 | V31: =100/U31*S31 -> 3.1743716 | W31: =SUM(MAI!D31) -> 0 | Y31: 0 | Z31: =100/Y31*W31 -> #DIV/0! | AA31: 0 | AC31: 0 | AD31: =100/AC31*AA31 -> #DIV/0! | AE31: =SUM(IOC!K34) -> 0 | AG31: 0 | AH31: =100/AG31*AE31 -> #DIV/0! | AI31: =SUM(HIE!L34) -> 0 | AJ31: 2000 | AK31: 15937.5 | AL31: =100/AK31*AI31 -> 0 | AM31: 0 | AO31: 0 | AP31: =100/AO31*AM31 -> #DIV/0! | AQ31: 0 | AS31: 0 | AT31: =100/AS31*AQ31 -> #DIV/0! | AU31: 0 | AW31: 0 | AX31: =100/AW31*AU31 -> #DIV/0! | AY31: ='CKR '!C30 -> 0 | BA31: 0 | BB31: =100/BA31*AY31 -> #DIV/0!
A32: Business Support Service #8 Investor rounds | B32: T4.9 | C32: =SUM(G32+K32+O32+S32+W32+AA32+AE32+AI32+AM32+AQ32+AU32+AY32) -> 5748.05 | D32: =SUM(H32+L32+P32+T32+X32+AB32+AF32+AJ32+AN32+AR32+AV32+AZ32) -> 26314.29 | E32: =SUM(I32+M32+Q32+U32+Y32+AC32+AG32+AG32+AK32+AO32+AS32+AW32+BA32) -> 94600.07 | F32: =100/E32*C32 -> 6.0761583 | G32: 5748.05 | H32: 0 | I32: 33437.5 | J32: =100/I32*G32 -> 17.19043 | K32: 0 | M32: 5856.24 | N32: =100/M32*K32 -> 0 | O32: 0 | P32: 4000 | Q32: 1731.25 | R32: =100/Q32*O32 -> 0 | S32: 0 | T32: 600 | U32: 2343.75 | V32: =100/U32*S32 -> 0 | W32: =SUM(MAI!D32) -> 0 | X32: 1000 | Y32: 4843.75 | Z32: =100/Y32*W32 -> 0 | AA32: 0 | AB32: 5714.29 | AC32: 5625 | AD32: =100/AC32*AA32 -> 0 | AE32: =SUM(IOC!K35) -> 0 | AF32: 800 | AG32: 5768.79 | AH32: =100/AG32*AE32 -> 0 | AI32: =SUM(HIE!L35) -> 0 | AJ32: 1000 | AK32: 5312.5 | AL32: =100/AK32*AI32 -> 0 | AM32: 0 | AN32: 2000 | AO32: 6187.5 | AP32: =100/AO32*AM32 -> 0 | AQ32: 0 | AR32: 1000 | AS32: 1787.5 | AT32: =100/AS32*AQ32 -> 0 | AU32: 0 | AV32: 7600 | AW32: 13750 | AX32: =100/AW32*AU32 -> 0 | AY32: ='CKR '!C31 -> 0 | AZ32: 2600 | BA32: 2187.5 | BB32: =100/BA32*AY32 -> 0
A33: Large-scale Demonstrator (LSD) setup, validation, and impact assessment | B33: WP5 | C33: =SUM(G33+K33+O33+S33+W33+AA33+AE33+AI33+AM33+AQ33+AU33+AY33) -> 42546.324 | D33: =SUM(H33+L33+P33+T33+X33+AB33+AF33+AJ33+AN33+AR33+AV33+AZ33) -> 0 | E33: =SUM(I33+M33+Q33+U33+Y33+AC33+AG33+AG33+AK33+AO33+AS33+AW33+BA33) -> 148095.23 | F33: =100/E33*C33 -> 28.729031 | G33: 4189.7313 | H33: =SUM(H34:H36) -> 0 | I33: =SUM(I34:I36) -> 10331.25 | J33: =100/I33*G33 -> 40.553962 | K33: 33402.48 | L33: =SUM(L34:L36) -> 0 | M33: =SUM(M34:M36) -> 70274.73 | N33: =100/M33*K33 -> 47.531282 | O33: 87.15 | P33: =SUM(P34:P36) -> 0 | Q33: =SUM(Q34:Q36) -> 2596.86 | R33: =100/Q33*O33 -> 3.3559761 | S33: 700.09011 | T33: =SUM(T34:T36) -> 0 | U33: =SUM(U34:U36) -> 3515.64 | V33: =100/U33*S33 -> 19.913589 | W33: =SUM(MAI!D33) -> 0 | X33: =SUM(X34:X36) -> 0 | Y33: =SUM(Y34:Y36) -> 7265.64 | Z33: =100/Y33*W33 -> 0 | AA33: 0 | AB33: =SUM(AB34:AB36) -> 0 | AC33: =SUM(AC34:AC36) -> 8436 | AD33: =100/AC33*AA33 -> 0 | AE33: =SUM(IOC!K36) -> 359.5625 | AF33: =SUM(AF34:AF36) -> 0 | AG33: =SUM(AG34:AG36) -> 8653.18 | AH33: =100/AG33*AE33 -> 4.1552643 | AI33: =SUM(HIE!L36) -> 0 | AJ33: =SUM(AJ34:AJ36) -> 0 | AK33: =SUM(AK34:AK36) -> 7968.75 | AL33: =100/AK33*AI33 -> 0 | AM33: 0 | AN33: =SUM(AN34:AN36) -> 0 | AO33: =SUM(AO34:AO36) -> 9281.25 | AP33: =100/AO33*AM33 -> 0 | AQ33: 1742.07 | AR33: =SUM(AR34:AR36) -> 0 | AS33: =SUM(AS34:AS36) -> 2681.25 | AT33: =100/AS33*AQ33 -> 64.972308 | AU33: 1627 | AV33: =SUM(AV34:AV36) -> 0 | AW33: =SUM(AW34:AW36) -> 5156.25 | AX33: =100/AW33*AU33 -> 31.553939 | AY33: ='CKR '!C32 -> 438.24065 | AZ33: =SUM(AZ34:AZ36) -> 0 | BA33: =SUM(BA34:BA36) -> 3281.25 | BB33: =100/BA33*AY33 -> 13.355905
A34: Set-up of the GreenOffshoreTech LSD in GreenOffshoreTech regions | B34: T5.1 | C34: =SUM(G34+K34+O34+S34+W34+AA34+AE34+AI34+AM34+AQ34+AU34+AY34) -> 40961.187 | D34: =SUM(H34+L34+P34+T34+X34+AB34+AF34+AJ34+AN34+AR34+AV34+AZ34) -> 0 | E34: =SUM(I34+M34+Q34+U34+Y34+AC34+AG34+AG34+AK34+AO34+AS34+AW34+BA34) -> 55221.35 | F34: =100/E34*C34 -> 74.17636 | G34: 2874.025 | I34: 3443.75 | J34: =100/I34*G34 -> 83.456261 | K34: 33402.48 | M34: 29281.19 | N34: =100/M34*K34 -> 114.07487 | O34: 69.72 | Q34: 865.62 | R34: =100/Q34*O34 -> 8.0543426 | S34: 700.09011 | U34: 1171.88 | V34: =100/U34*S34 -> 59.740768 | W34: =SUM(MAI!D34) -> 0 | Y34: 2421.88 | Z34: =100/Y34*W34 -> 0 | AA34: 0 | AC34: 2812 | AD34: =100/AC34*AA34 -> 0 | AE34: =SUM(IOC!K37) -> 359.5625 | AG34: 2884.39 | AH34: =100/AG34*AE34 -> 12.465807 | AI34: =SUM(HIE!L37) -> 0 | AK34: 2656.25 | AL34: =100/AK34*AI34 -> 0 | AM34: 0 | AO34: 3093.75 | AP34: =100/AO34*AM34 -> 0 | AQ34: 1742.07 | AS34: 893.75 | AT34: =100/AS34*AQ34 -> 194.91692 | AU34: 1375 | AW34: 1718.75 | AX34: =100/AW34*AU34 -> 80 | AY34: ='CKR '!C33 -> 438.24 | BA34: 1093.75 | BB34: =100/BA34*AY34 -> 40.067657
A35: Validation & Impact assessment of GreenOffshoreTech LSD (data collection) | B35: T5.2 | C35: =SUM(G35+K35+O35+S35+W35+AA35+AE35+AI35+AM35+AQ35+AU35+AY35) -> 771.5 | D35: =SUM(H35+L35+P35+T35+X35+AB35+AF35+AJ35+AN35+AR35+AV35+AZ35) -> 0 | E35: =SUM(I35+M35+Q35+U35+Y35+AC35+AG35+AG35+AK35+AO35+AS35+AW35+BA35) -> 55221.35 | F35: =100/E35*C35 -> 1.3971046 | G35: 746.5 | I35: 3443.75 | J35: =100/I35*G35 -> 21.676951 | K35: 0 | M35: 29281.19 | N35: =100/M35*K35 -> 0 | O35: 0 | Q35: 865.62 | R35: =100/Q35*O35 -> 0 | S35: 0 | U35: 1171.88 | V35: =100/U35*S35 -> 0 | W35: =SUM(MAI!D35) -> 0 | Y35: 2421.88 | Z35: =100/Y35*W35 -> 0 | AA35: 0 | AC35: 2812 | AD35: =100/AC35*AA35 -> 0 | AE35: =SUM(IOC!K38) -> 0 | AG35: 2884.39 | AH35: =100/AG35*AE35 -> 0 | AI35: =SUM(HIE!L38) -> 0 | AK35: 2656.25 | AL35: =100/AK35*AI35 -> 0 | AM35: 0 | AO35: 3093.75 | AP35: =100/AO35*AM35 -> 0 | AQ35: 0 | AS35: 893.75 | AT35: =100/AS35*AQ35 -> 0 | AU35: 25 | AW35: 1718.75 | AX35: =100/AW35*AU35 -> 1.4545455 | AY35: ='CKR '!C34 -> 0 | BA35: 1093.75 | BB35: =100/BA35*AY35 -> 0
A36: Guidelines of Best Practice to foster cross-sector/-border collaboration and technology transfer through Clusters | B36: T5.3 | C36: =SUM(G36+K36+O36+S36+W36+AA36+AE36+AI36+AM36+AQ36+AU36+AY36) -> 796.20625 | D36: =SUM(H36+L36+P36+T36+X36+AB36+AF36+AJ36+AN36+AR36+AV36+AZ36) -> 0 | E36: =SUM(I36+M36+Q36+U36+Y36+AC36+AG36+AG36+AK36+AO36+AS36+AW36+BA36) -> 37652.53 | F36: =100/E36*C36 -> 2.1146155 | G36: 569.20625 | I36: 3443.75 | J36: =100/I36*G36 -> 16.528675 | K36: 0 | M36: 11712.35 | N36: =100/M36*K36 -> 0 | O36: 0 | Q36: 865.62 | R36: =100/Q36*O36 -> 0 | S36: 0 | U36: 1171.88 | V36: =100/U36*S36 -> 0 | W36: =SUM(MAI!D36) -> 0 | Y36: 2421.88 | Z36: =100/Y36*W36 -> 0 | AA36: 0 | AC36: 2812 | AD36: =100/AC36*AA36 -> 0 | AE36: =SUM(IOC!K39) -> 0 | AG36: 2884.4 | AH36: =100/AG36*AE36 -> 0 | AI36: =SUM(HIE!L39) -> 0 | AK36: 2656.25 | AL36: =100/AK36*AI36 -> 0 | AM36: 0 | AO36: 3093.75 | AP36: =100/AO36*AM36 -> 0 | AQ36: 0 | AS36: 893.75 | AT36: =100/AS36*AQ36 -> 0 | AU36: 227 | AW36: 1718.75 | AX36: =100/AW36*AU36 -> 13.207273 | AY36: ='CKR '!C35 -> 0 | BA36: 1093.75 | BB36: =100/BA36*AY36 -> 0
A37: Communication, Dissemination, Exploitation & Sustainability | B37: WP6 | C37: =SUM(G37+K37+O37+S37+W37+AA37+AE37+AI37+AM37+AQ37+AU37+AY37) -> 56508.95 | D37: =SUM(H37+L37+P37+T37+X37+AB37+AF37+AJ37+AN37+AR37+AV37+AZ37) -> 0 | E37: =SUM(I37+M37+Q37+U37+Y37+AC37+AG37+AG37+AK37+AO37+AS37+AW37+BA37) -> 231218.95 | F37: =100/E37*C37 -> 24.439584 | G37: 8425.1856 | H37: =SUM(H38:H40) -> 0 | I37: =SUM(I38:I40) -> 26750 | J37: =100/I37*G37 -> 31.496021 | K37: 5847.4365 | L37: =SUM(L38:L40) -> 0 | M37: =SUM(M38:M40) -> 11712.44 | N37: =100/M37*K37 -> 49.925007 | O37: 25103.862 | P37: =SUM(P38:P40) -> 0 | Q37: =SUM(Q38:Q40) -> 25968.75 | R37: =100/Q37*O37 -> 96.669507 | S37: 3337.7579 | T37: =SUM(T38:T40) -> 0 | U37: =SUM(U38:U40) -> 9375 | V37: =100/U37*S37 -> 35.602751 | W37: =SUM(MAI!D37) -> 4596 | X37: =SUM(X38:X40) -> 0 | Y37: =SUM(Y38:Y40) -> 29062.5 | Z37: =100/Y37*W37 -> 15.814194 | AA37: 510.54688 | AB37: =SUM(AB38:AB40) -> 0 | AC37: =SUM(AC38:AC40) -> 22500 | AD37: =100/AC37*AA37 -> 2.2690972 | AE37: =SUM(IOC!K40) -> 4821.4062 | AF37: =SUM(AF38:AF40) -> 0 | AG37: =SUM(AG38:AG40) -> 23075.13 | AH37: =100/AG37*AE37 -> 20.894384 | AI37: =SUM(HIE!L40) -> 2261.1825 | AJ37: =SUM(AJ38:AJ40) -> 0 | AK37: =SUM(AK38:AK40) -> 21250 | AL37: =100/AK37*AI37 -> 10.640859 | AM37: 0 | AN37: =SUM(AN38:AN40) -> 0 | AO37: =SUM(AO38:AO40) -> 12375 | AP37: =100/AO37*AM37 -> 0 | AQ37: 590.43 | AR37: =SUM(AR38:AR40) -> 0 | AS37: =SUM(AS38:AS40) -> 3575 | AT37: =100/AS37*AQ37 -> 16.515524 | AU37: 620.725 | AV37: =SUM(AV38:AV40) -> 0 | AW37: =SUM(AW38:AW40) -> 13750 | AX37: =100/AW37*AU37 -> 4.5143636 | AY37: ='CKR '!C36 -> 394.41658 | AZ37: =SUM(AZ38:AZ40) -> 0 | BA37: =SUM(BA38:BA40) -> 8750 | BB37: =100/BA37*AY37 -> 4.5076181
A38: Communication plan and Communication activities | B38: T6.1 | C38: =SUM(G38+K38+O38+S38+W38+AA38+AE38+AI38+AM38+AQ38+AU38+AY38) -> 39463.093 | D38: =SUM(H38+L38+P38+T38+X38+AB38+AF38+AJ38+AN38+AR38+AV38+AZ38) -> 0 | E38: =SUM(I38+M38+Q38+U38+Y38+AC38+AG38+AG38+AK38+AO38+AS38+AW38+BA38) -> 55825.06 | F38: =100/E38*C38 -> 70.690641 | G38: 6531.875 | I38: 6687.5 | J38: =100/I38*G38 -> 97.672897 | K38: 4886.2141 | M38: 0 | N38: =100/M38*K38 -> #DIV/0! | O38: 16847.5 | Q38: 13850 | R38: =100/Q38*O38 -> 121.6426 | S38: 459.24468 | U38: 2343.75 | V38: =100/U38*S38 -> 19.59444 | W38: =SUM(MAI!D38) -> 4596 | Y38: 4843.75 | Z38: =100/Y38*W38 -> 94.885161 | AA38: 408.4375 | AC38: 5625 | AD38: =100/AC38*AA38 -> 7.2611111 | AE38: =SUM(IOC!K41) -> 4821.4062 | AG38: 5768.78 | AH38: =100/AG38*AE38 -> 83.577572 | AI38: =SUM(HIE!L41) -> 0 | AK38: 5312.5 | AL38: =100/AK38*AI38 -> 0 | AM38: 0 | AO38: =SUM(BAL!Q33*BAL!$S$1) -> 0 | AP38: =100/AO38*AM38 -> #DIV/0! | AQ38: 0 | AS38: 0 | AT38: =100/AS38*AQ38 -> #DIV/0! | AU38: 514.315 | AW38: 3437.5 | AX38: =100/AW38*AU38 -> 14.961891 | AY38: ='CKR '!C37 -> 398.1 | BA38: 2187.5 | BB38: =100/BA38*AY38 -> 18.198857
A39: Dissemination strategy and Dissemination activities | B39: T6.2 | C39: =SUM(G39+K39+O39+S39+W39+AA39+AE39+AI39+AM39+AQ39+AU39+AY39) -> 10860.063 | D39: =SUM(H39+L39+P39+T39+X39+AB39+AF39+AJ39+AN39+AR39+AV39+AZ39) -> 0 | E39: =SUM(I39+M39+Q39+U39+Y39+AC39+AG39+AG39+AK39+AO39+AS39+AW39+BA39) -> 108168.84 | F39: =100/E39*C39 -> 10.039918 | G39: 933.125 | I39: 13375 | J39: =100/I39*G39 -> 6.9766355 | K39: 961.22244 | M39: 5856.22 | N39: =100/M39*K39 -> 16.413701 | O39: 3235.59 | Q39: 10387.5 | R39: =100/Q39*O39 -> 31.148881 | S39: 2878.5132 | U39: 4687.5 | V39: =100/U39*S39 -> 61.408281 | W39: =SUM(MAI!D39) -> 0 | Y39: 9687.5 | Z39: =100/Y39*W39 -> 0 | AA39: 0 | AC39: 11250 | AD39: =100/AC39*AA39 -> 0 | AE39: =SUM(IOC!K42) -> 0 | AG39: 11537.56 | AH39: =100/AG39*AE39 -> 0 | AI39: =SUM(HIE!L42) -> 2261.1825 | AK39: 10625 | AL39: =100/AK39*AI39 -> 21.281718 | AM39: 0 | AO39: =SUM(BAL!Q34*BAL!$S$1) -> 6187.5 | AP39: =100/AO39*AM39 -> 0 | AQ39: 590.43 | AS39: 1787.5 | AT39: =100/AS39*AQ39 -> 33.031049 | AU39: 0 | AW39: 6875 | AX39: =100/AW39*AU39 -> 0 | AY39: ='CKR '!C38 -> 0 | BA39: 4375 | BB39: =100/BA39*AY39 -> 0
A40: Exploitation strategy, IPR and Sustainability | B40: T6.3 | C40: =SUM(G40+K40+O40+S40+W40+AA40+AE40+AI40+AM40+AQ40+AU40+AY40) -> 1066.5956 | D40: =SUM(H40+L40+P40+T40+X40+AB40+AF40+AJ40+AN40+AR40+AV40+AZ40) -> 0 | E40: =SUM(I40+M40+Q40+U40+Y40+AC40+AG40+AG40+AK40+AO40+AS40+AW40+BA40) -> 67225.05 | F40: =100/E40*C40 -> 1.5866044 | G40: 960.18563 | I40: 6687.5 | J40: =100/I40*G40 -> 14.357916 | K40: 0 | M40: 5856.22 | N40: =100/M40*K40 -> 0 | O40: 0 | Q40: 1731.25 | R40: =100/Q40*O40 -> 0 | S40: 0 | U40: 2343.75 | V40: =100/U40*S40 -> 0 | W40: =SUM(MAI!D40) -> 0 | Y40: 14531.25 | Z40: =100/Y40*W40 -> 0 | AA40: 0 | AC40: 5625 | AD40: =100/AC40*AA40 -> 0 | AE40: =SUM(IOC!K43) -> 0 | AG40: 5768.79 | AH40: =100/AG40*AE40 -> 0 | AI40: =SUM(HIE!L43) -> 0 | AK40: 5312.5 | AL40: =100/AK40*AI40 -> 0 | AM40: 0 | AO40: =SUM(BAL!Q35*BAL!$S$1) -> 6187.5 | AP40: =100/AO40*AM40 -> 0 | AQ40: 0 | AS40: 1787.5 | AT40: =100/AS40*AQ40 -> 0 | AU40: 106.41 | AW40: 3437.5 | AX40: =100/AW40*AU40 -> 3.0955636 | AY40: ='CKR '!C39 -> 0 | BA40: 2187.5 | BB40: =100/BA40*AY40 -> 0
A41: Project Management and Coordination | B41: WP7 | C41: =SUM(G41+K41+O41+S41+W41+AA41+AE41+AI41+AM41+AQ41+AU41+AY41) -> 116025.33 | D41: =SUM(H41+L41+P41+T41+X41+AB41+AF41+AJ41+AN41+AR41+AV41+AZ41) -> 0 | E41: =SUM(I41+M41+Q41+U41+Y41+AC41+AG41+AG41+AK41+AO41+AS41+AW41+BA41) -> 214000 | F41: =100/E41*C41 -> 54.217445 | G41: 108068.01 | H41: =SUM(H42:H44) -> 0 | I41: =SUM(I42:I44) -> 214000 | J41: =100/I41*G41 -> 50.499068 | K41: 1682.1393 | L41: =SUM(L42:L44) -> 0 | M41: =SUM(M42:M44) -> 0 | N41: =100/M41*K41 -> #DIV/0! | O41: 0 | P41: =SUM(P42:P44) -> 0 | Q41: =SUM(Q42:Q44) -> 0 | R41: =100/Q41*O41 -> #DIV/0! | S41: 0 | T41: =SUM(T42:T44) -> 0 | U41: =SUM(U42:U44) -> 0 | V41: =100/U41*S41 -> #DIV/0! | W41: =SUM(MAI!D41) -> 0 | X41: =SUM(X42:X44) -> 0 | Y41: =SUM(Y42:Y44) -> 0 | Z41: =100/Y41*W41 -> #DIV/0! | AA41: 459.49219 | AB41: =SUM(AB42:AB44) -> 0 | AC41: =SUM(AC42:AC44) -> 0 | AD41: =100/AC41*AA41 -> #DIV/0! | AE41: =SUM(IOC!K44) -> 0 | AF41: =SUM(AF42:AF44) -> 0 | AG41: =SUM(AG42:AG44) -> 0 | AH41: =100/AG41*AE41 -> #DIV/0! | AI41: =SUM(HIE!L44) -> 5531.9342 | AJ41: =SUM(AJ42:AJ44) -> 0 | AK41: =SUM(AK42:AK44) -> 0 | AL41: =100/AK41*AI41 -> #DIV/0! | AM41: 0 | AN41: =SUM(AN42:AN44) -> 0 | AO41: =SUM(AO42:AO44) -> 0 | AP41: =100/AO41*AM41 -> #DIV/0! | AQ41: 0 | AR41: =SUM(AR42:AR44) -> 0 | AS41: =SUM(AS42:AS44) -> 0 | AT41: =100/AS41*AQ41 -> #DIV/0! | AU41: 283.76 | AV41: =SUM(AV42:AV44) -> 0 | AW41: =SUM(AW42:AW44) -> 0 | AX41: =100/AW41*AU41 -> #DIV/0! | AY41: ='CKR '!C40 -> 0 | AZ41: =SUM(AZ42:AZ44) -> 0 | BA41: =SUM(BA42:BA44) -> 0 | BB41: =100/BA41*AY41 -> #DIV/0!
...

Sheet MNU
C1: TOTAL COSTS
C2: Dir & Indir (EUR)
C3: ACTUAL
A4: GreenOfshoreTech MNU (Period M1 to M10) | B4: Task/ | C4: M1-M10
B5: WP
A6: Otherdirect Cost ( travel, equipment & Other goods and services)(ODC)
A7: Assessment of potential new value chains and selection of Topics for Call of Proposals | B7: WP1 | C7: =SUM(C8:C10) -> 8024.875
A8: Sustainable challenges, needs and trends of four industrial offshore sectors | B8: T1.1 | C8: =G14*1.25 -> 3265.9375
A9: Assessment of emerging technology trends and solutions | B9: T1.2 | C9: =G15*1.25 -> 1399.6875 | F9: Budget rate | H9: Actual | K9: 1PM iequals to | M9: 143.333
A10: Potential new value chains and selection of Call Topics | B10: T1.3 | C10: =G16*1.25 -> 3359.25 | F10: Project manager | H10: Project manager
A11: Methodologies and tools for cross-sectoral/-border collaboration and technology transfer | B11: WP2 | C11: =SUM(C12:C15) -> 5346.8063 | F11: hrs | G11: Salery rate | H11: hrs | I11: Salery rate
A12: Methologies and tools for cross-sectoral/-border collaboration and technology transfer | B12: T2.1 | C12: =G18*1.25 -> 1306.375 | G12: 74.65 | I12: 82
A13: Establishment of a Collaborative Virtual Environment | B13: T2.2 | C13: =G19*1.25 -> 4040.4313 | F13: =SUM(F14:F16) -> 86 | G13: =F13*G$12*(1+I$9) -> 6419.9 | H13: =SUM(H14:H16) -> 0 | I13: =H13*I$12*(1+I$9) -> 0 | J13: PM | K13: 0.6
A14: Establishment of a Survey tool | B14: T2.3 | C14: =G20*1.25 -> 0 | F14: 35 | G14: =F14*G$12*(1+I$9) -> 2612.75 | H14: 0 | I14: =H14*I$12*(1+I$9) -> 0
A15: Establishment of the GreenOffshoreTech Cluster Collaboration Platform | B15: T2.4 | C15: =G21*1.25 -> 0 | F15: 15 | G15: =F15*G$12*(1+I$9) -> 1119.75 | H15: 0 | I15: =H15*I$12*(1+I$9) -> 0
A16: Direct financial support to SMEs through a competitive Call for Proposals | B16: WP3 | C16: =SUM(C17:C22) -> 1306.375 | F16: 36 | G16: =F16*G$12*(1+I$9) -> 2687.4 | H16: 0 | I16: =H16*I$12*(1+I$9) -> 0
A17: Preparation of the Call for Proposals | B17: T3.1 | C17: =G23*1.25 -> 559.875 | F17: =SUM(F18:F21) -> 57.3 | G17: =F17*G$12*(1+I$9) -> 4277.445 | I17: =H17*I$12*(1+I$9) -> 0 | J17: PM | K17: 0.4
A18: Publication of the Call for Proposals and Proposal reception. | B18: T3.2 | C18: =G24*1.25 -> 466.5625 | F18: 14 | G18: =F18*G$12*(1+I$9) -> 1045.1 | H18: 0 | I18: =H18*I$12*(1+I$9) -> 0
A19: Evaluation and Selection of SMEs Proposals | B19: T3.3 | C19: =G25*1.25 -> 279.9375 | F19: 43.3 | G19: =F19*G$12*(1+I$9) -> 3232.345 | H19: 0 | I19: =H19*I$12*(1+I$9) -> 0
A20: Contracting with winner SMEs Projects | B20: T3.4 | C20: =G26*1.25 -> 0 | F20: 0 | G20: =F20*G$12*(1+I$9) -> 0 | H20: 0 | I20: =H20*I$12*(1+I$9) -> 0
A21: Payments and financial monitoring of winner SMEs Projects | B21: T3.5 | C21: =G27*1.25 -> 0 | F21: 0 | G21: =F21*G$12*(1+I$9) -> 0 | H21: 0 | I21: =H21*I$12*(1+I$9) -> 0
A22: Technical monitoring of winner SMEs Projects | B22: T3.6 | C22: =G28*1.25 -> 0 | F22: =SUM(F23:F28) -> 14 | G22: =F22*G$12*(1+I$9) -> 1045.1 | H22: =SUM(H23:H28) -> 0 | I22: =H22*I$12*(1+I$9) -> 0 | J22: PM | K22: 0.1
A23: Business Support Services to winner SMEs (preparation) | B23: WP4 | C23: =SUM(C24:C32) -> 6681.175 | F23: 6 | G23: =F23*G$12*(1+I$9) -> 447.9 | H23: 0 | I23: =H23*I$12*(1+I$9) -> 0
A24: Programme of Business Support Services to winner SMEs (prep) | B24: T4.1 | C24: =G30*1.25 -> 933.125 | F24: 5 | G24: =F24*G$12*(1+I$9) -> 373.25 | H24: 0 | I24: =H24*I$12*(1+I$9) -> 0
A25: Business Support Service #1 Business & Tech Academy | B25: T4.2 | C25: =G31*1.25 -> 0 | F25: 3 | G25: =F25*G$12*(1+I$9) -> 223.95 | H25: 0 | I25: =H25*I$12*(1+I$9) -> 0
A26: Business Support Service #2 Brokerage & B2B matchmaking events | B26: T4.3 | C26: =G32*1.25 -> 0 | F26: 0 | G26: =F26*G$12*(1+I$9) -> 0 | H26: 0 | I26: =H26*I$12*(1+I$9) -> 0
A27: Business Support Service #3 Access to Finance | B27: T4.4 | C27: =G33*1.25 -> 0 | F27: 0 | G27: =F27*G$12*(1+I$9) -> 0 | H27: 0 | I27: =H27*I$12*(1+I$9) -> 0
A28: Business Support Service #4 One-to-One Mentoring and Coaching (prep) | B28: T4.5 | C28: =G34*1.25 -> 0 | F28: 0 | G28: =F28*G$12*(1+I$9) -> 0 | H28: 0 | I28: =H28*I$12*(1+I$9) -> 0
A29: Business Support Service #5 Branding | B29: T4.6 | C29: =G35*1.25 -> 0 | F29: =SUM(F30:F38) -> 71.6 | G29: =F29*G$12*(1+I$9) -> 5344.94 | I29: =H29*I$12*(1+I$9) -> 0 | J29: PM | K29: 0.5
A30: Business Support Service #6 Internationalisation | B30: T4.7 | C30: =G36*1.25 -> 0 | F30: 10 | G30: =F30*G$12*(1+I$9) -> 746.5 | H30: 0 | I30: =H30*I$12*(1+I$9) -> 0
A31: Business Support Service #7 Investor pitching | B31: T4.8 | C31: =G37*1.25 -> 0 | F31: 0 | G31: =F31*G$12*(1+I$9) -> 0 | H31: 0 | I31: =H31*I$12*(1+I$9) -> 0
A32: Business Support Service #8 Investor rounds | B32: T4.9 | C32: =G38*1.25 -> 5748.05 | F32: 0 | G32: =F32*G$12*(1+I$9) -> 0 | H32: 0 | I32: =H32*I$12*(1+I$9) -> 0
A33: Large-scale Demonstrator (LSD) setup, validation, and impact assessment | B33: WP5 | C33: =SUM(C34:C36) -> 4189.7313 | F33: 0 | G33: =F33*G$12*(1+I$9) -> 0 | H33: 0 | I33: =H33*I$12*(1+I$9) -> 0
A34: Set-up of the GreenOffshoreTech LSD in GreenOffshoreTech regions | B34: T5.1 | C34: =G40*1.25 -> 2874.025 | F34: 0 | G34: =F34*G$12*(1+I$9) -> 0 | H34: 0 | I34: =H34*I$12*(1+I$9) -> 0
A35: Validation & Impact assessment of GreenOffshoreTech LSD (data collection) | B35: T5.2 | C35: =G41*1.25 -> 746.5 | F35: 0 | G35: =F35*G$12*(1+I$9) -> 0 | H35: 0 | I35: =H35*I$12*(1+I$9) -> 0
A36: Guidelines of Best Practice to foster cross-sector/-border collaboration and technology transfer through Clusters | B36: T5.3 | C36: =G42*1.25 -> 569.20625 | F36: 0 | G36: =F36*G$12*(1+I$9) -> 0 | H36: 0 | I36: =H36*I$12*(1+I$9) -> 0
A37: Communication, Dissemination, Exploitation & Sustainability | B37: WP6 | C37: =SUM(C38:C40) -> 8425.1856 | F37: 0 | G37: =F37*G$12*(1+I$9) -> 0 | H37: 0 | I37: =H37*I$12*(1+I$9) -> 0
A38: Communication plan and Communication activities | B38: T6.1 | C38: =G44*1.25 -> 6531.875 | F38: 61.6 | G38: =F38*G$12*(1+I$9) -> 4598.44 | H38: 0 | I38: =H38*I$12*(1+I$9) -> 0
A39: Dissemination strategy and Dissemination activities | B39: T6.2 | C39: =G45*1.25 -> 933.125 | F39: =SUM(F40:F42) -> 44.9 | G39: =F39*G$12*(1+I$9) -> 3351.785 | I39: =H39*I$12*(1+I$9) -> 0 | J39: PM | K39: 0.31
A40: Exploitation strategy, IPR and Sustainability | B40: T6.3 | C40: =G46*1.25 -> 960.18563 | F40: 30.8 | G40: =F40*G$12*(1+I$9) -> 2299.22 | H40: 0 | I40: =H40*I$12*(1+I$9) -> 0
...

Sheet SCA
D2: TOTAL COSTS
B3: 10797.74 | D3: Dir & Indir (EUR)
D4: ACTUAL
B5: SCABERIA AS | C5: Task/ | D5: M1-M9
C6: WP
B7: Otherdirect Cost ( travel, equipment & Other goods and services)(ODC) | C7: ALL | D7: 0
B8: Assessment of potential new value chains and selection of Topics for Call of Proposals | C8: WP1 | D8: 13497.165
B9: Sustainable challenges, needs and trends of four industrial offshore sectors | C9: T1.1 | D9: 6648.4552
B10: Assessment of emerging technology trends and solutions | C10: T1.2 | D10: 3484.4313
B11: Potential new value chains and selection of Call Topics | C11: T1.3 | D11: 3364.2785
B12: Methodologies and tools for cross-sectoral/-border collaboration and technology transfer | C12: WP2 | D12: 3123.9729
B13: Methologies and tools for cross-sectoral/-border collaboration and technology transfer | C13: T2.1 | D13: 40.050935
B14: Establishment of a Collaborative Virtual Environment | C14: T2.2 | D14: 520.66216
B15: Establishment of a Survey tool | C15: T2.3 | D15: 1321.6809
B16: Establishment of the GreenOffshoreTech Cluster Collaboration Platform | C16: T2.4 | D16: 1241.579
B17: Direct financial support to SMEs through a competitive Call for Proposals | C17: WP3 | D17: 11374.466
B18: Preparation of the Call for Proposals | C18: T3.1 | D18: 10613.498
... B45: Quality Assurance | C45: T7.3 | D45: 720.91683
D46: =SUM(D8+D12+D17+D24+D34+D38+D42) -> 71651.123

Sheet FOC
D2: TOTAL COSTS
D3: Indir & DIR (EUR)
D4: ACTUAL
B5: GreenOffshoreTech - FÓRUM OCEANO | C5: Task/ | D5: M1-M9
C6: WP
B7: Otherdirect Cost ( travel, equipment & Other goods and services)(ODC) | C7: ALL | D7: 0
B8: Assessment of potential new value chains and selection of Topics for Call of Proposals | C8: WP1 | D8: =SUM(D9:D11)*1.25 -> 1875.625
B9: Sustainable challenges, needs and trends of four industrial offshore sectors | C9: T1.1 | D9: 780.13
B10: Assessment of emerging technology trends and solutions | C10: T1.2 | D10: 194.2
B11: Potential new value chains and selection of Call Topics | C11: T1.3 | D11: 526.17
B12: Methodologies and tools for cross-sectoral/-border collaboration and technology transfer | C12: WP2 | D12: =SUM(D13:D16)*1.25 -> 174.2875
B13: Methologies and tools for cross-sectoral/-border collaboration and technology transfer | C13: T2.1 | D13: 0
B14: Establishment of a Collaborative Virtual Environment | C14: T2.2 | D14: 0
B15: Establishment of a Survey tool | C15: T2.3 | D15: 139.43
